Workbook

Sheet Sample Size
A1: SAMPLE SIZE CALCULATION for one domain | G1: This template can be used to examine sample sizes for alternativel candidate indicators, both in terms of rates and amounts. Changing the input parameter values as necessary will produce a new sample size (cell E6). The template can also be used for the reverse problem of examining margins of errors for given sample sizes, as in the case of child labour surveys attached as module to a broader labour force survey. The sample size should be specified as input value (cell B17). The template will produce the corresponding margin of error in absolute and relative terms (E11 and E12). Indicators with comparatively low values of r (cell B6) should be used only. Do not use indicators with r values that are higher than 0.4 or lower than 0.1. Do not change the cell contents that are red. | Q1: Template User Instructions: SIMPOC Interactive Tools "Sample size and Margin of error" ILO, Geneva, 5 August 2014
A3: INPUT VALUES | D3: OUTPUT VALUES
A4: Parameter | B4: Value | D4: Estimate | E4: Value
A6: Predicted value of main indicator r | B6: 0.1 | D6: Sample size (number of households) n | E6: =(B17="")*(4*(E7^2)*E8/((E11^2)*E13*E16))+(1-(B17=""))*B17 -> 2379.2593
A7: Standard deviation of underlying variable s | D7: Standard deviation of underlying variable s | E7: =+IF(B7="",SQRT(B6*(1-B6)),B7) -> 0.3
A8: Design effect deff | D8: Design effect deff | E8: =+(B8="")*(1+(B10*E13-1)*B9)+(1-(B8=""))*B8 -> 10.100629
A9: Intraclass correlation rho | B9: =1/3 -> 0.33333333 | D9: Intraclass correlation rho | E9: =+IF(B9="",(E8-1)/(B21*E13-1),B9) -> 0.33333333
A10: Number of households per cluster b | B10: 15 | D10: Standard error of estimate se | E10: =+B11/2 -> 0.015
A11: Margin of error at 95% confidence ME | B11: 0.03 | D11: Margin of error at 95% confidence ME | E11: =IF(B17="",(B11="")*B12*B6+(1-(B11=""))*B11,SQRT(4*(E7^2)*E8/(B17*E13*E16))) -> 0.03
A12: RME | D12: RME | E12: =+E11/B6 -> 0.3
A13: Average no. of persons in base population per HH AveHH | B13: =1/0.53 -> 1.8867925 | D13: AveHH | E13: =+(B13="")*B14*B15+(1-(B13=""))*B13 -> 1.8867925
A14: Average household size AveSize | D14: Confidence limits (at 95% confidence) Lower | E14: =+B6*(1-E12) -> 0.07
A15: Proportion of base population in total population pb | D15: Upper | E15: =+B6*(1+E12) -> 0.13
A16: Response rate RR | B16: 0.9 | D16: RR | E16: =+(B16="")+(1-(B16=""))*B16 -> 0.9
A17: Sample size (number of households) n
A19: ADDITIONAL INPUTS | D19: ADDITIONAL OUTPUTS | G19: Confidence limits (95% confidence): Upper: r * (1 + RME) Lower: r * (1 - RME) Sample size: 4 * s2 * deff n = --------------------------------------------- ME2 * AveHH * RR Variance: s2 = r * (1-r) | L19: Absolute margin of error: ME = r * RME Standard error (se): (r * RME) / 2 Design effect and intraclass correlation: deff = 1+(b/h -1)*rho Average number of persons in base population per household: AveHH = pb * AveSize | Q19: Number of households for one person in base population: h = 1/AveHH Margin of error for given sample size: 4 * s2 * deff ME =sqrt( -----------------------) n * AveHH * RR
A21: Cluster size (Number of households per cluster) b | B21: 16 | D21: Number of clusters | E21: =+E6/B21 -> 148.7037
A22: Average household size AveSize | B22: 5
A23: Base populations in total population | D23: Expected sample households | E23: =+E6*B16 -> 2141.3333
A24: Proportions of: | D24: Expected sample household members | E24: =+E23*B22 -> 10706.667
A25: Households with children 5-17 yrs | B25: 0.9 | D25: Expected sample hslds with children 5-17 yrs | E25: =+E23*B25 -> 1927.2
A26: Chidren 5-17 yrs | B26: 0.15 | D26: Expected sample children 5-17 yrs | E26: =E24*B26 -> 1606
A27: Children 5-11 yrs | B27: =+B26*858915/1585566 -> 0.081256315 | D27: Expected sample children 5-11 yrs | E27: =E24*B27 -> 869.98428
A28: Children 12-14 yrs | B28: =+B26*362146/1585566 -> 0.034260258 | D28: Expected sample children 12-14 yrs | E28: =E24*B28 -> 366.81316
A29: Children 15-17 yrs | B29: =+B26*364495/1585566 -> 0.034482481 | D29: Expected sample children 15-17 yrs | E29: =+E24*B29 -> 369.19243
A40: =+#REF!="" -> #REF!

Sheet Sample Allocation
A1: SAMPLE ALLOCATION among domains or strata | J1: This template is to assist you to examine sample allocations among domains or strata, allowing for different allocation procedures, including equal allocation, proportional allocation, the compromise square-root allocation and general allocation where the allocation parameter and the minimum sample size in each stratum can be specified. More strata or domains can be inserted as needed. Specify the number of domains or strata as part of the input values. Do not change the content of cells that are red and those that are within the intermediary calculations.
A3: INPUT VALUES | E3: OUTPUT VALUES | J3: INTERMEDIARY CALCULATIONS
A4: Total sample size | B4: n = | C4: 11675 | L4: Fixed-point algorithm (Newton's equation)
A5: Number of domains or strata | B5: H = | C5: =+COUNTA(A10:A2500) -> 20 | L5: Iteration 1 | N5: Iteration 2 | P5: Iteration 3
A6: Allocation parameter | B6: α = | C6: 0.5 | L6: k = | M6: =+C4/K9 -> 7.1173716 | N6: k = | O6: =+M6-(M9-$C4)/L9 -> 7.0682005 | P6: k = | Q6: =O6-(O9-$C4)/N9 -> 7.0682005
A7: Strata | B7: Allocation variable | C7: Minmum allocation | E7: Equal allocation | F7: Proportional allocation | G7: Square-root allocation | H7: General allocation
A8: h | B8: Zh | C8: Zo | E8: 0 | F8: 1 | G8: 0.5 | H8: α | J8: √ | K8: Zh^α | L8: f'(k) | M8: f(k) | N8: f'(k) | O8: f(k) | P8: f'(k) | Q8: f(k)
A9: Total | B9: =SUM(B10:B2500) -> 198256 | C9: =SUM(C10:C2500) -> 5000 | E9: =+SUM(E10:E2500) -> 11675 | F9: =+SUM(F10:F2500) -> 11675 | G9: =+SUM(G10:G2500) -> 11675 | H9: =+SUM(H10:H2500) -> 11675 | J9: =+SUM(J10:J22500) -> 1640.3527 | K9: =+SUM(K10:K22500) -> 1640.3527 | L9: =+SUM(L10:L22500) -> 1616.3944 | M9: =+SUM(M10:M22500) -> 11754.48 | N9: =+SUM(N10:N22500) -> 1616.3944 | O9: =+SUM(O10:O22500) -> 11675 | P9: =+SUM(P10:P22500) -> 1616.3944 | Q9: =+SUM(Q10:Q22500) -> 11675
A10: Domain or Stratum 1 | B10: 4708 | C10: 250 | E10: =C$4/C$5 -> 583.75 | F10: =+C$4*B10/B$9 -> 277.24709 | G10: =+C$4*J10/J$9 -> 488.35751 | H10: =+Q10 -> 484.98364 | J10: =+SQRT(B10) -> 68.614867 | K10: =+B10^C$6 -> 68.614867 | L10: =+($K10/2)*(1+SIGN(M$6*$K10-$C10)) -> 68.614867 | M10: =+MAX($C10,M$6*$K10) -> 488.35751 | N10: =+($K10/2)*(1+SIGN(O$6*$K10-$C10)) -> 68.614867 | O10: =+MAX($C10,O$6*$K10) -> 484.98364 | P10: =+($K10/2)*(1+SIGN(Q$6*$K10-$C10)) -> 68.614867 | Q10: =+MAX($C10,Q$6*$K10) -> 484.98364
A11: Domain or Stratum 2 | B11: 72945 | C11: 250 | E11: =MAX(C11,C$4/C$5) -> 583.75 | F11: =+C$4*B11/B$9 -> 4295.6222 | G11: =+C$4*J11/J$9 -> 1922.2834 | H11: =+Q11 -> 1909.0031 | J11: =+SQRT(B11) -> 270.08332 | K11: =+B11^C$6 -> 270.08332 | L11: =+($K11/2)*(1+SIGN(M$6*$K11-$C11)) -> 270.08332 | M11: =+MAX($C11,M$6*$K11) -> 1922.2834 | N11: =+($K11/2)*(1+SIGN(O$6*$K11-$C11)) -> 270.08332 | O11: =+MAX($C11,O$6*$K11) -> 1909.0031 | P11: =+($K11/2)*(1+SIGN(Q$6*$K11-$C11)) -> 270.08332 | Q11: =+MAX($C11,Q$6*$K11) -> 1909.0031
A12: Domain or Stratum 3 | B12: 6880 | C12: 250 | E12: =MAX(C12,C$4/C$5) -> 583.75 | F12: =+C$4*B12/B$9 -> 405.15293 | G12: =+C$4*J12/J$9 -> 590.35584 | H12: =+Q12 -> 586.2773 | J12: =+SQRT(B12) -> 82.945765 | K12: =+B12^C$6 -> 82.945765 | L12: =+($K12/2)*(1+SIGN(M$6*$K12-$C12)) -> 82.945765 | M12: =+MAX($C12,M$6*$K12) -> 590.35584 | N12: =+($K12/2)*(1+SIGN(O$6*$K12-$C12)) -> 82.945765 | O12: =+MAX($C12,O$6*$K12) -> 586.2773 | P12: =+($K12/2)*(1+SIGN(Q$6*$K12-$C12)) -> 82.945765 | Q12: =+MAX($C12,Q$6*$K12) -> 586.2773
A13: Domain or Stratum 4 | B13: 9343 | C13: 250 | E13: =MAX(C13,C$4/C$5) -> 583.75 | F13: =+C$4*B13/B$9 -> 550.19533 | G13: =+C$4*J13/J$9 -> 687.95941 | H13: =+Q13 -> 683.20657 | J13: =+SQRT(B13) -> 96.659195 | K13: =+B13^C$6 -> 96.659195 | L13: =+($K13/2)*(1+SIGN(M$6*$K13-$C13)) -> 96.659195 | M13: =+MAX($C13,M$6*$K13) -> 687.95941 | N13: =+($K13/2)*(1+SIGN(O$6*$K13-$C13)) -> 96.659195 | O13: =+MAX($C13,O$6*$K13) -> 683.20657 | P13: =+($K13/2)*(1+SIGN(Q$6*$K13-$C13)) -> 96.659195 | Q13: =+MAX($C13,Q$6*$K13) -> 683.20657
A14: Domain or Stratum 5 | B14: 17622 | C14: 250 | E14: =MAX(C14,C$4/C$5) -> 583.75 | F14: =+C$4*B14/B$9 -> 1037.7333 | G14: =+C$4*J14/J$9 -> 944.816 | H14: =+Q14 -> 938.28864 | J14: =+SQRT(B14) -> 132.74788 | K14: =+B14^C$6 -> 132.74788 | L14: =+($K14/2)*(1+SIGN(M$6*$K14-$C14)) -> 132.74788 | M14: =+MAX($C14,M$6*$K14) -> 944.816 | N14: =+($K14/2)*(1+SIGN(O$6*$K14-$C14)) -> 132.74788 | O14: =+MAX($C14,O$6*$K14) -> 938.28864 | P14: =+($K14/2)*(1+SIGN(Q$6*$K14-$C14)) -> 132.74788 | Q14: =+MAX($C14,Q$6*$K14) -> 938.28864
A15: Domain or Stratum 6 | B15: 2326 | C15: 250 | E15: =MAX(C15,C$4/C$5) -> 583.75 | F15: =+C$4*B15/B$9 -> 136.97467 | G15: =+C$4*J15/J$9 -> 343.26103 | H15: =+Q15 -> 340.88957 | J15: =+SQRT(B15) -> 48.228622 | K15: =+B15^C$6 -> 48.228622 | L15: =+($K15/2)*(1+SIGN(M$6*$K15-$C15)) -> 48.228622 | M15: =+MAX($C15,M$6*$K15) -> 343.26103 | N15: =+($K15/2)*(1+SIGN(O$6*$K15-$C15)) -> 48.228622 | O15: =+MAX($C15,O$6*$K15) -> 340.88957 | P15: =+($K15/2)*(1+SIGN(Q$6*$K15-$C15)) -> 48.228622 | Q15: =+MAX($C15,Q$6*$K15) -> 340.88957
A16: Domain or Stratum 7 | B16: 4628 | C16: 250 | E16: =MAX(C16,C$4/C$5) -> 583.75 | F16: =+C$4*B16/B$9 -> 272.53601 | G16: =+C$4*J16/J$9 -> 484.19056 | H16: =+Q16 -> 480.84548 | J16: =+SQRT(B16) -> 68.029405 | K16: =+B16^C$6 -> 68.029405 | L16: =+($K16/2)*(1+SIGN(M$6*$K16-$C16)) -> 68.029405 | M16: =+MAX($C16,M$6*$K16) -> 484.19056 | N16: =+($K16/2)*(1+SIGN(O$6*$K16-$C16)) -> 68.029405 | O16: =+MAX($C16,O$6*$K16) -> 480.84548 | P16: =+($K16/2)*(1+SIGN(Q$6*$K16-$C16)) -> 68.029405 | Q16: =+MAX($C16,Q$6*$K16) -> 480.84548
A17: Domain or Stratum 8 | B17: 3152 | C17: 250 | E17: =MAX(C17,C$4/C$5) -> 583.75 | F17: =+C$4*B17/B$9 -> 185.61658 | G17: =+C$4*J17/J$9 -> 399.58828 | H17: =+Q17 -> 396.82769 | J17: =+SQRT(B17) -> 56.142675 | K17: =+B17^C$6 -> 56.142675 | L17: =+($K17/2)*(1+SIGN(M$6*$K17-$C17)) -> 56.142675 | M17: =+MAX($C17,M$6*$K17) -> 399.58828 | N17: =+($K17/2)*(1+SIGN(O$6*$K17-$C17)) -> 56.142675 | O17: =+MAX($C17,O$6*$K17) -> 396.82769 | P17: =+($K17/2)*(1+SIGN(Q$6*$K17-$C17)) -> 56.142675 | Q17: =+MAX($C17,Q$6*$K17) -> 396.82769
A18: Domain or Stratum 9 | B18: 1378 | C18: 250 | E18: =MAX(C18,C$4/C$5) -> 583.75 | F18: =+C$4*B18/B$9 -> 81.148364 | G18: =+C$4*J18/J$9 -> 264.20696 | H18: =+Q18 -> 262.38166 | J18: =+SQRT(B18) -> 37.121422 | K18: =+B18^C$6 -> 37.121422 | L18: =+($K18/2)*(1+SIGN(M$6*$K18-$C18)) -> 37.121422 | M18: =+MAX($C18,M$6*$K18) -> 264.20696 | N18: =+($K18/2)*(1+SIGN(O$6*$K18-$C18)) -> 37.121422 | O18: =+MAX($C18,O$6*$K18) -> 262.38166 | P18: =+($K18/2)*(1+SIGN(Q$6*$K18-$C18)) -> 37.121422 | Q18: =+MAX($C18,Q$6*$K18) -> 262.38166
A19: Domain or Stratum 10 | B19: 3225 | C19: 250 | E19: =MAX(C19,C$4/C$5) -> 583.75 | F19: =+C$4*B19/B$9 -> 189.91544 | G19: =+C$4*J19/J$9 -> 404.18901 | H19: =+Q19 -> 401.39663 | J19: =+SQRT(B19) -> 56.789083 | K19: =+B19^C$6 -> 56.789083 | L19: =+($K19/2)*(1+SIGN(M$6*$K19-$C19)) -> 56.789083 | M19: =+MAX($C19,M$6*$K19) -> 404.18901 | N19: =+($K19/2)*(1+SIGN(O$6*$K19-$C19)) -> 56.789083 | O19: =+MAX($C19,O$6*$K19) -> 401.39663 | P19: =+($K19/2)*(1+SIGN(Q$6*$K19-$C19)) -> 56.789083 | Q19: =+MAX($C19,Q$6*$K19) -> 401.39663
A20: Domain or Stratum 11 | B20: 574 | C20: 250 | E20: =MAX(C20,C$4/C$5) -> 583.75 | F20: =+C$4*B20/B$9 -> 33.802003 | G20: =+C$4*J20/J$9 -> 170.5201 | H20: =+Q20 -> 250 | J20: =+SQRT(B20) -> 23.958297 | K20: =+B20^C$6 -> 23.958297 | L20: =+($K20/2)*(1+SIGN(M$6*$K20-$C20)) -> 0 | M20: =+MAX($C20,M$6*$K20) -> 250 | N20: =+($K20/2)*(1+SIGN(O$6*$K20-$C20)) -> 0 | O20: =+MAX($C20,O$6*$K20) -> 250 | P20: =+($K20/2)*(1+SIGN(Q$6*$K20-$C20)) -> 0 | Q20: =+MAX($C20,Q$6*$K20) -> 250
A21: Domain or Stratum 12 | B21: 3447 | C21: 250 | E21: =MAX(C21,C$4/C$5) -> 583.75 | F21: =+C$4*B21/B$9 -> 202.98869 | G21: =+C$4*J21/J$9 -> 417.86912 | H21: =+Q21 -> 414.98223 | J21: =+SQRT(B21) -> 58.711157 | K21: =+B21^C$6 -> 58.711157 | L21: =+($K21/2)*(1+SIGN(M$6*$K21-$C21)) -> 58.711157 | M21: =+MAX($C21,M$6*$K21) -> 417.86912 | N21: =+($K21/2)*(1+SIGN(O$6*$K21-$C21)) -> 58.711157 | O21: =+MAX($C21,O$6*$K21) -> 414.98223 | P21: =+($K21/2)*(1+SIGN(Q$6*$K21-$C21)) -> 58.711157 | Q21: =+MAX($C21,Q$6*$K21) -> 414.98223
A22: Domain or Stratum 13 | B22: 3523 | C22: 250 | E22: =MAX(C22,C$4/C$5) -> 583.75 | F22: =+C$4*B22/B$9 -> 207.46421 | G22: =+C$4*J22/J$9 -> 422.45063 | H22: =+Q22 -> 419.53209 | J22: =+SQRT(B22) -> 59.354865 | K22: =+B22^C$6 -> 59.354865 | L22: =+($K22/2)*(1+SIGN(M$6*$K22-$C22)) -> 59.354865 | M22: =+MAX($C22,M$6*$K22) -> 422.45063 | N22: =+($K22/2)*(1+SIGN(O$6*$K22-$C22)) -> 59.354865 | O22: =+MAX($C22,O$6*$K22) -> 419.53209 | P22: =+($K22/2)*(1+SIGN(Q$6*$K22-$C22)) -> 59.354865 | Q22: =+MAX($C22,Q$6*$K22) -> 419.53209
... A29: Domain or Stratum 20 | B29: 14529 | C29: 250 | E29: =MAX(C29,C$4/C$5) -> 583.75 | F29: =+C$4*B29/B$9 -> 855.59113 | G29: =+C$4*J29/J$9 -> 857.90165 | H29: =+Q29 -> 851.97475 | J29: =+SQRT(B29) -> 120.5363 | K29: =+B29^C$6 -> 120.5363 | L29: =+($K29/2)*(1+SIGN(M$6*$K29-$C29)) -> 120.5363 | M29: =+MAX($C29,M$6*$K29) -> 857.90165 | N29: =+($K29/2)*(1+SIGN(O$6*$K29-$C29)) -> 120.5363 | O29: =+MAX($C29,O$6*$K29) -> 851.97475 | P29: =+($K29/2)*(1+SIGN(Q$6*$K29-$C29)) -> 120.5363 | Q29: =+MAX($C29,Q$6*$K29) -> 851.97475

Sheet PSU Selection
A1: SAMPLE SELECTION OF PSUs in given stratum or domain by systematic pps sampling | O1: This template is to assist you to select sample PSUs within a given stratum or domain by systematic random sampling with probabilities proportional to size. Two treatments of very large PSUs are incorporated: (1) Very large PSUs are divided into smaller virtual PSUs and (2) Very large PSUs are selected with probability one, self-represented PSUs. The results of treatment (1) are given in columns F to I and those of treatment (2) in columns J to M. More rows can be inserted as there are PSUs in the frame. Specify the sample size allocated for this stratum or domain in terms of number of households as well as the sample take per PSU as part of the input values. Specify also the total number of PSUs in the frame for this stratum or domain. Do not change the content of cells that are red and those that are within the intermediary calculations.
A3: INPUT VALUES | F3: OUTPUT VALUES | J3: OUTPUT VALUES | O3: INTERMEDIARY CALCULATIONS
A4: Total sample size in stratum/domain (number of households) | C4: 156 | D4: New random | F4: Effective sample size in stratum or domain | I4: =+I9 -> 160 | M4: =+M9 -> 160 | O4: Fixed-point algorithm (Newton's equation)
A5: Total number of PSUs in stratum/domain in frame | C5: =+COUNTA(A10:A2500) -> 134 | D5: start | F5: Number of sample PSU to be selected | I5: =+M5 -> 10 | M5: =+ROUND(C4/C6,0) -> 10 | O5: Iteration 1 | Q5: Iteration 2 | S5: Iteration 3
A6: Sample take per PSU (number of households) | C6: 16 | D6: =+RAND() -> 0.2977869 | F6: Selection (1): Virtual division of very large PSUs | J6: Selection (2):Automatic selection of very large PSUs | O6: k = | P6: =+M5/D9 -> 0.00074626866 | Q6: k = | R6: =+P6-(P9-$M5)/O9 -> 0.00083728719 | S6: k = | T6: =R6-(R9-$M5)/Q9 -> 0.00083728719
A7: Stratum or domain | B7: PSU code number | C7: Number of households | D7: Measure of PSU size | F7: Selection proportion | G7: Random value | H7: Sample | I7: Effective sample size | J7: Selection probability | K7: Random value | L7: Sample | M7: Effective sample size
A8: h | B8: i | C8: Ni | D8: xi | F8: pi | G8: =-D6 -> -0.2977869 | H8: si | I8: ni | J8: πi | K8: =-D6 -> -0.2977869 | L8: si | M8: ni | O8: f'(k) | P8: f(k) | Q8: f'(k) | R8: f(k) | S8: f'(k) | T8: f(k)
C9: =SUM(C10:C2500) -> 13400 | D9: =SUM(D10:D2500) -> 13400 | F9: =+SUM(F10:F2500) -> 10 | G9: =+SUM(G10:G2500) -> 718.27715 | H9: =+SUM(H10:H2500) -> 10 | I9: =+SUM(I10:I2500) -> 160 | J9: =+SUM(J10:J2500) -> 10 | K9: =+SUM(K10:K2500) -> 654.63354 | L9: =+SUM(L10:L2500) -> 10 | M9: =+SUM(M10:M2500) -> 160 | O9: =+SUM(O10:O2500)+V11+U9 -> 10749 | P9: =+SUM(P10:P2500) -> 9.0216418 | Q9: =+SUM(Q10:Q2500) -> 10749 | R9: =+SUM(R10:R2500) -> 10 | S9: =+SUM(S10:S2500) -> 10749 | T9: =+SUM(T10:T2500) -> 10
A10: Stratum or domain 1 | B10: PSU 1 | C10: =+D10 -> 31 | D10: 31 | F10: =+I$5*D10/D$9 -> 0.023134328 | G10: =+F10+G8 -> -0.27465257 | H10: =+INT(G10)-INT(G8) -> 0 | I10: =MIN(C10,H10*C$6) -> 0 | J10: =+T10 -> 0.025955903 | K10: =+J10+K8 -> -0.27183099 | L10: =+INT(K10)-INT(K8) -> 0 | M10: =MIN(C10,L10*C$6) -> 0 | O10: =+($D10/2)*(SIGN(1-P$6*$D10)+1) -> 31 | P10: =MIN(1,P$6*$D10) -> 0.023134328 | Q10: =+($D10/2)*(SIGN(1-R$6*$D10)+1) -> 31 | R10: =MIN(1,R$6*$D10) -> 0.025955903 | S10: =+($D10/2)*(SIGN(1-T$6*$D10)+1) -> 31 | T10: =MIN(1,T$6*$D10) -> 0.025955903
A11: Stratum or domain 1 | B11: PSU 2 | C11: =+D11 -> 71 | D11: 71 | F11: =+I$5*D11/D$9 -> 0.052985075 | G11: =+F11+G10 -> -0.22166749 | H11: =+INT(G11)-INT(G10) -> 0 | I11: =MIN(C11,H11*C$6) -> 0 | J11: =+T11 -> 0.05944739 | K11: =+J11+K10 -> -0.2123836 | L11: =+INT(K11)-INT(K10) -> 0 | M11: =MIN(C11,L11*C$6) -> 0 | O11: =+($D11/2)*(SIGN(1-P$6*$D11)+1) -> 71 | P11: =MIN(1,P$6*$D11) -> 0.052985075 | Q11: =+($D11/2)*(SIGN(1-R$6*$D11)+1) -> 71 | R11: =MIN(1,R$6*$D11) -> 0.05944739 | S11: =+($D11/2)*(SIGN(1-T$6*$D11)+1) -> 71 | T11: =MIN(1,T$6*$D11) -> 0.05944739
A12: Stratum or domain 1 | B12: PSU 3 | C12: =+D12 -> 211 | D12: 211 | F12: =+I$5*D12/D$9 -> 0.15746269 | G12: =+F12+G11 -> -0.064204806 | H12: =+INT(G12)-INT(G11) -> 0 | I12: =MIN(C12,H12*C$6) -> 0 | J12: =+T12 -> 0.1766676 | K12: =+J12+K11 -> -0.035716005 | L12: =+INT(K12)-INT(K11) -> 0 | M12: =MIN(C12,L12*C$6) -> 0 | O12: =+($D12/2)*(SIGN(1-P$6*$D12)+1) -> 211 | P12: =MIN(1,P$6*$D12) -> 0.15746269 | Q12: =+($D12/2)*(SIGN(1-R$6*$D12)+1) -> 211 | R12: =MIN(1,R$6*$D12) -> 0.1766676 | S12: =+($D12/2)*(SIGN(1-T$6*$D12)+1) -> 211 | T12: =MIN(1,T$6*$D12) -> 0.1766676
A13: Stratum or domain 1 | B13: PSU 4 | C13: =+D13 -> 23 | D13: 23 | F13: =+I$5*D13/D$9 -> 0.017164179 | G13: =+F13+G12 -> -0.047040627 | H13: =+INT(G13)-INT(G12) -> 0 | I13: =MIN(C13,H13*C$6) -> 0 | J13: =+T13 -> 0.019257605 | K13: =+J13+K12 -> -0.016458399 | L13: =+INT(K13)-INT(K12) -> 0 | M13: =MIN(C13,L13*C$6) -> 0 | O13: =+($D13/2)*(SIGN(1-P$6*$D13)+1) -> 23 | P13: =MIN(1,P$6*$D13) -> 0.017164179 | Q13: =+($D13/2)*(SIGN(1-R$6*$D13)+1) -> 23 | R13: =MIN(1,R$6*$D13) -> 0.019257605 | S13: =+($D13/2)*(SIGN(1-T$6*$D13)+1) -> 23 | T13: =MIN(1,T$6*$D13) -> 0.019257605
A14: Stratum or domain 1 | B14: PSU 5 | C14: =+D14 -> 151 | D14: 151 | F14: =+I$5*D14/D$9 -> 0.11268657 | G14: =+F14+G13 -> 0.065645941 | H14: =+INT(G14)-INT(G13) -> 1 | I14: =MIN(C14,H14*C$6) -> 16 | J14: =+T14 -> 0.12643037 | K14: =+J14+K13 -> 0.10997197 | L14: =+INT(K14)-INT(K13) -> 1 | M14: =MIN(C14,L14*C$6) -> 16 | O14: =+($D14/2)*(SIGN(1-P$6*$D14)+1) -> 151 | P14: =MIN(1,P$6*$D14) -> 0.11268657 | Q14: =+($D14/2)*(SIGN(1-R$6*$D14)+1) -> 151 | R14: =MIN(1,R$6*$D14) -> 0.12643037 | S14: =+($D14/2)*(SIGN(1-T$6*$D14)+1) -> 151 | T14: =MIN(1,T$6*$D14) -> 0.12643037
A15: Stratum or domain 1 | B15: PSU 6 | C15: =+D15 -> 74 | D15: 74 | F15: =+I$5*D15/D$9 -> 0.055223881 | G15: =+F15+G14 -> 0.12086982 | H15: =+INT(G15)-INT(G14) -> 0 | I15: =MIN(C15,H15*C$6) -> 0 | J15: =+T15 -> 0.061959252 | K15: =+J15+K14 -> 0.17193122 | L15: =+INT(K15)-INT(K14) -> 0 | M15: =MIN(C15,L15*C$6) -> 0 | O15: =+($D15/2)*(SIGN(1-P$6*$D15)+1) -> 74 | P15: =MIN(1,P$6*$D15) -> 0.055223881 | Q15: =+($D15/2)*(SIGN(1-R$6*$D15)+1) -> 74 | R15: =MIN(1,R$6*$D15) -> 0.061959252 | S15: =+($D15/2)*(SIGN(1-T$6*$D15)+1) -> 74 | T15: =MIN(1,T$6*$D15) -> 0.061959252
A16: Stratum or domain 1 | B16: PSU 7 | C16: =+D16 -> 2651 | D16: 2651 | F16: =+I$5*D16/D$9 -> 1.9783582 | G16: =+F16+G15 -> 2.099228 | H16: =+INT(G16)-INT(G15) -> 2 | I16: =MIN(C16,H16*C$6) -> 32 | J16: =+T16 -> 1 | K16: =+J16+K15 -> 1.1719312 | L16: =+INT(K16)-INT(K15) -> 1 | M16: =MIN(C16,L16*C$6) -> 16 | O16: =+($D16/2)*(SIGN(1-P$6*$D16)+1) -> 0 | P16: =MIN(1,P$6*$D16) -> 1 | Q16: =+($D16/2)*(SIGN(1-R$6*$D16)+1) -> 0 | R16: =MIN(1,R$6*$D16) -> 1 | S16: =+($D16/2)*(SIGN(1-T$6*$D16)+1) -> 0 | T16: =MIN(1,T$6*$D16) -> 1
A17: Stratum or domain 1 | B17: PSU 8 | C17: =+D17 -> 64 | D17: 64 | F17: =+I$5*D17/D$9 -> 0.047761194 | G17: =+F17+G16 -> 2.1469892 | H17: =+INT(G17)-INT(G16) -> 0 | I17: =MIN(C17,H17*C$6) -> 0 | J17: =+T17 -> 0.05358638 | K17: =+J17+K16 -> 1.2255176 | L17: =+INT(K17)-INT(K16) -> 0 | M17: =MIN(C17,L17*C$6) -> 0 | O17: =+($D17/2)*(SIGN(1-P$6*$D17)+1) -> 64 | P17: =MIN(1,P$6*$D17) -> 0.047761194 | Q17: =+($D17/2)*(SIGN(1-R$6*$D17)+1) -> 64 | R17: =MIN(1,R$6*$D17) -> 0.05358638 | S17: =+($D17/2)*(SIGN(1-T$6*$D17)+1) -> 64 | T17: =MIN(1,T$6*$D17) -> 0.05358638
A18: Stratum or domain 1 | B18: PSU 9 | C18: =+D18 -> 107 | D18: 107 | F18: =+I$5*D18/D$9 -> 0.079850746 | G18: =+F18+G17 -> 2.22684 | H18: =+INT(G18)-INT(G17) -> 0 | I18: =MIN(C18,H18*C$6) -> 0 | J18: =+T18 -> 0.089589729 | K18: =+J18+K17 -> 1.3151073 | L18: =+INT(K18)-INT(K17) -> 0 | M18: =MIN(C18,L18*C$6) -> 0 | O18: =+($D18/2)*(SIGN(1-P$6*$D18)+1) -> 107 | P18: =MIN(1,P$6*$D18) -> 0.079850746 | Q18: =+($D18/2)*(SIGN(1-R$6*$D18)+1) -> 107 | R18: =MIN(1,R$6*$D18) -> 0.089589729 | S18: =+($D18/2)*(SIGN(1-T$6*$D18)+1) -> 107 | T18: =MIN(1,T$6*$D18) -> 0.089589729
A19: Stratum or domain 1 | B19: PSU 10 | C19: =+D19 -> 102 | D19: 102 | F19: =+I$5*D19/D$9 -> 0.076119403 | G19: =+F19+G18 -> 2.3029594 | H19: =+INT(G19)-INT(G18) -> 0 | I19: =MIN(C19,H19*C$6) -> 0 | J19: =+T19 -> 0.085403293 | K19: =+J19+K18 -> 1.4005106 | L19: =+INT(K19)-INT(K18) -> 0 | M19: =MIN(C19,L19*C$6) -> 0 | O19: =+($D19/2)*(SIGN(1-P$6*$D19)+1) -> 102 | P19: =MIN(1,P$6*$D19) -> 0.076119403 | Q19: =+($D19/2)*(SIGN(1-R$6*$D19)+1) -> 102 | R19: =MIN(1,R$6*$D19) -> 0.085403293 | S19: =+($D19/2)*(SIGN(1-T$6*$D19)+1) -> 102 | T19: =MIN(1,T$6*$D19) -> 0.085403293
A20: Stratum or domain 1 | B20: PSU 11 | C20: =+D20 -> 12 | D20: 12 | F20: =+I$5*D20/D$9 -> 0.0089552239 | G20: =+F20+G19 -> 2.3119146 | H20: =+INT(G20)-INT(G19) -> 0 | I20: =MIN(C20,H20*C$6) -> 0 | J20: =+T20 -> 0.010047446 | K20: =+J20+K19 -> 1.4105581 | L20: =+INT(K20)-INT(K19) -> 0 | M20: =MIN(C20,L20*C$6) -> 0 | O20: =+($D20/2)*(SIGN(1-P$6*$D20)+1) -> 12 | P20: =MIN(1,P$6*$D20) -> 0.0089552239 | Q20: =+($D20/2)*(SIGN(1-R$6*$D20)+1) -> 12 | R20: =MIN(1,R$6*$D20) -> 0.010047446 | S20: =+($D20/2)*(SIGN(1-T$6*$D20)+1) -> 12 | T20: =MIN(1,T$6*$D20) -> 0.010047446
A21: Stratum or domain 1 | B21: PSU 12 | C21: =+D21 -> 60 | D21: 60 | F21: =+I$5*D21/D$9 -> 0.044776119 | G21: =+F21+G20 -> 2.3566907 | H21: =+INT(G21)-INT(G20) -> 0 | I21: =MIN(C21,H21*C$6) -> 0 | J21: =+T21 -> 0.050237231 | K21: =+J21+K20 -> 1.4607953 | L21: =+INT(K21)-INT(K20) -> 0 | M21: =MIN(C21,L21*C$6) -> 0 | O21: =+($D21/2)*(SIGN(1-P$6*$D21)+1) -> 60 | P21: =MIN(1,P$6*$D21) -> 0.044776119 | Q21: =+($D21/2)*(SIGN(1-R$6*$D21)+1) -> 60 | R21: =MIN(1,R$6*$D21) -> 0.050237231 | S21: =+($D21/2)*(SIGN(1-T$6*$D21)+1) -> 60 | T21: =MIN(1,T$6*$D21) -> 0.050237231
A22: Stratum or domain 1 | B22: PSU 13 | C22: =+D22 -> 71 | D22: 71 | F22: =+I$5*D22/D$9 -> 0.052985075 | G22: =+F22+G21 -> 2.4096758 | H22: =+INT(G22)-INT(G21) -> 0 | I22: =MIN(C22,H22*C$6) -> 0 | J22: =+T22 -> 0.05944739 | K22: =+J22+K21 -> 1.5202427 | L22: =+INT(K22)-INT(K21) -> 0 | M22: =MIN(C22,L22*C$6) -> 0 | O22: =+($D22/2)*(SIGN(1-P$6*$D22)+1) -> 71 | P22: =MIN(1,P$6*$D22) -> 0.052985075 | Q22: =+($D22/2)*(SIGN(1-R$6*$D22)+1) -> 71 | R22: =MIN(1,R$6*$D22) -> 0.05944739 | S22: =+($D22/2)*(SIGN(1-T$6*$D22)+1) -> 71 | T22: =MIN(1,T$6*$D22) -> 0.05944739
... A143: Stratum or domain 1 | B143: PSU 134 | C143: =+D143 -> 60 | D143: 60 | F143: =+I$5*D143/D$9 -> 0.044776119 | G143: =+F143+G142 -> 9.7022131 | H143: =+INT(G143)-INT(G142) -> 0 | I143: =MIN(C143,H143*C$6) -> 0 | J143: =+T143 -> 0.050237231 | K143: =+J143+K142 -> 9.7022131 | L143: =+INT(K143)-INT(K142) -> 0 | M143: =MIN(C143,L143*C$6) -> 0 | O143: =+($D143/2)*(SIGN(1-P$6*$D143)+1) -> 60 | P143: =MIN(1,P$6*$D143) -> 0.044776119 | Q143: =+($D143/2)*(SIGN(1-R$6*$D143)+1) -> 60 | R143: =MIN(1,R$6*$D143) -> 0.050237231 | S143: =+($D143/2)*(SIGN(1-T$6*$D143)+1) -> 60 | T143: =MIN(1,T$6*$D143) -> 0.050237231

Sheet PSU Listing
A1: SAMPLE PSU LISTING and SAMPLE SELECTION OF HOUSEHOLDS | AN1: lambda | AO1: 1
AN2: p | AO2: 0.2
A3: INPUT VALUES | L3: OUTPUT VALUES | V3: INTERMEDIARY CALCULATIONS | AN3: correl | AO3: 0
A4: Input parameters | L4: Design 1 | O4: Design 2 | R4: Design 3 | V4: Design 1 | Z4: Design 2 | AE4: Design 3 | AN4: lambda*p | AO4: =+AO1*AO2+AO1*(AO1-1)*AO3*AO2 -> 0.2
C5: b = | D5: 15 | E5: alpha C = | F5: -1 | G5: random = | H5: 0.318383 | L5: Sampling all listed households | O5: Sampling only households with children (5-17 years old) | R5: Stratified sampling of households with children and with working children | AN5: (1-e-lampd) | AO5: =IF(AO4=0,1,1-EXP(-AO4)) -> 0.18126925
A6: Input data | V6: Number of A-hslds in PSU | W6: Selection probability of A-HSLD | X6: random | Y6: sample A | Z6: Stratum B | AA6: Number of B-hslds in PSU | AB6: Selection probability of B-HSLD | AE6: Stratum C | AF6: Number of hslds in PSU in C-stratra | AG6: Allocation of sample-take b | AH6: Selection probability of C-HSLD | AN6: sigma2 | AO6: =+(AO5*(AO4+AO4^2)-AO4^2)/(AO5^2) -> 0.10665779
A7: Stratum or domain | B7: Sample PSU id no. | C7: Buiding serial no. | D7: Dwelling serial no. | E7: Household serial no. | F7: Name | G7: Address | H7: A | I7: B | J7: C | L7: Strata A | M7: Probability HSLD | N7: Sample A | O7: Strata B | P7: Probability HSLD | Q7: Sample B | R7: Strata C | S7: Probability HSLD | T7: Sample C | AC7: random | AD7: sample B | AI7: random | AJ7: sample C | AN7: n | AO7: N | AP7: Nd | AQ7: (1-f) | AR7: (1-fd) | AS7: Var1 | AT7: Var2 | AU7: gain var | AV7: gain stdev
E8: =COUNT(H9:H99999) -> 208 | H8: =+SUM(H9:H99999) -> 847 | I8: =+SUM(I9:I99999) -> 149 | J8: =+SUM(J9:J99999) -> 17 | L8: =SUMPRODUCT($N9:$N9999,I9:I9999) -> 29 | M8: =SUMPRODUCT($N9:$N9999,J9:J9999) -> 3 | N8: =SUM(N9:N99999) -> 42 | O8: =SUMPRODUCT($Q9:$Q9999,I9:I9999) -> 37 | P8: =SUMPRODUCT($Q9:$Q9999,J9:J9999) -> 4 | Q8: =SUM(Q9:Q99999) -> 37 | R8: =+SUMPRODUCT($T9:$T9999,I9:I9999) -> 37 | S8: =+SUMPRODUCT($T9:$T9999,J9:J9999) -> 17 | T8: =+SUM(T9:T99999) -> 37 | W8: =SUM(W9:W99999) -> 42 | X8: =-$H$5 -> -0.318383 | Y8: =SUM(Y9:Y99999) -> 42 | AB8: =SUM(AB9:AB99999) -> 37 | AC8: =-$H$5 -> -0.318383 | AD8: =SUM(AD9:AD99999) -> 37 | AI8: =-$H$5 -> -0.318383 | AJ8: =SUM(AJ9:AJ99999) -> 37 | AN8: =+SUM(AN9:AN9999) -> 42.576803 | AO8: =+SUM(AO9:AO9999) -> 213.80084 | AP8: =+SUM(AP9:AP9999) -> 155.09583 | AS8: =+SUM(AS9:AS11) -> 235.28762 | AT8: =+SUM(AT9:AT11) -> 62.231265 | AU8: =IF(AS8=0,0,1-AT8/AS8) -> 0.73550982 | AV8: =IF(AS8=0,0,1-SQRT(AT8)/SQRT(AS8)) -> 0.48571391
A9: Stratum 1 | B9: PSU 1 | C9: 1 | D9: 1 | E9: 1 | F9: AA BB | G9: CC DDDD | H9: 2 | I9: 1 | J9: 1 | L9: 1 | M9: =+W9 -> 0.20547945 | N9: =+IF(Y9=1,Y9,"") | O9: =+Z9 -> 1 | P9: =+AB9 -> 0.29411765 | Q9: =IF(AD9=1,AD9,"") | R9: =+AE9 -> 2 | S9: =+AH9 -> 1 | T9: =IF(AJ9=1,AJ9,"") -> 1 | V9: =IF(B9=B8,V8,COUNTIFS(B:B,B9,H:H,">0")) -> 73 | W9: =+MIN(1,$D$5/V9) -> 0.20547945 | X9: =+W9+X8 -> -0.11290355 | Y9: =+INT(X9)-INT(X8) -> 0 | Z9: =1*(I9>0) -> 1 | AA9: =IF(B9=B8,AA8,COUNTIFS(B:B,B9,I:I,">0")) -> 51 | AB9: =+I9*MIN(1,$D$5/AA9) -> 0.29411765 | AC9: =+AB9+AC8 -> -0.024265353 | AD9: =+INT(AC9)-INT(AC8) -> 0 | AE9: =+(J9>0)+(I9>0) -> 2 | AF9: =+COUNTIFS(B:B,B9,AE:AE,AE9) -> 6 | AG9: =IF(OR(AF9=0,AE9=0),0,IF(AE9=2,ROUND(MIN($D$5*(AF9^$F$5)/(AF9^$F$5+(AA9-AF9)^$F$5),AF9),0),IF(AF9=0,0,MIN($D$5,AA9)-IF(AA9=AF9,0,ROUND(MIN((AE9>0)*$D$5*((AA9-AF9)^$F$5)/((AA9-AF9)^$F$5+AF9^$F$5),AA9-AF9),0))))) -> 6 | AH9: =+MIN(1,AG9/AF9) -> 1 | AI9: =+AH9+AI8 -> 0.681617 | AJ9: =+INT(AI9)-INT(AI8) -> 1 | AL9: =IF(AE9=1,IF(AF9=0,0,MIN($D$5,AA9)-IF(AA9=AF9,0,ROUND(MIN((AE9>0)*$D$5*((AA9-AF9)^$F$5)/((AA9-AF9)^$F$5+AF9^$F$5),AA9-AF9),0))),"") | AM9: PSU 1 | AN9: =+SUMIF($B:$B,$AM9,Q:Q) -> 15 | AO9: =+COUNTIF($B:$B,$AM9) -> 73 | AP9: =+COUNTIFS($B:$B,$AM9,I:I,">0") -> 51 | AQ9: =+(1-$AN9/AO9) -> 0.79452055 | AR9: =+(1-$AN9/AP9) -> 0.70588235 | AS9: =+(AO9^2)*AQ9*$AO$4/$AN9 -> 56.453333 | AT9: =+(AP9^2)*AR9*$AO$6/$AN9 -> 13.054914 | AU9: =IF(AS9=0,0,1-AT9/AS9) -> 0.76874858 | AV9: =IF(AS9=0,0,1-SQRT(AT9)/SQRT(AS9)) -> 0.51911392
A10: Stratum 1 | B10: PSU 1 | C10: =+C9+1 -> 2 | D10: =1+D9 -> 2 | E10: =1+E9 -> 2 | F10: AA BB | G10: CC DDDD | H10: 4 | I10: 1 | J10: 1 | L10: 1 | M10: =+W10 -> 0.20547945 | N10: =+IF(Y10=1,Y10,"") -> 1 | O10: =+Z10 -> 1 | P10: =+AB10 -> 0.29411765 | Q10: =IF(AD10=1,AD10,"") -> 1 | R10: =+AE10 -> 2 | S10: =+AH10 -> 1 | T10: =IF(AJ10=1,AJ10,"") -> 1 | V10: =+IF(B10=B9,V9,COUNTIFS(B:B,B10,H:H,">0")) -> 73 | W10: =+MIN(1,$D$5/V10) -> 0.20547945 | X10: =+W10+X9 -> 0.092575904 | Y10: =+INT(X10)-INT(X9) -> 1 | Z10: =1*(I10>0) -> 1 | AA10: =IF(B10=B9,AA9,COUNTIFS(B:B,B10,I:I,">0")) -> 51 | AB10: =+I10*MIN(1,$D$5/AA10) -> 0.29411765 | AC10: =+AB10+AC9 -> 0.26985229 | AD10: =+INT(AC10)-INT(AC9) -> 1 | AE10: =+(J10>0)+(I10>0) -> 2 | AF10: =+COUNTIFS(B:B,B10,AE:AE,AE10) -> 6 | AG10: =IF(OR(AF10=0,AE10=0),0,IF(AE10=2,ROUND(MIN($D$5*(AF10^$F$5)/(AF10^$F$5+(AA10-AF10)^$F$5),AF10),0),IF(AF10=0,0,MIN($D$5,AA10)-IF(AA10=AF10,0,ROUND(MIN((AE10>0)*$D$5*((AA10-AF10)^$F$5)/((AA10-AF10)^$F$5+AF10^$F$5),AA10-AF10),0))))) -> 6 | AH10: =+MIN(1,AG10/AF10) -> 1 | AI10: =+AH10+AI9 -> 1.681617 | AJ10: =+INT(AI10)-INT(AI9) -> 1 | AL10: =IF(AE10=1,IF(AF10=0,0,MIN($D$5,AA10)-IF(AA10=AF10,0,ROUND(MIN((AE10>0)*$D$5*((AA10-AF10)^$F$5)/((AA10-AF10)^$F$5+AF10^$F$5),AA10-AF10),0))),"") | AM10: PSU 2 | AN10: =+SUMIF($B:$B,$AM10,Q:Q) -> 7 | AO10: =+COUNTIF($B:$B,$AM10) -> 12 | AP10: =+COUNTIFS($B:$B,$AM10,I:I,">0") -> 7 | AQ10: =+(1-$AN10/AO10) -> 0.41666667 | AR10: =+(1-$AN10/AP10) -> 0 | AS10: =+(AO10^2)*AQ10*$AO$4/$AN10 -> 1.7142857 | AT10: =+(AP10^2)*AR10*$AO$6/$AN10 -> 0 | AU10: =IF(AS10=0,0,1-AT10/AS10) -> 1 | AV10: =IF(AS10=0,0,1-SQRT(AT10)/SQRT(AS10)) -> 1
A11: Stratum 1 | B11: PSU 1 | C11: =+C10+1 -> 3 | D11: =1+D10 -> 3 | E11: =1+E10 -> 3 | F11: AA BB | G11: CC DDDD | H11: 7 | I11: 1 | J11: 1 | L11: 1 | M11: =+W11 -> 0.20547945 | N11: =+IF(Y11=1,Y11,"") | O11: =+Z11 -> 1 | P11: =+AB11 -> 0.29411765 | Q11: =IF(AD11=1,AD11,"") | R11: =+AE11 -> 2 | S11: =+AH11 -> 1 | T11: =IF(AJ11=1,AJ11,"") -> 1 | V11: =+IF(B11=B10,V10,COUNTIFS(B:B,B11,H:H,">0")) -> 73 | W11: =+MIN(1,$D$5/V11) -> 0.20547945 | X11: =+W11+X10 -> 0.29805536 | Y11: =+INT(X11)-INT(X10) -> 0 | Z11: =1*(I11>0) -> 1 | AA11: =IF(B11=B10,AA10,COUNTIFS(B:B,B11,I:I,">0")) -> 51 | AB11: =+I11*MIN(1,$D$5/AA11) -> 0.29411765 | AC11: =+AB11+AC10 -> 0.56396994 | AD11: =+INT(AC11)-INT(AC10) -> 0 | AE11: =+(J11>0)+(I11>0) -> 2 | AF11: =+COUNTIFS(B:B,B11,AE:AE,AE11) -> 6 | AG11: =IF(OR(AF11=0,AE11=0),0,IF(AE11=2,ROUND(MIN($D$5*(AF11^$F$5)/(AF11^$F$5+(AA11-AF11)^$F$5),AF11),0),IF(AF11=0,0,MIN($D$5,AA11)-IF(AA11=AF11,0,ROUND(MIN((AE11>0)*$D$5*((AA11-AF11)^$F$5)/((AA11-AF11)^$F$5+AF11^$F$5),AA11-AF11),0))))) -> 6 | AH11: =+MIN(1,AG11/AF11) -> 1 | AI11: =+AH11+AI10 -> 2.681617 | AJ11: =+INT(AI11)-INT(AI10) -> 1 | AL11: =IF(AE11=1,IF(AF11=0,0,MIN($D$5,AA11)-IF(AA11=AF11,0,ROUND(MIN((AE11>0)*$D$5*((AA11-AF11)^$F$5)/((AA11-AF11)^$F$5+AF11^$F$5),AA11-AF11),0))),"") | AM11: PSU 3 | AN11: =+SUMIF($B:$B,$AM11,Q:Q) -> 15 | AO11: =+COUNTIF($B:$B,$AM11) -> 123 | AP11: =+COUNTIFS($B:$B,$AM11,I:I,">0") -> 91 | AQ11: =+(1-$AN11/AO11) -> 0.87804878 | AR11: =+(1-$AN11/AP11) -> 0.83516484 | AS11: =+(AO11^2)*AQ11*$AO$4/$AN11 -> 177.12 | AT11: =+(AP11^2)*AR11*$AO$6/$AN11 -> 49.176352 | AU11: =IF(AS11=0,0,1-AT11/AS11) -> 0.72235574 | AV11: =IF(AS11=0,0,1-SQRT(AT11)/SQRT(AS11)) -> 0.4730804
A12: Stratum 1 | B12: PSU 1 | C12: 3 | D12: 3 | E12: =1+E11 -> 4 | F12: AA BB | G12: CC DDDD | H12: 2 | I12: 1 | J12: 1 | L12: 1 | M12: =+W12 -> 0.20547945 | N12: =+IF(Y12=1,Y12,"") | O12: =+Z12 -> 1 | P12: =+AB12 -> 0.29411765 | Q12: =IF(AD12=1,AD12,"") | R12: =+AE12 -> 2 | S12: =+AH12 -> 1 | T12: =IF(AJ12=1,AJ12,"") -> 1 | V12: =+IF(B12=B11,V11,COUNTIFS(B:B,B12,H:H,">0")) -> 73 | W12: =+MIN(1,$D$5/V12) -> 0.20547945 | X12: =+W12+X11 -> 0.50353481 | Y12: =+INT(X12)-INT(X11) -> 0 | Z12: =1*(I12>0) -> 1 | AA12: =IF(B12=B11,AA11,COUNTIFS(B:B,B12,I:I,">0")) -> 51 | AB12: =+I12*MIN(1,$D$5/AA12) -> 0.29411765 | AC12: =+AB12+AC11 -> 0.85808759 | AD12: =+INT(AC12)-INT(AC11) -> 0 | AE12: =+(J12>0)+(I12>0) -> 2 | AF12: =+COUNTIFS(B:B,B12,AE:AE,AE12) -> 6 | AG12: =IF(OR(AF12=0,AE12=0),0,IF(AE12=2,ROUND(MIN($D$5*(AF12^$F$5)/(AF12^$F$5+(AA12-AF12)^$F$5),AF12),0),IF(AF12=0,0,MIN($D$5,AA12)-IF(AA12=AF12,0,ROUND(MIN((AE12>0)*$D$5*((AA12-AF12)^$F$5)/((AA12-AF12)^$F$5+AF12^$F$5),AA12-AF12),0))))) -> 6 | AH12: =+MIN(1,AG12/AF12) -> 1 | AI12: =+AH12+AI11 -> 3.681617 | AJ12: =+INT(AI12)-INT(AI11) -> 1 | AL12: =IF(AE12=1,IF(AF12=0,0,MIN($D$5,AA12)-IF(AA12=AF12,0,ROUND(MIN((AE12>0)*$D$5*((AA12-AF12)^$F$5)/((AA12-AF12)^$F$5+AF12^$F$5),AA12-AF12),0))),"")
A13: Stratum 1 | B13: PSU 1 | C13: =+C12+1 -> 4 | D13: =1+D12 -> 4 | E13: =1+E12 -> 5 | F13: AA BB | G13: CC DDDD | H13: 5 | I13: 1 | J13: 1 | L13: 1 | M13: =+W13 -> 0.20547945 | N13: =+IF(Y13=1,Y13,"") | O13: =+Z13 -> 1 | P13: =+AB13 -> 0.29411765 | Q13: =IF(AD13=1,AD13,"") -> 1 | R13: =+AE13 -> 2 | S13: =+AH13 -> 1 | T13: =IF(AJ13=1,AJ13,"") -> 1 | V13: =+IF(B13=B12,V12,COUNTIFS(B:B,B13,H:H,">0")) -> 73 | W13: =+MIN(1,$D$5/V13) -> 0.20547945 | X13: =+W13+X12 -> 0.70901426 | Y13: =+INT(X13)-INT(X12) -> 0 | Z13: =1*(I13>0) -> 1 | AA13: =IF(B13=B12,AA12,COUNTIFS(B:B,B13,I:I,">0")) -> 51 | AB13: =+I13*MIN(1,$D$5/AA13) -> 0.29411765 | AC13: =+AB13+AC12 -> 1.1522052 | AD13: =+INT(AC13)-INT(AC12) -> 1 | AE13: =+(J13>0)+(I13>0) -> 2 | AF13: =+COUNTIFS(B:B,B13,AE:AE,AE13) -> 6 | AG13: =IF(OR(AF13=0,AE13=0),0,IF(AE13=2,ROUND(MIN($D$5*(AF13^$F$5)/(AF13^$F$5+(AA13-AF13)^$F$5),AF13),0),IF(AF13=0,0,MIN($D$5,AA13)-IF(AA13=AF13,0,ROUND(MIN((AE13>0)*$D$5*((AA13-AF13)^$F$5)/((AA13-AF13)^$F$5+AF13^$F$5),AA13-AF13),0))))) -> 6 | AH13: =+MIN(1,AG13/AF13) -> 1 | AI13: =+AH13+AI12 -> 4.681617 | AJ13: =+INT(AI13)-INT(AI12) -> 1 | AL13: =IF(AE13=1,IF(AF13=0,0,MIN($D$5,AA13)-IF(AA13=AF13,0,ROUND(MIN((AE13>0)*$D$5*((AA13-AF13)^$F$5)/((AA13-AF13)^$F$5+AF13^$F$5),AA13-AF13),0))),"")
A14: Stratum 1 | B14: PSU 1 | C14: 5 | D14: =1+D13 -> 5 | E14: =1+E13 -> 6 | F14: AA BB | G14: CC DDDD | H14: 6 | I14: 1 | J14: 1 | L14: 1 | M14: =+W14 -> 0.20547945 | N14: =+IF(Y14=1,Y14,"") | O14: =+Z14 -> 1 | P14: =+AB14 -> 0.29411765 | Q14: =IF(AD14=1,AD14,"") | R14: =+AE14 -> 2 | S14: =+AH14 -> 1 | T14: =IF(AJ14=1,AJ14,"") -> 1 | V14: =+IF(B14=B13,V13,COUNTIFS(B:B,B14,H:H,">0")) -> 73 | W14: =+MIN(1,$D$5/V14) -> 0.20547945 | X14: =+W14+X13 -> 0.91449371 | Y14: =+INT(X14)-INT(X13) -> 0 | Z14: =1*(I14>0) -> 1 | AA14: =IF(B14=B13,AA13,COUNTIFS(B:B,B14,I:I,">0")) -> 51 | AB14: =+I14*MIN(1,$D$5/AA14) -> 0.29411765 | AC14: =+AB14+AC13 -> 1.4463229 | AD14: =+INT(AC14)-INT(AC13) -> 0 | AE14: =+(J14>0)+(I14>0) -> 2 | AF14: =+COUNTIFS(B:B,B14,AE:AE,AE14) -> 6 | AG14: =IF(OR(AF14=0,AE14=0),0,IF(AE14=2,ROUND(MIN($D$5*(AF14^$F$5)/(AF14^$F$5+(AA14-AF14)^$F$5),AF14),0),IF(AF14=0,0,MIN($D$5,AA14)-IF(AA14=AF14,0,ROUND(MIN((AE14>0)*$D$5*((AA14-AF14)^$F$5)/((AA14-AF14)^$F$5+AF14^$F$5),AA14-AF14),0))))) -> 6 | AH14: =+MIN(1,AG14/AF14) -> 1 | AI14: =+AH14+AI13 -> 5.681617 | AJ14: =+INT(AI14)-INT(AI13) -> 1 | AL14: =IF(AE14=1,IF(AF14=0,0,MIN($D$5,AA14)-IF(AA14=AF14,0,ROUND(MIN((AE14>0)*$D$5*((AA14-AF14)^$F$5)/((AA14-AF14)^$F$5+AF14^$F$5),AA14-AF14),0))),"") | AM14: Efficiency of design 2 (sampling only households with children identified during listing)
A15: Stratum 1 | B15: PSU 1 | C15: 5 | D15: =1+D14 -> 6 | E15: =1+E14 -> 7 | F15: AA BB | G15: CC DDDD | H15: 5 | I15: 1 | J15: 0 | L15: 1 | M15: =+W15 -> 0.20547945 | N15: =+IF(Y15=1,Y15,"") -> 1 | O15: =+Z15 -> 1 | P15: =+AB15 -> 0.29411765 | Q15: =IF(AD15=1,AD15,"") | R15: =+AE15 -> 1 | S15: =+AH15 -> 0.2 | T15: =IF(AJ15=1,AJ15,"") | V15: =+IF(B15=B14,V14,COUNTIFS(B:B,B15,H:H,">0")) -> 73 | W15: =+MIN(1,$D$5/V15) -> 0.20547945 | X15: =+W15+X14 -> 1.1199732 | Y15: =+INT(X15)-INT(X14) -> 1 | Z15: =1*(I15>0) -> 1 | AA15: =IF(B15=B14,AA14,COUNTIFS(B:B,B15,I:I,">0")) -> 51 | AB15: =+I15*MIN(1,$D$5/AA15) -> 0.29411765 | AC15: =+AB15+AC14 -> 1.7404405 | AD15: =+INT(AC15)-INT(AC14) -> 0 | AE15: =+(J15>0)+(I15>0) -> 1 | AF15: =+COUNTIFS(B:B,B15,AE:AE,AE15) -> 45 | AG15: =IF(OR(AF15=0,AE15=0),0,IF(AE15=2,ROUND(MIN($D$5*(AF15^$F$5)/(AF15^$F$5+(AA15-AF15)^$F$5),AF15),0),IF(AF15=0,0,MIN($D$5,AA15)-IF(AA15=AF15,0,ROUND(MIN((AE15>0)*$D$5*((AA15-AF15)^$F$5)/((AA15-AF15)^$F$5+AF15^$F$5),AA15-AF15),0))))) -> 9 | AH15: =+MIN(1,AG15/AF15) -> 0.2 | AI15: =+AH15+AI14 -> 5.881617 | AJ15: =+INT(AI15)-INT(AI14) -> 0 | AM15: Average gain in standard error of estimate of percentage of children in child labour
A16: Stratum 1 | B16: PSU 1 | C16: =+C15+1 -> 6 | D16: =1+D15 -> 7 | E16: =1+E15 -> 8 | F16: AA BB | G16: CC DDDD | H16: 3 | I16: 1 | J16: 0 | L16: 1 | M16: =+W16 -> 0.20547945 | N16: =+IF(Y16=1,Y16,"") | O16: =+Z16 -> 1 | P16: =+AB16 -> 0.29411765 | Q16: =IF(AD16=1,AD16,"") -> 1 | R16: =+AE16 -> 1 | S16: =+AH16 -> 0.2 | T16: =IF(AJ16=1,AJ16,"") -> 1 | V16: =+IF(B16=B15,V15,COUNTIFS(B:B,B16,H:H,">0")) -> 73 | W16: =+MIN(1,$D$5/V16) -> 0.20547945 | X16: =+W16+X15 -> 1.3254526 | Y16: =+INT(X16)-INT(X15) -> 0 | Z16: =1*(I16>0) -> 1 | AA16: =IF(B16=B15,AA15,COUNTIFS(B:B,B16,I:I,">0")) -> 51 | AB16: =+I16*MIN(1,$D$5/AA16) -> 0.29411765 | AC16: =+AB16+AC15 -> 2.0345582 | AD16: =+INT(AC16)-INT(AC15) -> 1 | AE16: =+(J16>0)+(I16>0) -> 1 | AF16: =+COUNTIFS(B:B,B16,AE:AE,AE16) -> 45 | AG16: =IF(OR(AF16=0,AE16=0),0,IF(AE16=2,ROUND(MIN($D$5*(AF16^$F$5)/(AF16^$F$5+(AA16-AF16)^$F$5),AF16),0),IF(AF16=0,0,MIN($D$5,AA16)-IF(AA16=AF16,0,ROUND(MIN((AE16>0)*$D$5*((AA16-AF16)^$F$5)/((AA16-AF16)^$F$5+AF16^$F$5),AA16-AF16),0))))) -> 9 | AH16: =+MIN(1,AG16/AF16) -> 0.2 | AI16: =+AH16+AI15 -> 6.081617 | AJ16: =+INT(AI16)-INT(AI15) -> 1 | AM16: Numerical illustration: Three PSUs with 208 households, 149 households with children
A17: Stratum 1 | B17: PSU 1 | C17: =+C16+1 -> 7 | D17: =1+D16 -> 8 | E17: =1+E16 -> 9 | F17: AA BB | G17: CC DDDD | H17: 1 | I17: 1 | J17: 0 | L17: 1 | M17: =+W17 -> 0.20547945 | N17: =+IF(Y17=1,Y17,"") | O17: =+Z17 -> 1 | P17: =+AB17 -> 0.29411765 | Q17: =IF(AD17=1,AD17,"") | R17: =+AE17 -> 1 | S17: =+AH17 -> 0.2 | T17: =IF(AJ17=1,AJ17,"") | V17: =+IF(B17=B16,V16,COUNTIFS(B:B,B17,H:H,">0")) -> 73 | W17: =+MIN(1,$D$5/V17) -> 0.20547945 | X17: =+W17+X16 -> 1.5309321 | Y17: =+INT(X17)-INT(X16) -> 0 | Z17: =1*(I17>0) -> 1 | AA17: =IF(B17=B16,AA16,COUNTIFS(B:B,B17,I:I,">0")) -> 51 | AB17: =+I17*MIN(1,$D$5/AA17) -> 0.29411765 | AC17: =+AB17+AC16 -> 2.3286758 | AD17: =+INT(AC17)-INT(AC16) -> 0 | AE17: =+(J17>0)+(I17>0) -> 1 | AF17: =+COUNTIFS(B:B,B17,AE:AE,AE17) -> 45 | AG17: =IF(OR(AF17=0,AE17=0),0,IF(AE17=2,ROUND(MIN($D$5*(AF17^$F$5)/(AF17^$F$5+(AA17-AF17)^$F$5),AF17),0),IF(AF17=0,0,MIN($D$5,AA17)-IF(AA17=AF17,0,ROUND(MIN((AE17>0)*$D$5*((AA17-AF17)^$F$5)/((AA17-AF17)^$F$5+AF17^$F$5),AA17-AF17),0))))) -> 9 | AH17: =+MIN(1,AG17/AF17) -> 0.2 | AI17: =+AH17+AI16 -> 6.281617 | AJ17: =+INT(AI17)-INT(AI16) -> 0 | AM17: % children in child labour (p) | AN17: No correlation within household (ρ=0) | AT17: Full correlation within household (ρ=1)
A18: Stratum 1 | B18: PSU 1 | C18: 7 | D18: 8 | E18: =1+E17 -> 10 | F18: AA BB | G18: CC DDDD | H18: 7 | I18: 1 | J18: 0 | L18: 1 | M18: =+W18 -> 0.20547945 | N18: =+IF(Y18=1,Y18,"") | O18: =+Z18 -> 1 | P18: =+AB18 -> 0.29411765 | Q18: =IF(AD18=1,AD18,"") | R18: =+AE18 -> 1 | S18: =+AH18 -> 0.2 | T18: =IF(AJ18=1,AJ18,"") | V18: =+IF(B18=B17,V17,COUNTIFS(B:B,B18,H:H,">0")) -> 73 | W18: =+MIN(1,$D$5/V18) -> 0.20547945 | X18: =+W18+X17 -> 1.7364115 | Y18: =+INT(X18)-INT(X17) -> 0 | Z18: =1*(I18>0) -> 1 | AA18: =IF(B18=B17,AA17,COUNTIFS(B:B,B18,I:I,">0")) -> 51 | AB18: =+I18*MIN(1,$D$5/AA18) -> 0.29411765 | AC18: =+AB18+AC17 -> 2.6227935 | AD18: =+INT(AC18)-INT(AC17) -> 0 | AE18: =+(J18>0)+(I18>0) -> 1 | AF18: =+COUNTIFS(B:B,B18,AE:AE,AE18) -> 45 | AG18: =IF(OR(AF18=0,AE18=0),0,IF(AE18=2,ROUND(MIN($D$5*(AF18^$F$5)/(AF18^$F$5+(AA18-AF18)^$F$5),AF18),0),IF(AF18=0,0,MIN($D$5,AA18)-IF(AA18=AF18,0,ROUND(MIN((AE18>0)*$D$5*((AA18-AF18)^$F$5)/((AA18-AF18)^$F$5+AF18^$F$5),AA18-AF18),0))))) -> 9 | AH18: =+MIN(1,AG18/AF18) -> 0.2 | AI18: =+AH18+AI17 -> 6.481617 | AJ18: =+INT(AI18)-INT(AI17) -> 0 | AN18: Average number of children per hsld (λ) | AT18: Average number of children per hsld (λ)
A19: Stratum 1 | B19: PSU 1 | C19: =+C18+1 -> 8 | D19: =1+D18 -> 9 | E19: =1+E18 -> 11 | F19: AA BB | G19: CC DDDD | H19: 7 | I19: 1 | J19: 0 | L19: 1 | M19: =+W19 -> 0.20547945 | N19: =+IF(Y19=1,Y19,"") | O19: =+Z19 -> 1 | P19: =+AB19 -> 0.29411765 | Q19: =IF(AD19=1,AD19,"") | R19: =+AE19 -> 1 | S19: =+AH19 -> 0.2 | T19: =IF(AJ19=1,AJ19,"") | V19: =+IF(B19=B18,V18,COUNTIFS(B:B,B19,H:H,">0")) -> 73 | W19: =+MIN(1,$D$5/V19) -> 0.20547945 | X19: =+W19+X18 -> 1.941891 | Y19: =+INT(X19)-INT(X18) -> 0 | Z19: =1*(I19>0) -> 1 | AA19: =IF(B19=B18,AA18,COUNTIFS(B:B,B19,I:I,">0")) -> 51 | AB19: =+I19*MIN(1,$D$5/AA19) -> 0.29411765 | AC19: =+AB19+AC18 -> 2.9169111 | AD19: =+INT(AC19)-INT(AC18) -> 0 | AE19: =+(J19>0)+(I19>0) -> 1 | AF19: =+COUNTIFS(B:B,B19,AE:AE,AE19) -> 45 | AG19: =IF(OR(AF19=0,AE19=0),0,IF(AE19=2,ROUND(MIN($D$5*(AF19^$F$5)/(AF19^$F$5+(AA19-AF19)^$F$5),AF19),0),IF(AF19=0,0,MIN($D$5,AA19)-IF(AA19=AF19,0,ROUND(MIN((AE19>0)*$D$5*((AA19-AF19)^$F$5)/((AA19-AF19)^$F$5+AF19^$F$5),AA19-AF19),0))))) -> 9 | AH19: =+MIN(1,AG19/AF19) -> 0.2 | AI19: =+AH19+AI18 -> 6.681617 | AJ19: =+INT(AI19)-INT(AI18) -> 0 | AN19: 0.1 | AO19: 0.5 | AP19: 1 | AQ19: 1.5 | AR19: 2 | AT19: 0.1 | AU19: 0.5 | AV19: 1 | AW19: 1.5 | AX19: 2
A20: Stratum 1 | B20: PSU 1 | C20: =+C19+1 -> 9 | D20: =1+D19 -> 10 | E20: =1+E19 -> 12 | F20: AA BB | G20: CC DDDD | H20: 1 | I20: 1 | J20: 0 | L20: 1 | M20: =+W20 -> 0.20547945 | N20: =+IF(Y20=1,Y20,"") -> 1 | O20: =+Z20 -> 1 | P20: =+AB20 -> 0.29411765 | Q20: =IF(AD20=1,AD20,"") -> 1 | R20: =+AE20 -> 1 | S20: =+AH20 -> 0.2 | T20: =IF(AJ20=1,AJ20,"") | V20: =+IF(B20=B19,V19,COUNTIFS(B:B,B20,H:H,">0")) -> 73 | W20: =+MIN(1,$D$5/V20) -> 0.20547945 | X20: =+W20+X19 -> 2.1473704 | Y20: =+INT(X20)-INT(X19) -> 1 | Z20: =1*(I20>0) -> 1 | AA20: =IF(B20=B19,AA19,COUNTIFS(B:B,B20,I:I,">0")) -> 51 | AB20: =+I20*MIN(1,$D$5/AA20) -> 0.29411765 | AC20: =+AB20+AC19 -> 3.2110288 | AD20: =+INT(AC20)-INT(AC19) -> 1 | AE20: =+(J20>0)+(I20>0) -> 1 | AF20: =+COUNTIFS(B:B,B20,AE:AE,AE20) -> 45 | AG20: =IF(OR(AF20=0,AE20=0),0,IF(AE20=2,ROUND(MIN($D$5*(AF20^$F$5)/(AF20^$F$5+(AA20-AF20)^$F$5),AF20),0),IF(AF20=0,0,MIN($D$5,AA20)-IF(AA20=AF20,0,ROUND(MIN((AE20>0)*$D$5*((AA20-AF20)^$F$5)/((AA20-AF20)^$F$5+AF20^$F$5),AA20-AF20),0))))) -> 9 | AH20: =+MIN(1,AG20/AF20) -> 0.2 | AI20: =+AH20+AI19 -> 6.881617 | AJ20: =+INT(AI20)-INT(AI19) -> 0 | AM20: 0.01 | AN20: 0.50194092 | AO20: 0.50160911 | AP20: 0.50119465 | AQ20: 0.50078054 | AR20: 0.50036677 | AT20: 0.50202091 | AU20: 0.50181647 | AV20: 0.50119465 | AW20: 0.50016002 | AX20: 0.49871524
A21: Stratum 1 | B21: PSU 1 | C21: 10 | D21: =1+D20 -> 11 | E21: =1+E20 -> 13 | F21: AA BB | G21: CC DDDD | H21: 4 | I21: 1 | J21: 0 | L21: 1 | M21: =+W21 -> 0.20547945 | N21: =+IF(Y21=1,Y21,"") | O21: =+Z21 -> 1 | P21: =+AB21 -> 0.29411765 | Q21: =IF(AD21=1,AD21,"") | R21: =+AE21 -> 1 | S21: =+AH21 -> 0.2 | T21: =IF(AJ21=1,AJ21,"") -> 1 | V21: =+IF(B21=B20,V20,COUNTIFS(B:B,B21,H:H,">0")) -> 73 | W21: =+MIN(1,$D$5/V21) -> 0.20547945 | X21: =+W21+X20 -> 2.3528499 | Y21: =+INT(X21)-INT(X20) -> 0 | Z21: =1*(I21>0) -> 1 | AA21: =IF(B21=B20,AA20,COUNTIFS(B:B,B21,I:I,">0")) -> 51 | AB21: =+I21*MIN(1,$D$5/AA21) -> 0.29411765 | AC21: =+AB21+AC20 -> 3.5051464 | AD21: =+INT(AC21)-INT(AC20) -> 0 | AE21: =+(J21>0)+(I21>0) -> 1 | AF21: =+COUNTIFS(B:B,B21,AE:AE,AE21) -> 45 | AG21: =IF(OR(AF21=0,AE21=0),0,IF(AE21=2,ROUND(MIN($D$5*(AF21^$F$5)/(AF21^$F$5+(AA21-AF21)^$F$5),AF21),0),IF(AF21=0,0,MIN($D$5,AA21)-IF(AA21=AF21,0,ROUND(MIN((AE21>0)*$D$5*((AA21-AF21)^$F$5)/((AA21-AF21)^$F$5+AF21^$F$5),AA21-AF21),0))))) -> 9 | AH21: =+MIN(1,AG21/AF21) -> 0.2 | AI21: =+AH21+AI20 -> 7.081617 | AJ21: =+INT(AI21)-INT(AI20) -> 1 | AM21: 0.1 | AN21: 0.50119465 | AO21: 0.4978916 | AP21: 0.49379507 | AQ21: 0.48973546 | AR21: 0.48571391 | AT21: 0.50194092 | AU21: 0.49995336 | AV21: 0.49379507 | AW21: 0.48371774 | AX21: 0.47002937
A22: Stratum 1 | B22: PSU 1 | C22: 10 | D22: =1+D21 -> 12 | E22: =1+E21 -> 14 | F22: AA BB | G22: CC DDDD | H22: 6 | I22: 1 | J22: 0 | L22: 1 | M22: =+W22 -> 0.20547945 | N22: =+IF(Y22=1,Y22,"") | O22: =+Z22 -> 1 | P22: =+AB22 -> 0.29411765 | Q22: =IF(AD22=1,AD22,"") | R22: =+AE22 -> 1 | S22: =+AH22 -> 0.2 | T22: =IF(AJ22=1,AJ22,"") | V22: =+IF(B22=B21,V21,COUNTIFS(B:B,B22,H:H,">0")) -> 73 | W22: =+MIN(1,$D$5/V22) -> 0.20547945 | X22: =+W22+X21 -> 2.5583293 | Y22: =+INT(X22)-INT(X21) -> 0 | Z22: =1*(I22>0) -> 1 | AA22: =IF(B22=B21,AA21,COUNTIFS(B:B,B22,I:I,">0")) -> 51 | AB22: =+I22*MIN(1,$D$5/AA22) -> 0.29411765 | AC22: =+AB22+AC21 -> 3.7992641 | AD22: =+INT(AC22)-INT(AC21) -> 0 | AE22: =+(J22>0)+(I22>0) -> 1 | AF22: =+COUNTIFS(B:B,B22,AE:AE,AE22) -> 45 | AG22: =IF(OR(AF22=0,AE22=0),0,IF(AE22=2,ROUND(MIN($D$5*(AF22^$F$5)/(AF22^$F$5+(AA22-AF22)^$F$5),AF22),0),IF(AF22=0,0,MIN($D$5,AA22)-IF(AA22=AF22,0,ROUND(MIN((AE22>0)*$D$5*((AA22-AF22)^$F$5)/((AA22-AF22)^$F$5+AF22^$F$5),AA22-AF22),0))))) -> 9 | AH22: =+MIN(1,AG22/AF22) -> 0.2 | AI22: =+AH22+AI21 -> 7.281617 | AJ22: =+INT(AI22)-INT(AI21) -> 0 | AM22: 0.2 | AN22: 0.50036677 | AO22: 0.49379507 | AP22: 0.48571391 | AQ22: 0.47778927 | AR22: 0.47002937 | AT22: 0.50185795 | AU22: 0.4978916 | AV22: 0.48571391 | AW22: 0.46621359 | AX22: 0.44077816
A23: Stratum 1 | B23: PSU 1 | C23: 10 | D23: =1+D22 -> 13 | E23: =1+E22 -> 15 | F23: AA BB | G23: CC DDDD | H23: 2 | I23: 1 | J23: 0 | L23: 1 | M23: =+W23 -> 0.20547945 | N23: =+IF(Y23=1,Y23,"") | O23: =+Z23 -> 1 | P23: =+AB23 -> 0.29411765 | Q23: =IF(AD23=1,AD23,"") -> 1 | R23: =+AE23 -> 1 | S23: =+AH23 -> 0.2 | T23: =IF(AJ23=1,AJ23,"") | V23: =+IF(B23=B22,V22,COUNTIFS(B:B,B23,H:H,">0")) -> 73 | W23: =+MIN(1,$D$5/V23) -> 0.20547945 | X23: =+W23+X22 -> 2.7638088 | Y23: =+INT(X23)-INT(X22) -> 0 | Z23: =1*(I23>0) -> 1 | AA23: =IF(B23=B22,AA22,COUNTIFS(B:B,B23,I:I,">0")) -> 51 | AB23: =+I23*MIN(1,$D$5/AA23) -> 0.29411765 | AC23: =+AB23+AC22 -> 4.0933817 | AD23: =+INT(AC23)-INT(AC22) -> 1 | AE23: =+(J23>0)+(I23>0) -> 1 | AF23: =+COUNTIFS(B:B,B23,AE:AE,AE23) -> 45 | AG23: =IF(OR(AF23=0,AE23=0),0,IF(AE23=2,ROUND(MIN($D$5*(AF23^$F$5)/(AF23^$F$5+(AA23-AF23)^$F$5),AF23),0),IF(AF23=0,0,MIN($D$5,AA23)-IF(AA23=AF23,0,ROUND(MIN((AE23>0)*$D$5*((AA23-AF23)^$F$5)/((AA23-AF23)^$F$5+AF23^$F$5),AA23-AF23),0))))) -> 9 | AH23: =+MIN(1,AG23/AF23) -> 0.2 | AI23: =+AH23+AI22 -> 7.481617 | AJ23: =+INT(AI23)-INT(AI22) -> 0 | AM23: 0.3 | AN23: 0.4995403 | AO23: 0.48973546 | AP23: 0.47778927 | AQ23: 0.46621359 | AR23: 0.45503337 | AT23: 0.50177499 | AU23: 0.49583879 | AV23: 0.47778927 | AW23: 0.44959841 | AX23: 0.41464143
A24: Stratum 1 | B24: PSU 1 | C24: 10 | D24: =1+D23 -> 14 | E24: =1+E23 -> 16 | F24: AA BB | G24: CC DDDD | H24: 1 | I24: 1 | J24: 0 | L24: 1 | M24: =+W24 -> 0.20547945 | N24: =+IF(Y24=1,Y24,"") | O24: =+Z24 -> 1 | P24: =+AB24 -> 0.29411765 | Q24: =IF(AD24=1,AD24,"") | R24: =+AE24 -> 1 | S24: =+AH24 -> 0.2 | T24: =IF(AJ24=1,AJ24,"") | V24: =+IF(B24=B23,V23,COUNTIFS(B:B,B24,H:H,">0")) -> 73 | W24: =+MIN(1,$D$5/V24) -> 0.20547945 | X24: =+W24+X23 -> 2.9692882 | Y24: =+INT(X24)-INT(X23) -> 0 | Z24: =1*(I24>0) -> 1 | AA24: =IF(B24=B23,AA23,COUNTIFS(B:B,B24,I:I,">0")) -> 51 | AB24: =+I24*MIN(1,$D$5/AA24) -> 0.29411765 | AC24: =+AB24+AC23 -> 4.3874994 | AD24: =+INT(AC24)-INT(AC23) -> 0 | AE24: =+(J24>0)+(I24>0) -> 1 | AF24: =+COUNTIFS(B:B,B24,AE:AE,AE24) -> 45 | AG24: =IF(OR(AF24=0,AE24=0),0,IF(AE24=2,ROUND(MIN($D$5*(AF24^$F$5)/(AF24^$F$5+(AA24-AF24)^$F$5),AF24),0),IF(AF24=0,0,MIN($D$5,AA24)-IF(AA24=AF24,0,ROUND(MIN((AE24>0)*$D$5*((AA24-AF24)^$F$5)/((AA24-AF24)^$F$5+AF24^$F$5),AA24-AF24),0))))) -> 9 | AH24: =+MIN(1,AG24/AF24) -> 0.2 | AI24: =+AH24+AI23 -> 7.681617 | AJ24: =+INT(AI24)-INT(AI23) -> 0 | AM24: 0.4 | AN24: 0.49871524 | AO24: 0.48571391 | AP24: 0.47002937 | AQ24: 0.45503337 | AR24: 0.44077816 | AT24: 0.50169204 | AU24: 0.49379507 | AV24: 0.47002937 | AW24: 0.43394154 | AX24: 0.39180527
A25: Stratum 1 | B25: PSU 1 | C25: 10 | D25: =1+D24 -> 15 | E25: =1+E24 -> 17 | F25: AA BB | G25: CC DDDD | H25: 6 | I25: 1 | J25: 0 | L25: 1 | M25: =+W25 -> 0.20547945 | N25: =+IF(Y25=1,Y25,"") -> 1 | O25: =+Z25 -> 1 | P25: =+AB25 -> 0.29411765 | Q25: =IF(AD25=1,AD25,"") | R25: =+AE25 -> 1 | S25: =+AH25 -> 0.2 | T25: =IF(AJ25=1,AJ25,"") | V25: =+IF(B25=B24,V24,COUNTIFS(B:B,B25,H:H,">0")) -> 73 | W25: =+MIN(1,$D$5/V25) -> 0.20547945 | X25: =+W25+X24 -> 3.1747677 | Y25: =+INT(X25)-INT(X24) -> 1 | Z25: =1*(I25>0) -> 1 | AA25: =IF(B25=B24,AA24,COUNTIFS(B:B,B25,I:I,">0")) -> 51 | AB25: =+I25*MIN(1,$D$5/AA25) -> 0.29411765 | AC25: =+AB25+AC24 -> 4.681617 | AD25: =+INT(AC25)-INT(AC24) -> 0 | AE25: =+(J25>0)+(I25>0) -> 1 | AF25: =+COUNTIFS(B:B,B25,AE:AE,AE25) -> 45 | AG25: =IF(OR(AF25=0,AE25=0),0,IF(AE25=2,ROUND(MIN($D$5*(AF25^$F$5)/(AF25^$F$5+(AA25-AF25)^$F$5),AF25),0),IF(AF25=0,0,MIN($D$5,AA25)-IF(AA25=AF25,0,ROUND(MIN((AE25>0)*$D$5*((AA25-AF25)^$F$5)/((AA25-AF25)^$F$5+AF25^$F$5),AA25-AF25),0))))) -> 9 | AH25: =+MIN(1,AG25/AF25) -> 0.2 | AI25: =+AH25+AI24 -> 7.881617 | AJ25: =+INT(AI25)-INT(AI24) -> 0 | AM25: 0.5 | AN25: 0.4978916 | AO25: 0.4817315 | AP25: 0.46244177 | AQ25: 0.44427008 | AR25: 0.4273045 | AT25: 0.50160911 | AU25: 0.49176058 | AV25: 0.46244177 | AW25: 0.41929374 | AX25: 0.37227875
A26: Stratum 1 | B26: PSU 1 | C26: =+C25+1 -> 11 | D26: =1+D25 -> 16 | E26: =1+E25 -> 18 | F26: AA BB | G26: CC DDDD | H26: 3 | I26: 1 | J26: 0 | L26: 1 | M26: =+W26 -> 0.20547945 | N26: =+IF(Y26=1,Y26,"") | O26: =+Z26 -> 1 | P26: =+AB26 -> 0.29411765 | Q26: =IF(AD26=1,AD26,"") | R26: =+AE26 -> 1 | S26: =+AH26 -> 0.2 | T26: =IF(AJ26=1,AJ26,"") -> 1 | V26: =+IF(B26=B25,V25,COUNTIFS(B:B,B26,H:H,">0")) -> 73 | W26: =+MIN(1,$D$5/V26) -> 0.20547945 | X26: =+W26+X25 -> 3.3802471 | Y26: =+INT(X26)-INT(X25) -> 0 | Z26: =1*(I26>0) -> 1 | AA26: =IF(B26=B25,AA25,COUNTIFS(B:B,B26,I:I,">0")) -> 51 | AB26: =+I26*MIN(1,$D$5/AA26) -> 0.29411765 | AC26: =+AB26+AC25 -> 4.9757346 | AD26: =+INT(AC26)-INT(AC25) -> 0 | AE26: =+(J26>0)+(I26>0) -> 1 | AF26: =+COUNTIFS(B:B,B26,AE:AE,AE26) -> 45 | AG26: =IF(OR(AF26=0,AE26=0),0,IF(AE26=2,ROUND(MIN($D$5*(AF26^$F$5)/(AF26^$F$5+(AA26-AF26)^$F$5),AF26),0),IF(AF26=0,0,MIN($D$5,AA26)-IF(AA26=AF26,0,ROUND(MIN((AE26>0)*$D$5*((AA26-AF26)^$F$5)/((AA26-AF26)^$F$5+AF26^$F$5),AA26-AF26),0))))) -> 9 | AH26: =+MIN(1,AG26/AF26) -> 0.2 | AI26: =+AH26+AI25 -> 8.081617 | AJ26: =+INT(AI26)-INT(AI25) -> 1 | AM26: 0.6 | AN26: 0.4970694 | AO26: 0.47778927 | AP26: 0.45503337 | AQ26: 0.43394154 | AR26: 0.41464143 | AT26: 0.50152619 | AU26: 0.48973546 | AV26: 0.45503337 | AW26: 0.40568694 | AX26: 0.3559205
A27: Stratum 1 | B27: PSU 1 | C27: =+C26+1 -> 12 | D27: =1+D26 -> 17 | E27: =1+E26 -> 19 | F27: AA BB | G27: CC DDDD | H27: 3 | I27: 1 | J27: 0 | L27: 1 | M27: =+W27 -> 0.20547945 | N27: =+IF(Y27=1,Y27,"") | O27: =+Z27 -> 1 | P27: =+AB27 -> 0.29411765 | Q27: =IF(AD27=1,AD27,"") -> 1 | R27: =+AE27 -> 1 | S27: =+AH27 -> 0.2 | T27: =IF(AJ27=1,AJ27,"") | V27: =+IF(B27=B26,V26,COUNTIFS(B:B,B27,H:H,">0")) -> 73 | W27: =+MIN(1,$D$5/V27) -> 0.20547945 | X27: =+W27+X26 -> 3.5857266 | Y27: =+INT(X27)-INT(X26) -> 0 | Z27: =1*(I27>0) -> 1 | AA27: =IF(B27=B26,AA26,COUNTIFS(B:B,B27,I:I,">0")) -> 51 | AB27: =+I27*MIN(1,$D$5/AA27) -> 0.29411765 | AC27: =+AB27+AC26 -> 5.2698523 | AD27: =+INT(AC27)-INT(AC26) -> 1 | AE27: =+(J27>0)+(I27>0) -> 1 | AF27: =+COUNTIFS(B:B,B27,AE:AE,AE27) -> 45 | AG27: =IF(OR(AF27=0,AE27=0),0,IF(AE27=2,ROUND(MIN($D$5*(AF27^$F$5)/(AF27^$F$5+(AA27-AF27)^$F$5),AF27),0),IF(AF27=0,0,MIN($D$5,AA27)-IF(AA27=AF27,0,ROUND(MIN((AE27>0)*$D$5*((AA27-AF27)^$F$5)/((AA27-AF27)^$F$5+AF27^$F$5),AA27-AF27),0))))) -> 9 | AH27: =+MIN(1,AG27/AF27) -> 0.2 | AI27: =+AH27+AI26 -> 8.281617 | AJ27: =+INT(AI27)-INT(AI26) -> 0 | AM27: 0.7 | AN27: 0.49624863 | AO27: 0.47388824 | AP27: 0.44781034 | AQ27: 0.42406187 | AR27: 0.4028063 | AT27: 0.50144328 | AU27: 0.48771986 | AV27: 0.44781034 | AW27: 0.39313484 | AX27: 0.34247672
A28: Stratum 1 | B28: PSU 1 | C28: =+C27+1 -> 13 | D28: =1+D27 -> 18 | E28: =1+E27 -> 20 | F28: AA BB | G28: CC DDDD | H28: 5 | I28: 1 | J28: 0 | L28: 1 | M28: =+W28 -> 0.20547945 | N28: =+IF(Y28=1,Y28,"") | O28: =+Z28 -> 1 | P28: =+AB28 -> 0.29411765 | Q28: =IF(AD28=1,AD28,"") | R28: =+AE28 -> 1 | S28: =+AH28 -> 0.2 | T28: =IF(AJ28=1,AJ28,"") | V28: =+IF(B28=B27,V27,COUNTIFS(B:B,B28,H:H,">0")) -> 73 | W28: =+MIN(1,$D$5/V28) -> 0.20547945 | X28: =+W28+X27 -> 3.791206 | Y28: =+INT(X28)-INT(X27) -> 0 | Z28: =1*(I28>0) -> 1 | AA28: =IF(B28=B27,AA27,COUNTIFS(B:B,B28,I:I,">0")) -> 51 | AB28: =+I28*MIN(1,$D$5/AA28) -> 0.29411765 | AC28: =+AB28+AC27 -> 5.5639699 | AD28: =+INT(AC28)-INT(AC27) -> 0 | AE28: =+(J28>0)+(I28>0) -> 1 | AF28: =+COUNTIFS(B:B,B28,AE:AE,AE28) -> 45 | AG28: =IF(OR(AF28=0,AE28=0),0,IF(AE28=2,ROUND(MIN($D$5*(AF28^$F$5)/(AF28^$F$5+(AA28-AF28)^$F$5),AF28),0),IF(AF28=0,0,MIN($D$5,AA28)-IF(AA28=AF28,0,ROUND(MIN((AE28>0)*$D$5*((AA28-AF28)^$F$5)/((AA28-AF28)^$F$5+AF28^$F$5),AA28-AF28),0))))) -> 9 | AH28: =+MIN(1,AG28/AF28) -> 0.2 | AI28: =+AH28+AI27 -> 8.481617 | AJ28: =+INT(AI28)-INT(AI27) -> 0 | AM28: 0.8 | AN28: 0.49542931 | AO28: 0.47002937 | AP28: 0.44077816 | AQ28: 0.41464143 | AR28: 0.39180527 | AT28: 0.50136039 | AU28: 0.48571391 | AV28: 0.44077816 | AW28: 0.38163403 | AX28: 0.33162262
A29: Stratum 1 | B29: PSU 1 | C29: =+C28+1 -> 14 | D29: =1+D28 -> 19 | E29: =1+E28 -> 21 | F29: AA BB | G29: CC DDDD | H29: 1 | I29: 1 | J29: 0 | L29: 1 | M29: =+W29 -> 0.20547945 | N29: =+IF(Y29=1,Y29,"") | O29: =+Z29 -> 1 | P29: =+AB29 -> 0.29411765 | Q29: =IF(AD29=1,AD29,"") | R29: =+AE29 -> 1 | S29: =+AH29 -> 0.2 | T29: =IF(AJ29=1,AJ29,"") | V29: =+IF(B29=B28,V28,COUNTIFS(B:B,B29,H:H,">0")) -> 73 | W29: =+MIN(1,$D$5/V29) -> 0.20547945 | X29: =+W29+X28 -> 3.9966855 | Y29: =+INT(X29)-INT(X28) -> 0 | Z29: =1*(I29>0) -> 1 | AA29: =IF(B29=B28,AA28,COUNTIFS(B:B,B29,I:I,">0")) -> 51 | AB29: =+I29*MIN(1,$D$5/AA29) -> 0.29411765 | AC29: =+AB29+AC28 -> 5.8580876 | AD29: =+INT(AC29)-INT(AC28) -> 0 | AE29: =+(J29>0)+(I29>0) -> 1 | AF29: =+COUNTIFS(B:B,B29,AE:AE,AE29) -> 45 | AG29: =IF(OR(AF29=0,AE29=0),0,IF(AE29=2,ROUND(MIN($D$5*(AF29^$F$5)/(AF29^$F$5+(AA29-AF29)^$F$5),AF29),0),IF(AF29=0,0,MIN($D$5,AA29)-IF(AA29=AF29,0,ROUND(MIN((AE29>0)*$D$5*((AA29-AF29)^$F$5)/((AA29-AF29)^$F$5+AF29^$F$5),AA29-AF29),0))))) -> 9 | AH29: =+MIN(1,AG29/AF29) -> 0.2 | AI29: =+AH29+AI28 -> 8.681617 | AJ29: =+INT(AI29)-INT(AI28) -> 0 | AM29: 0.9 | AN29: 0.49461146 | AO29: 0.46621359 | AP29: 0.43394154 | AQ29: 0.40568694 | AR29: 0.38163403 | AT29: 0.50127751 | AU29: 0.48371774 | AV29: 0.43394154 | AW29: 0.37116569 | AX29: 0.32300088
A30: Stratum 1 | B30: PSU 1 | C30: =+C29+1 -> 15 | D30: =1+D29 -> 20 | E30: =1+E29 -> 22 | F30: AA BB | G30: CC DDDD | H30: 2 | I30: 1 | J30: 0 | L30: 1 | M30: =+W30 -> 0.20547945 | N30: =+IF(Y30=1,Y30,"") -> 1 | O30: =+Z30 -> 1 | P30: =+AB30 -> 0.29411765 | Q30: =IF(AD30=1,AD30,"") -> 1 | R30: =+AE30 -> 1 | S30: =+AH30 -> 0.2 | T30: =IF(AJ30=1,AJ30,"") | V30: =+IF(B30=B29,V29,COUNTIFS(B:B,B30,H:H,">0")) -> 73 | W30: =+MIN(1,$D$5/V30) -> 0.20547945 | X30: =+W30+X29 -> 4.2021649 | Y30: =+INT(X30)-INT(X29) -> 1 | Z30: =1*(I30>0) -> 1 | AA30: =IF(B30=B29,AA29,COUNTIFS(B:B,B30,I:I,">0")) -> 51 | AB30: =+I30*MIN(1,$D$5/AA30) -> 0.29411765 | AC30: =+AB30+AC29 -> 6.1522052 | AD30: =+INT(AC30)-INT(AC29) -> 1 | AE30: =+(J30>0)+(I30>0) -> 1 | AF30: =+COUNTIFS(B:B,B30,AE:AE,AE30) -> 45 | AG30: =IF(OR(AF30=0,AE30=0),0,IF(AE30=2,ROUND(MIN($D$5*(AF30^$F$5)/(AF30^$F$5+(AA30-AF30)^$F$5),AF30),0),IF(AF30=0,0,MIN($D$5,AA30)-IF(AA30=AF30,0,ROUND(MIN((AE30>0)*$D$5*((AA30-AF30)^$F$5)/((AA30-AF30)^$F$5+AF30^$F$5),AA30-AF30),0))))) -> 9 | AH30: =+MIN(1,AG30/AF30) -> 0.2 | AI30: =+AH30+AI29 -> 8.881617 | AJ30: =+INT(AI30)-INT(AI29) -> 0 | AM30: 1 | AN30: 0.49379507 | AO30: 0.46244177 | AP30: 0.4273045 | AQ30: 0.39720156 | AR30: 0.37227875 | AT30: 0.50119465 | AU30: 0.4817315 | AV30: 0.4273045 | AW30: 0.3616977 | AX30: 0.31625307
A31: Stratum 1 | B31: PSU 1 | C31: =+C30+1 -> 16 | D31: =1+D30 -> 21 | E31: =1+E30 -> 23 | F31: AA BB | G31: CC DDDD | H31: 7 | I31: 1 | J31: 0 | L31: 1 | M31: =+W31 -> 0.20547945 | N31: =+IF(Y31=1,Y31,"") | O31: =+Z31 -> 1 | P31: =+AB31 -> 0.29411765 | Q31: =IF(AD31=1,AD31,"") | R31: =+AE31 -> 1 | S31: =+AH31 -> 0.2 | T31: =IF(AJ31=1,AJ31,"") -> 1 | V31: =+IF(B31=B30,V30,COUNTIFS(B:B,B31,H:H,">0")) -> 73 | W31: =+MIN(1,$D$5/V31) -> 0.20547945 | X31: =+W31+X30 -> 4.4076444 | Y31: =+INT(X31)-INT(X30) -> 0 | Z31: =1*(I31>0) -> 1 | AA31: =IF(B31=B30,AA30,COUNTIFS(B:B,B31,I:I,">0")) -> 51 | AB31: =+I31*MIN(1,$D$5/AA31) -> 0.29411765 | AC31: =+AB31+AC30 -> 6.4463229 | AD31: =+INT(AC31)-INT(AC30) -> 0 | AE31: =+(J31>0)+(I31>0) -> 1 | AF31: =+COUNTIFS(B:B,B31,AE:AE,AE31) -> 45 | AG31: =IF(OR(AF31=0,AE31=0),0,IF(AE31=2,ROUND(MIN($D$5*(AF31^$F$5)/(AF31^$F$5+(AA31-AF31)^$F$5),AF31),0),IF(AF31=0,0,MIN($D$5,AA31)-IF(AA31=AF31,0,ROUND(MIN((AE31>0)*$D$5*((AA31-AF31)^$F$5)/((AA31-AF31)^$F$5+AF31^$F$5),AA31-AF31),0))))) -> 9 | AH31: =+MIN(1,AG31/AF31) -> 0.2 | AI31: =+AH31+AI30 -> 9.081617 | AJ31: =+INT(AI31)-INT(AI30) -> 1
A32: Stratum 1 | B32: PSU 1 | C32: =+C31+1 -> 17 | D32: =1+D31 -> 22 | E32: =1+E31 -> 24 | F32: AA BB | G32: CC DDDD | H32: 4 | I32: 1 | J32: 0 | L32: 1 | M32: =+W32 -> 0.20547945 | N32: =+IF(Y32=1,Y32,"") | O32: =+Z32 -> 1 | P32: =+AB32 -> 0.29411765 | Q32: =IF(AD32=1,AD32,"") | R32: =+AE32 -> 1 | S32: =+AH32 -> 0.2 | T32: =IF(AJ32=1,AJ32,"") | V32: =+IF(B32=B31,V31,COUNTIFS(B:B,B32,H:H,">0")) -> 73 | W32: =+MIN(1,$D$5/V32) -> 0.20547945 | X32: =+W32+X31 -> 4.6131238 | Y32: =+INT(X32)-INT(X31) -> 0 | Z32: =1*(I32>0) -> 1 | AA32: =IF(B32=B31,AA31,COUNTIFS(B:B,B32,I:I,">0")) -> 51 | AB32: =+I32*MIN(1,$D$5/AA32) -> 0.29411765 | AC32: =+AB32+AC31 -> 6.7404405 | AD32: =+INT(AC32)-INT(AC31) -> 0 | AE32: =+(J32>0)+(I32>0) -> 1 | AF32: =+COUNTIFS(B:B,B32,AE:AE,AE32) -> 45 | AG32: =IF(OR(AF32=0,AE32=0),0,IF(AE32=2,ROUND(MIN($D$5*(AF32^$F$5)/(AF32^$F$5+(AA32-AF32)^$F$5),AF32),0),IF(AF32=0,0,MIN($D$5,AA32)-IF(AA32=AF32,0,ROUND(MIN((AE32>0)*$D$5*((AA32-AF32)^$F$5)/((AA32-AF32)^$F$5+AF32^$F$5),AA32-AF32),0))))) -> 9 | AH32: =+MIN(1,AG32/AF32) -> 0.2 | AI32: =+AH32+AI31 -> 9.281617 | AJ32: =+INT(AI32)-INT(AI31) -> 0
A33: Stratum 1 | B33: PSU 1 | C33: =+C32+1 -> 18 | D33: =1+D32 -> 23 | E33: =1+E32 -> 25 | F33: AA BB | G33: CC DDDD | H33: 2 | I33: 1 | J33: 0 | L33: 1 | M33: =+W33 -> 0.20547945 | N33: =+IF(Y33=1,Y33,"") | O33: =+Z33 -> 1 | P33: =+AB33 -> 0.29411765 | Q33: =IF(AD33=1,AD33,"") -> 1 | R33: =+AE33 -> 1 | S33: =+AH33 -> 0.2 | T33: =IF(AJ33=1,AJ33,"") | V33: =+IF(B33=B32,V32,COUNTIFS(B:B,B33,H:H,">0")) -> 73 | W33: =+MIN(1,$D$5/V33) -> 0.20547945 | X33: =+W33+X32 -> 4.8186033 | Y33: =+INT(X33)-INT(X32) -> 0 | Z33: =1*(I33>0) -> 1 | AA33: =IF(B33=B32,AA32,COUNTIFS(B:B,B33,I:I,">0")) -> 51 | AB33: =+I33*MIN(1,$D$5/AA33) -> 0.29411765 | AC33: =+AB33+AC32 -> 7.0345582 | AD33: =+INT(AC33)-INT(AC32) -> 1 | AE33: =+(J33>0)+(I33>0) -> 1 | AF33: =+COUNTIFS(B:B,B33,AE:AE,AE33) -> 45 | AG33: =IF(OR(AF33=0,AE33=0),0,IF(AE33=2,ROUND(MIN($D$5*(AF33^$F$5)/(AF33^$F$5+(AA33-AF33)^$F$5),AF33),0),IF(AF33=0,0,MIN($D$5,AA33)-IF(AA33=AF33,0,ROUND(MIN((AE33>0)*$D$5*((AA33-AF33)^$F$5)/((AA33-AF33)^$F$5+AF33^$F$5),AA33-AF33),0))))) -> 9 | AH33: =+MIN(1,AG33/AF33) -> 0.2 | AI33: =+AH33+AI32 -> 9.481617 | AJ33: =+INT(AI33)-INT(AI32) -> 0
