Workbook
Name _ftn1: OVERVIEW!#REF!
Name _ftnref1: OVERVIEW!$B$3

Sheet OVERVIEW
A1: OVERVIEW of the Risk Stress Test (RiST) tool
A2: Purpose | B2: RiST provides a simple approach to test a project's resilience to climate change and natural disasters based on its economic analysis. Although uncertainty around climate futures is too large to provide a precise estimate of climate impacts over a project's lifetime, this "stress test" can help to improve understanding of possible impacts, enhance preparation and project design, as well as inform decision-makers.
A3: How RiST works | B3: The analysis estimates climate and disaster impacts on the cost and benefit flows of a project’s net present value (NPV). The methodology accounts for: (i) changes in average climate conditions, (ii) impacts from natural disasters, and (iii) changes in the frequency of disasters. The results of this analysis should be considered as a stress test of project robustness: If the NPV or a project’s benefit cost ration (BCR) fall below a certain threshold (e.g. NPV<0 or BCR<1), due to the additional impact of climate and disasters, project teams can modify the project to include risk management measures where necessary, and report to stakeholders on how risks were considered.
A4: Disclaimer | B4: The Risk Stress Testing Methodology (http://hdl.handle.net/10986/35751) and associated RiST Tool can help identify potential climate and disaster risks to a project and inform decision makers on project robustness. However, findings, interpretations, and conclusions derived from applying this Methodology or Tool should not be attributed to the World Bank, its affiliated institutions, the Executive Directors of the World Bank or the governments they represent. Use of this tool is at the user's own risk and under no circumstances shall the World Bank be liable for any loss, damage, liability, or expense incurred or suffered which is claimed to result from the use of this Methodology/Tool.

Sheet Excel Sheet Navigation
B2: Excel-Sheet Navigation
B4: Color Guide
B5: Inputs: Light green cells/sheets indicate inputs needed from users
B6: Calculation: Light orange cells/sheets indicate model calculations
B7: Result: Grey/blue represents parameters and results
B8: Guidance: Beige indicates further guidance

Sheet Calculations >>

Sheet Net Benefit Calculations
A1: Year | B1: 2020 | C1: 2021 | D1: 2022 | E1: 2023 | F1: 2024 | G1: 2025 | H1: 2026 | I1: 2027 | J1: 2028 | K1: 2029 | L1: 2030 | M1: 2031 | N1: 2032 | O1: 2033 | P1: 2034 | Q1: 2035 | R1: 2036 | S1: 2037 | T1: 2038 | U1: 2039 | V1: 2040 | W1: 2041 | X1: 2042 | Y1: 2043 | Z1: 2044
A2: Costs
A3: CAPEX with project | B3: 0 | C3: 933.08134 | D3: 974.2647 | E3: 1456.1167 | F3: 379.78744 | G3: 0 | H3: 0 | I3: 0 | J3: 0 | K3: 56.88 | L3: 63.00045 | M3: 0 | N3: 0 | O3: 0 | P3: 0 | Q3: 56.88 | R3: 63.00045 | S3: 0 | T3: 0 | U3: 0 | V3: 0 | W3: 56.88 | X3: 63.00045 | Y3: 0 | Z3: -748.65003
A4: OPEX without project | B4: 0.14417977 | C4: 0.89825962 | D4: 1.7986269 | E4: 2.5203077 | F4: 2.9916177 | G4: 3.1691729 | H4: 3.3006501 | I4: 3.4383134 | J4: 3.5829907 | K4: 3.7350721 | L4: 3.8948852 | M4: 4.0627427 | N4: 4.1919374 | O4: 4.2931482 | P4: 4.3975446 | Q4: 4.507815 | R4: 4.628631 | S4: 4.7617587 | T4: 4.9055742 | U4: 5.0578663 | V4: 5.2184691 | W4: 5.3877134 | X4: 5.5660372 | Y4: 5.753922 | Z4: 5.9518778
A5: OPEX with project | B5: =((0.14417977)*-1)*-1 -> 0.14417977 | C5: 0 | D5: 0 | E5: 59.151552 | F5: 50.619565 | G5: 0 | H5: 0 | I5: 0 | J5: 0 | K5: 0.15310362 | L5: 0.07655181 | M5: 0 | N5: 0 | O5: 0 | P5: 0 | Q5: 0.0377728 | R5: 0.01783389 | S5: 0 | T5: 0 | U5: 0 | V5: 0 | W5: 0.05590701 | X5: 0.01783389 | Y5: 0 | Z5: 0
A6: MT Vehicle Operation without project | B6: 1761.338 | C6: 1866.0167 | D6: 1995.1374 | E6: 2167.7769 | F6: 2376.2885 | G6: 2571.8985 | H6: 2745.6024 | I6: 2939.3105 | J6: 3158.276 | K6: 3378.8507 | L6: 3579.1352 | M6: 3780.2661 | N6: 3988.094 | O6: 4206.3651 | P6: 4438.6088 | Q6: 4686.647 | R6: 4950.5822 | S6: 5226.7897 | T6: 5513.5773 | U6: 5819.8678 | V6: 6148.6449 | W6: 6506.6403 | X6: 6901.5262 | Y6: 7329.6234 | Z6: 7802.2375
A7: MT Vehicle Operation with project | B7: -1761.338 | C7: -1866.0167 | D7: -1960.7502 | E7: -2060.3957 | F7: -2071.4 | G7: -2081.8416 | H7: -2187.5408 | I7: -2298.877 | J7: -2805.7318 | K7: -2949.7509 | L7: -3101.8531 | M7: -3260.3296 | N7: -3427.2927 | O7: -3606.0633 | P7: -3796.1759 | Q7: -4002.4476 | R7: -4226.9589 | S7: -4463.461 | T7: -4714.1847 | U7: -4988.0531 | V7: -5280.2389 | W7: -5591.4093 | X7: -5916.078 | Y7: -6229.6882 | Z7: -6558.034
A8: MT Travel Time without project | B8: 1237.552 | C8: 1303.9513 | D8: 1376.6631 | E8: 1467.7078 | F8: 1615.4276 | G8: 1762.485 | H8: 1870.2687 | I8: 1996.999 | J8: 2151.5879 | K8: 2316.4837 | L8: 2467.6918 | M8: 2618.108 | N8: 2773.4452 | O8: 2938.8564 | P8: 3117.4905 | Q8: 3311.9717 | R8: 3522.2408 | S8: 3747.0233 | T8: 3985.0053 | U8: 4247.1061 | V8: 4535.2139 | W8: 4859.2455 | X8: 5226.053 | Y8: 5626.6205 | Z8: 6076.1513
A9: MT Travel Time with project | B9: -1237.552 | C9: -1303.9513 | D9: -1373.2119 | E9: -1446.4023 | F9: -1312.0825 | G9: -1171.8848 | H9: -1233.9469 | I9: -1299.5369 | J9: -1565.9648 | K9: -1650.6831 | L9: -1740.4736 | M9: -1835.7054 | N9: -1937.8651 | O9: -2051.4564 | P9: -2173.7733 | Q9: -2312.4253 | R9: -2469.5849 | S9: -2643.9236 | T9: -2840.6304 | U9: -3068.1739 | V9: -3312.2325 | W9: -3565.7871 | X9: -3820.3527 | Y9: -4039.5191 | Z9: -4279.5964
A10: NMT Travel and Operation without project | B10: 47.174228 | C10: 48.862871 | D10: 52.658607 | E10: 59.168352 | F10: 67.33336 | G10: 73.026481 | H10: 74.827963 | I10: 76.916101 | J10: 79.399789 | K10: 81.663805 | L10: 83.13894 | M10: 84.588853 | N10: 86.026605 | O10: 87.552318 | P10: 89.202248 | Q10: 91.009995 | R10: 92.950485 | S10: 94.629695 | T10: 95.861529 | U10: 96.819786 | V10: 97.787716 | W10: 98.765481 | X10: 99.753087 | Y10: 100.75056 | Z10: 101.75801
A11: NMT Travel and Operation with project | B11: -47.174228 | C11: -48.862871 | D11: -49.351501 | E11: -49.845015 | F11: -41.054601 | G11: -39.384956 | H11: -39.826797 | I11: -40.277769 | J11: -47.101804 | K11: -47.652631 | L11: -48.212899 | M11: -48.742214 | N11: -49.269022 | O11: -49.809035 | P11: -50.365491 | Q11: -50.946118 | R11: -51.546214 | S11: -52.113372 | T11: -52.681849 | U11: -53.265712 | V11: -53.868514 | W11: -54.499122 | X11: -55.151427 | Y11: -55.765043 | Z11: -56.379843
B12: -1
A13: Net Benefit With Project | B13: 2019 | C13: 2020 | D13: 2021 | E13: 2022 | F13: 2023 | G13: 2024 | H13: 2025 | I13: 2026 | J13: 2027 | K13: 2028 | L13: 2029 | M13: 2030 | N13: 2031 | O13: 2032 | P13: 2033 | Q13: 2034 | R13: 2035 | S13: 2036 | T13: 2037 | U13: 2038 | V13: 2039 | W13: 2040 | X13: 2041 | Y13: 2042 | Z13: 2043
A14: MT Vehicle Operation with project | B14: 1761.338 | C14: 1866.0167 | D14: 1960.7502 | E14: 2060.3957 | F14: 2071.4 | G14: 2081.8416 | H14: 2187.5408 | I14: 2298.877 | J14: 2805.7318 | K14: 2949.7509 | L14: 3101.8531 | M14: 3260.3296 | N14: 3427.2927 | O14: 3606.0633 | P14: 3796.1759 | Q14: 4002.4476 | R14: 4226.9589 | S14: 4463.461 | T14: 4714.1847 | U14: 4988.0531 | V14: 5280.2389 | W14: 5591.4093 | X14: 5916.078 | Y14: 6229.6882 | Z14: 6558.034
A15: MT Travel Time with project | B15: 1237.552 | C15: 1303.9513 | D15: 1373.2119 | E15: 1446.4023 | F15: 1312.0825 | G15: 1171.8848 | H15: 1233.9469 | I15: 1299.5369 | J15: 1565.9648 | K15: 1650.6831 | L15: 1740.4736 | M15: 1835.7054 | N15: 1937.8651 | O15: 2051.4564 | P15: 2173.7733 | Q15: 2312.4253 | R15: 2469.5849 | S15: 2643.9236 | T15: 2840.6304 | U15: 3068.1739 | V15: 3312.2325 | W15: 3565.7871 | X15: 3820.3527 | Y15: 4039.5191 | Z15: 4279.5964
A16: NMT Travel and Operation with project | B16: 47.174228 | C16: 48.862871 | D16: 49.351501 | E16: 49.845015 | F16: 41.054601 | G16: 39.384956 | H16: 39.826797 | I16: 40.277769 | J16: 47.101804 | K16: 47.652631 | L16: 48.212899 | M16: 48.742214 | N16: 49.269022 | O16: 49.809035 | P16: 50.365491 | Q16: 50.946118 | R16: 51.546214 | S16: 52.113372 | T16: 52.681849 | U16: 53.265712 | V16: 53.868514 | W16: 54.499122 | X16: 55.151427 | Y16: 55.765043 | Z16: 56.379843
A17: Carbon Emission | B17: 1766.4686 | C17: 1865.5029 | D17: 1972.0249 | E17: 2088.0662 | F17: 2230.3334 | G17: 2370.6138 | H17: 2520.4711 | I17: 2689.0394 | J17: 2970.9472 | K17: 3173.686 | L17: 3358.9609 | M17: 3555.2794 | N17: 3764.951 | O17: 3989.7306 | P17: 4230.6114 | Q17: 4490.1698 | R17: 4771.855 | S17: 5071.8919 | T17: 5397.1667 | U17: 5764.5526 | V17: 6169.4207 | W17: 6617.7058 | X17: 7139.6974 | Y17: 7712.8336 | Z17: 8393.4331 | AA17: 108289.95
A18: Net Benefit with project | B18: =((SUM(B14:B17))) -> 4812.5328 | C18: =((SUM(C14:C17))*-1)*-1 -> 5084.3337 | D18: =((SUM(D14:D17))*-1)*-1 -> 5355.3384 | E18: =((SUM(E14:E17))*-1)*-1 -> 5644.7092 | F18: =((SUM(F14:F17))*-1)*-1 -> 5654.8706 | G18: =((SUM(G14:G17))*-1)*-1 -> 5663.7252 | H18: =((SUM(H14:H17))*-1)*-1 -> 5981.7857 | I18: =((SUM(I14:I17))*-1)*-1 -> 6327.7309 | J18: =((SUM(J14:J17))*-1)*-1 -> 7389.7455 | ... Z18: =((SUM(Z14:Z17))*-1)*-1 -> 19287.443 | AA18: =SUM(B18:Z18) -> 252201.19
A20: Net Benefit Without Project | B20: 2019 | C20: 2020 | D20: 2021 | E20: 2022 | F20: 2023 | G20: 2024 | H20: 2025 | I20: 2026 | J20: 2027 | K20: 2028 | L20: 2029 | M20: 2030 | N20: 2031 | O20: 2032 | P20: 2033 | Q20: 2034 | R20: 2035 | S20: 2036 | T20: 2037 | U20: 2038 | V20: 2039 | W20: 2040 | X20: 2041 | Y20: 2042 | Z20: 2043
A21: MT Vehicle Operation without project | B21: 1761.338 | C21: 1866.0167 | D21: 1995.1374 | E21: 2167.7769 | F21: 2376.2885 | G21: 2571.8985 | H21: 2745.6024 | I21: 2939.3105 | J21: 3158.276 | K21: 3378.8507 | L21: 3579.1352 | M21: 3780.2661 | N21: 3988.094 | O21: 4206.3651 | P21: 4438.6088 | Q21: 4686.647 | R21: 4950.5822 | S21: 5226.7897 | T21: 5513.5773 | U21: 5819.8678 | V21: 6148.6449 | W21: 6506.6403 | X21: 6901.5262 | Y21: 7329.6234 | Z21: 7802.2375
A22: MT Travel Time without project | B22: 1237.552 | C22: 1303.9513 | D22: 1376.6631 | E22: 1467.7078 | F22: 1615.4276 | G22: 1762.485 | H22: 1870.2687 | I22: 1996.999 | J22: 2151.5879 | K22: 2316.4837 | L22: 2467.6918 | M22: 2618.108 | N22: 2773.4452 | O22: 2938.8564 | P22: 3117.4905 | Q22: 3311.9717 | R22: 3522.2408 | S22: 3747.0233 | T22: 3985.0053 | U22: 4247.1061 | V22: 4535.2139 | W22: 4859.2455 | X22: 5226.053 | Y22: 5626.6205 | Z22: 6076.1513
A23: NMT Travel and Operation without project | B23: 47.174228 | C23: 48.862871 | D23: 52.658607 | E23: 59.168352 | F23: 67.33336 | G23: 73.026481 | H23: 74.827963 | I23: 76.916101 | J23: 79.399789 | K23: 81.663805 | L23: 83.13894 | M23: 84.588853 | N23: 86.026605 | O23: 87.552318 | P23: 89.202248 | Q23: 91.009995 | R23: 92.950485 | S23: 94.629695 | T23: 95.861529 | U23: 96.819786 | V23: 97.787716 | W23: 98.765481 | X23: 99.753087 | Y23: 100.75056 | Z23: 101.75801
A24: Carbon emission | B24: 1766.4686 | C24: 1865.5029 | D24: 1972.0282 | E24: 2088.0768 | F24: 2230.3456 | G24: 2370.6535 | H24: 2520.5219 | I24: 2689.106 | J24: 2971.0244 | K24: 3173.7875 | L24: 3359.0787 | M24: 3555.4146 | N24: 3765.1056 | O24: 3989.9089 | P24: 4230.8155 | Q24: 4490.4046 | R24: 4772.1219 | S24: 5072.1981 | T24: 5397.5251 | U24: 5764.9718 | V24: 6169.9189 | W24: 6618.3063 | X24: 7140.4365 | Y24: 7713.7646 | Z24: 8394.636 | AA24: 104082.12
A25: Net Benefit Without Project | B25: =((SUM(B21:B24))) -> 4812.5328 | C25: =((SUM(C21:C24))*-1)*-1 -> 5084.3337 | D25: =((SUM(D21:D24))*-1)*-1 -> 5396.4872 | E25: =((SUM(E21:E24))*-1)*-1 -> 5782.7299 | F25: =((SUM(F21:F24))*-1)*-1 -> 6289.395 | G25: =((SUM(G21:G24))*-1)*-1 -> 6778.0636 | H25: =((SUM(H21:H24))*-1)*-1 -> 7211.2209 | I25: =((SUM(I21:I24))*-1)*-1 -> 7702.3316 | J25: =((SUM(J21:J24))*-1)*-1 -> 8360.2881 | ... Z25: =((SUM(Z21:Z24))*-1)*-1 -> 22374.783 | AA25: =SUM(B25:Z25) -> 288134.2
A27: Difference | B27: =B25-B18 -> 0 | C27: =C25-C18 -> 0 | D27: =D25-D18 -> 41.148807 | E27: =E25-E18 -> 138.02068 | F27: =F25-F18 -> 634.52441 | G27: =G25-G18 -> 1114.3384 | H27: =H25-H18 -> 1229.4352 | I27: =I25-I18 -> 1374.6006 | ... Z27: =Z25-Z18 -> 3087.3394
A28: 1.1
B29: 1826.8178 | C29: 1932.2726 | D29: 2042.8781 | E29: 2163.2103 | F29: 2300.9319 | G29: 2454.9545 | H29: 2599.6344 | I29: 2754.0338 | J29: 3121.5794 | K29: 3308.5685 | L29: 3508.7976 | M29: 3720.8259 | N29: 3946.2491 | O29: 4188.9086 | P29: 4450.0756 | Q29: 4731.9894 | R29: 5037.6486 | S29: 5368.2565 | T29: 5712.4588 | U29: 6081.5251 | V29: 6480.6746 | W29: 6913.7812 | X29: 7382.5358 | Y29: 7873.9586 | Z29: 8387.3845
A30: Pessimistic Costs | B30: 5293.9447 | C30: 5592.7671 | D30: 5890.8723 | E30: 6274.2469 | F30: 6276.0391 | G30: 6230.0977 | H30: 6579.9643 | I30: 6960.504 | J30: 8128.7201 | K30: 8604.1183 | L30: 9074.5349 | M30: 9570.0623 | N30: 10097.316 | O30: 10666.765 | P30: 11276.019 | Q30: 11941.629 | R30: 12671.959 | S30: 13454.529 | T30: 14305.13 | U30: 15261.45 | V30: 16297.337 | W30: 17412.403 | X30: 18624.427 | Y30: 19841.587 | Z30: 21216.188
A33: Carbon Emissions | B33: Without Project | C33: With Project
B34: 1766.4686 | C34: 1766.4686
B35: 1865.5029 | C35: 1865.5029
B36: 1972.0282 | C36: 1972.0249
B37: 2088.0768 | C37: 2088.0662
B38: 2230.3456 | C38: 2230.3334
B39: 2370.6535 | C39: 2370.6138
B40: 2520.5219 | C40: 2520.4711
B41: 2689.106 | C41: 2689.0394
B42: 2971.0244 | C42: 2970.9472
B43: 3173.7875 | C43: 3173.686
B44: 3359.0787 | C44: 3358.9609
...

Sheet Floods and Landslides 
C1: Floods | H1: Landslides
D2: Percentage Change with project (Low) | E2: Percentage Change with Project High | F2: Percenatge Change without Project Low | G2: Percentage Change Without Project High | H2: Percentage Change with project (Low) | I2: Percentage Change with Project High | J2: Percenatge Change without Project Low | K2: Percentage Change Without Project High
D3: =(D7-$D$29)/$D$29 *100 -> 0.24657534 | E3: =(E7-$D$29)/$D$29 *100 -> 0.49315068 | F3: =(F7-$D$30)/$D$30*100 -> 0.49315068 | G3: =(G7-$D$30)/$D$30*100 -> 0.73972603 | H3: =(H7-$D$29)/$D$29*100 -> 0.49315068 | I3: =(I7-$D$29)/$D$29*100 -> 0.73972603 | J3: =(J7-$D$30)/$D$30*100 -> 0.61643836 | K3: =(K7-$D$30)/$D$30*100 -> 0.8630137
D4: =(D8-$D$29)/$D$29 *100 -> 0.14794521 | E4: =(E8-$D$29)/$D$29 *100 -> 0.19726027 | F4: =(F8-$D$30)/$D$30*100 -> 0.19726027 | G4: =(G8-$D$30)/$D$30*100 -> 0.29589041 | H4: =(H8-$D$29)/$D$29*100 -> 0.19726027 | I4: =(I8-$D$29)/$D$29*100 -> 0.29589041 | J4: =(J8-$D$30)/$D$30*100 -> 0.22191781 | K4: =(K8-$D$30)/$D$30*100 -> 0.32054795
D5: =(D9-$D$29)/$D$29 *100 -> 0.036986301 | E5: =(E9-$D$29)/$D$29 *100 -> 0.051780822 | F5: =(F9-$D$30)/$D$30*100 -> 0.059178082 | G5: =(G9-$D$30)/$D$30*100 -> 0.073972603 | H5: =(H9-$D$29)/$D$29*100 -> 0.059178082 | I5: =(I9-$D$29)/$D$29*100 -> 0.073972603 | J5: =(J9-$D$30)/$D$30*100 -> 0.062876712 | K5: =(K9-$D$30)/$D$30*100 -> 0.077671233
A6: Ratio | B6: Prob a | C6: Return Period | D6: User Costs with project (Low) | E6: User Costs with project (High) | F6: Cost without low | G6: Costs without High | H6: Cost with Low | I6: Cost with High | J6: Cost without low | K6: Costs without High | L6: 100
A7: 2 | B7: =C7-C8 -> 0.09 | C7: =1/10 -> 0.1 | D7: =D15+D11 -> 252823.05 | E7: =E15+E11 -> 253444.92 | F7: =F15+F11 -> 289555.14 | G7: =G15+G11 -> 290265.6 | H7: =H15+H11 -> 253444.92 | I7: =I15+I11 -> 254066.79 | J7: =J15+J11 -> 289910.37 | K7: =K15+K11 -> 290620.84
A8: 3 | B8: =C8-C9 -> 0.009 | C8: =1/100 -> 0.01 | D8: =D16+D12 -> 252574.31 | E8: =E16+E12 -> 252698.68 | F8: =F16+F12 -> 288702.57 | G8: =G16+G12 -> 288986.76 | H8: =H16+H12 -> 252698.68 | I8: =I16+I12 -> 252947.43 | J8: =J16+J12 -> 288773.62 | K8: =K16+K12 -> 289057.81
A9: 4 | B9: 0.0009 | C9: =1/1000 -> 0.001 | D9: =D17+D13 -> 252294.47 | E9: =E17+E13 -> 252331.78 | F9: =F17+F13 -> 288304.71 | G9: =G17+G13 -> 288347.34 | H9: =H17+H13 -> 252350.44 | I9: =I17+I13 -> 252387.75 | J9: =J17+J13 -> 288315.37 | K9: =K17+K13 -> 288358
D10: Part 2 with Low | E10: Part 2 with High | F10: Part 2 without Low | G10: Part 2 without High | H10: Part 2 with Low | I10: Part 2 with High | J10: Part 2 without Low | K10: Part 2 without High
A11: 2 | B11: 0.09 | C11: 0.1 | D11: =$B11*D19*$A11*$D$29 -> 1243.7319 | E11: =$B11*E19*$A11*$D$29 -> 2487.4638 | F11: =$B11*F19*$A11*$D$30 -> 2841.8716 | G11: =$B11*G19*$A11*$D$30 -> 4262.8073 | H11: =$B11*H19*$A11*$D$29 -> 2487.4638 | I11: =$B11*I19*$A11*$D$29 -> 3731.1957 | J11: =$B11*J19*$A11*$D$30 -> 3552.3394 | K11: =$B11*K19*$A11*$D$30 -> 4973.2752
A12: 3 | B12: 0.009 | C12: 0.01 | D12: =$B12*D20*$A12*$D$29 -> 559.67935 | E12: =$B12*E20*$A12*$D$29 -> 746.23913 | F12: =$B12*F20*$A12*$D$30 -> 852.56147 | G12: =$B12*G20*$A12*$D$30 -> 1278.8422 | H12: =$B12*H20*$A12*$D$29 -> 746.23913 | I12: =$B12*I20*$A12*$D$29 -> 1119.3587 | J12: =$B12*J20*$A12*$D$30 -> 959.13165 | K12: =$B12*K20*$A12*$D$30 -> 1385.4124
A13: 4 | B13: 0.0009 | C13: 0.001 | D13: =$B13*D21*$A13*$D$29 -> 124.37319 | E13: =$B13*E21*$A13*$D$29 -> 174.12246 | F13: =$B13*F21*$A13*$D$30 -> 227.34972 | G13: =$B13*G21*$A13*$D$30 -> 284.18716 | H13: =$B13*H21*$A13*$D$29 -> 198.9971 | I13: =$B13*I21*$A13*$D$29 -> 248.74638 | J13: =$B13*J21*$A13*$D$30 -> 241.55908 | K13: =$B13*K21*$A13*$D$30 -> 298.39651
D14: Part 1 with Low | E14: Part 1 with High | F14: Part 1 without Low | G14: Part 1 without High | H14: Part 1 with Low | I14: Part 1 with High | J14: Part 1 without Low | K14: Part 1 without High
A15: 2 | B15: 0.09 | C15: 0.1 | D15: =(1-$B15*D19)*$D$29 -> 251579.32 | E15: =(1-$B15*E19)*$D$29 -> 250957.46 | F15: =(1-$B15*F19)*$D$30 -> 286713.26 | G15: =(1-$B15*G19)*$D$30 -> 286002.8 | H15: =(1-$B15*H19)*$D$29 -> 250957.46 | I15: =(1-$B15*I19)*$D$29 -> 250335.59 | J15: =(1-$B15*J19)*$D$30 -> 286358.03 | K15: =(1-$B15*K19)*$D$30 -> 285647.56
A16: 3 | B16: 0.009 | C16: 0.01 | D16: =(1-$B16*D20)*$D$29 -> 252014.63 | E16: =(1-$B16*E20)*$D$29 -> 251952.44 | F16: =(1-$B16*F20)*$D$30 -> 287850.01 | G16: =(1-$B16*G20)*$D$30 -> 287707.92 | H16: =(1-$B16*H20)*$D$29 -> 251952.44 | I16: =(1-$B16*I20)*$D$29 -> 251828.07 | J16: =(1-$B16*J20)*$D$30 -> 287814.49 | K16: =(1-$B16*K20)*$D$30 -> 287672.4
A17: 4 | B17: 0.0009 | C17: 0.001 | D17: =(1-$B17*D21)*$D$29 -> 252170.1 | E17: =(1-$B17*E21)*$D$29 -> 252157.66 | F17: =(1-$B17*F21)*$D$30 -> 288077.36 | G17: =(1-$B17*G21)*$D$30 -> 288063.15 | H17: =(1-$B17*H21)*$D$29 -> 252151.44 | I17: =(1-$B17*I21)*$D$29 -> 252139 | J17: =(1-$B17*J21)*$D$30 -> 288073.81 | K17: =(1-$B17*K21)*$D$30 -> 288059.6
C18: Prob a | D18: Loss of Service with Low Impact | E18: Loss of Service with High | F18: Loss of Service without Low | G18: Loss of service without High | H18: Loss of Service with project (Low) | I18: Loss of Service with project (High) | J18: Loss of Service without project (Low) | K18: Loss of service without project (High)
C19: =1/10 -> 0.1 | D19: =D23/365 -> 0.02739726 | E19: =E23/365 -> 0.054794521 | F19: =F23/365 -> 0.054794521 | G19: =G23/365 -> 0.082191781 | H19: =H23/365 -> 0.054794521 | I19: =I23/365 -> 0.082191781 | J19: =J23/365 -> 0.068493151 | K19: =K23/365 -> 0.095890411
C20: =1/100 -> 0.01 | D20: =D24/365 -> 0.082191781 | E20: =E24/365 -> 0.10958904 | F20: =F24/365 -> 0.10958904 | G20: =G24/365 -> 0.16438356 | H20: =H24/365 -> 0.10958904 | I20: =I24/365 -> 0.16438356 | J20: =J24/365 -> 0.12328767 | K20: =K24/365 -> 0.17808219
C21: =1/1000 -> 0.001 | D21: =D25/365 -> 0.1369863 | E21: =E25/365 -> 0.19178082 | F21: =F25/365 -> 0.21917808 | G21: =G25/365 -> 0.2739726 | H21: =H25/365 -> 0.21917808 | I21: =I25/365 -> 0.2739726 | J21: =J25/365 -> 0.23287671 | K21: =K25/365 -> 0.28767123
D22: Days with project (low impact) | E22: Days with project (high impact) | F22: Days without project (low impact) | G22: Days without (high impact) | H22: Days with Low | I22: Days with High | J22: Days without Low | K22: Days without High
C23: =1/10 -> 0.1 | D23: 10 | E23: 20 | F23: 20 | G23: 30 | H23: 20 | I23: 30 | J23: 25 | K23: 35
C24: =1/100 -> 0.01 | D24: 30 | E24: 40 | F24: 40 | G24: 60 | H24: 40 | I24: 60 | J24: 45 | K24: 65
C25: =1/1000 -> 0.001 | D25: 50 | E25: 70 | F25: 80 | G25: 100 | H25: 80 | I25: 100 | J25: 85 | K25: 105
D29: 252201.19
D30: 288134.2
A32: Change in Average Conditions | D32: With Project Low | E32: Without Project High | F32: Without Project Low | G32: Without Project High
C33: User Costs without Climate Change | D33: =ABS(SUM('Baseline scenario'!$D$15:$AB$15)) -> 252311.46 | E33: =ABS(SUM('Baseline scenario'!$D$15:$AB$15)) -> 252311.46 | F33: =ABS(SUM('Baseline scenario'!$D$16:$AB$16)) -> 288232.36 | G33: =ABS(SUM('Baseline scenario'!$D$16:$AB$16)) -> 288232.36
C34: 2030 | D34: =(1-D40)*D$33+D40*D43*D$33 -> 252311.46 | E34: =(1-E40)*E$33+E40*E43*E$33 -> 251205.44 | F34: =(1-F40)*F$33+F40*F43*F$33 -> 285705.39 | G34: =(1-G40)*G$33+G40*G43*G$33 -> 288232.36
C35: % change | D35: =(D34-D33)/D33 -> 0 | E35: =(E34-E33)/E33 -> -0.0043835616 | F35: =(F34-F33)/F33 -> -0.0087671233 | G35: =(G34-G33)/G33 -> 0
C36: 2050 | D36: =(1-D41)*D$33+D41*D44*D$33 -> 251205.44 | E36: =(1-E41)*E$33+E41*E44*E$33 -> 250237.67 | F36: =(1-F41)*F$33+F41*F44*F$33 -> 294549.78 | G36: =(1-G41)*G$33+G41*G44*G$33 -> 300077.52
C37: % change | D37: =(D36-D33)/D33 -> -0.0043835616 | E37: =(E36-E33)/E33 -> -0.0082191781 | F37: =(F36-F33)/F33 -> 0.021917808 | G37: =(G36-G33)/G33 -> 0.04109589
D38: With Project Low | E38: Without Project High | F38: Without Project Low | G38: Without Project High
C39: Alpha
C40: 2030 | D40: =0/365 -> 0 | E40: =2/365 -> 0.0054794521 | F40: =4/365 -> 0.010958904 | G40: =D18=6/365 -> FALSE
C41: 2044 | D41: =2/365 -> 0.0054794521 | E41: =4/365 -> 0.010958904 | F41: =8/365 -> 0.021917808 | G41: =10/365 -> 0.02739726
C42: Ratio
C43: 2030 | D43: 0 | E43: 0.2 | F43: 0.2 | G43: 0.25
C44: 2044 | D44: 0.2 | E44: 0.25 | F44: 2 | G44: 2.5

Sheet Input >>

Sheet Parameters_Results
B2: Main parameters and results
B3: Two functions of this sheet: (1) Decide on unacceptable NPV in the range of possible future (2) Identify "switching" scenario
B6: Guidance: 1. Step: Decision point - Is the project viable in the high impact climate and pessimistic baseline scenario? Actions: - Set 'All climate parameters' and 'Baseline level of pessimism' at 100% (red cells) - Decide if NPV and BCR for 'All climate risk adjusted results' is above threshold (if yes, no further actions required, if no -> proceed to step 2) 2. Step: Identify climate switching scenario - Identify what level of climate impact would be needed to make the project fail (NPV or BCR below threshold) at a given level of baseline pessimism? - Set 'Level of pessimism on baseline' at a certain value (e.g. 50%) - Identify approximate level of climate impact by looking at the NPV or BCR result graphs below - Change "All climate parameters" value until you have found the 'switching value' (the level of climate impact which leads to a NPV/BCR below threshold) - Look at the result boxes below which show your input parameters for this switching value. -> Continue with steps xy of gudiance
B9: INPUT: Change main parameters of analysis | F9: Guidance on Intepreting Results: Step 1: Decision point - Is the project viable in the high climate impact and pessimistic baseline scenario? - Set 'All climate parameters' and 'Baseline level of pessimism' at 100% (red cells) - Decide if NPV and BCR for 'All climate risk adjusted results' is above threshold (if yes, no further actions required, if no -> proceed to Step 2) Step 2: Identify climate switching scenario - Identify what level of climate impact would be needed to make the project fail (NPV or BCR below threshold) at a given level of baseline pessimism? - Set 'Level of pessimism on baseline' (cell D22) at a certain value (e.g. 50%) - Identify approximate level of climate impact by looking at the NPV or BCR result graphs below - Change "All climate parameters" value (cell D14) until you have found the 'switching value' (the level of climate impact which leads to a NPV/BCR below threshold) - Look at the result boxes below which show your input parameters for this switching value. Step 3: Report NPV and BCRs of the extreme scenarios (i.e. results when climate impacts are set to 0% and 100% and pessimism is set at 0% and 100%). Input results in reporting table and include in project documents/discussions with decisions makers. See sample table below.
B10: Project start date | D10: 2018
B11: Project end date | D11: 2044
B12: Discount rate | D12: 0.06
B14: Parameters to change climate impact (0%=no/low impact, 100%=high impact):
B15: Level of climate impact: All climate parameters (0 - 100%) | D15: 1
B16: Level of climate impact on quantities (0 - 100%) | D16: =D15 -> 1
B17: Level of climate impact on prices (0 - 100%) | D17: =D15 -> 1
B18: Level of climate impact on costs (0 - 100%) | D18: =D15 -> 1
B19: Magnitude of extreme event impacts (0 - 100%) Floods | D19: =D15 -> 1
B20: Future change in extreme event frequency (0 - 100%) Floods | D20: =D15 -> 1
B21: Magnitude of extreme event impacts (0 - 100%) Landslides | D21: =D15 -> 1
B22: Future change in extreme event frequency (0 - 100%) Landslides | D22: =D15 -> 1
B23: Magnitude of extreme event impacts (0 - 100%) | D23: =D15 -> 1
B24: Future change in extreme event frequency (0 - 100%) | D24: =D15 -> 1 | F24: SAMPLE REPORTING TABLE: NPVs and BCRs Under Extreme Scenarios (climate impact at 0% and 100%; project pessimism at 0% and 100%)
F25: Adjusted NPVs and BCRs Under Extreme Scenarios | H25: Level of climate impact
B26: Parameter to change CBA baseline (0%=optimistic, 100%=pessimistic): | H26: No/low impact | J26: High impact
B27: Level of pessimism on baseline (0 -100%) | D27: 1 | H27: NPV | I27: BC ratio | J27: NPV | K27: BC ratio
F28: Baseline scenario | G28: Optimistic | H28: 767.22485 | I28: 2.1250826 | J28: 632.65459 | K28: 1.5703317
G29: Pessimistic | H29: 140.58522 | I29: 1.2061586 | J29: 128.74862 | K29: 1.1160656
B30: RESULT: NPV and BCR for parameters set above
C32: NPV | D32: BCR
B33: Baseline results (without climate impact) | C33: ='Expected flows'!$C$20 -> 11478.573 | D33: ='Expected flows'!$C$21 -> 4.2165149
B34: All climate risks adjusted results | C34: ='Expected flows'!$C$52 -> 4362.5106 | D34: ='Expected flows'!$C$53 -> 1.6844521
B37: RESULT: Graphs for parameters set above
B64: RESULT: Change in average climate conditions for parameters set above
D66: 2030 | E66: 2050 | F66: 2100
B67: Expected change in quantity produced (e.g., corn yield) | C67: User Costs With Project | D67: =Parameters_Results!$D$16*'Climate impacts'!G11+(1-Parameters_Results!$D$16)*'Climate impacts'!F11 -> -0.004 | E67: =Parameters_Results!$D$16*'Climate impacts'!I11+(1-Parameters_Results!$D$16)*'Climate impacts'!H11 -> -0.008 | F67: =Parameters_Results!$D$16*'Climate impacts'!K11+(1-Parameters_Results!$D$16)*'Climate impacts'!J11 -> 0
C68: User Coss Without Project | D68: =Parameters_Results!$D$16*'Climate impacts'!G12+(1-Parameters_Results!$D$16)*'Climate impacts'!F12 -> -0.012 | E68: =Parameters_Results!$D$16*'Climate impacts'!I12+(1-Parameters_Results!$D$16)*'Climate impacts'!H12 -> -0.041 | F68: =Parameters_Results!$D$16*'Climate impacts'!K12+(1-Parameters_Results!$D$16)*'Climate impacts'!J12 -> 0
D69: =Parameters_Results!$D$16*'Climate impacts'!G13+(1-Parameters_Results!$D$16)*'Climate impacts'!F13 -> 0 | E69: =Parameters_Results!$D$16*'Climate impacts'!I13+(1-Parameters_Results!$D$16)*'Climate impacts'!H13 -> 0 | F69: =Parameters_Results!$D$16*'Climate impacts'!K13+(1-Parameters_Results!$D$16)*'Climate impacts'!J13 -> 0
B70: Expected change in price of supply (e.g., unit corn price) | C70: User Costs With Project | D70: =Parameters_Results!$D$16*'Climate impacts'!G14+(1-Parameters_Results!$D$16)*'Climate impacts'!F14 -> 0 | E70: =Parameters_Results!$D$16*'Climate impacts'!I14+(1-Parameters_Results!$D$16)*'Climate impacts'!H14 -> 0 | F70: =Parameters_Results!$D$16*'Climate impacts'!K14+(1-Parameters_Results!$D$16)*'Climate impacts'!J14 -> 0
C71: User Coss Without Project | D71: =Parameters_Results!$D$16*'Climate impacts'!G15+(1-Parameters_Results!$D$16)*'Climate impacts'!F15 -> 0 | E71: =Parameters_Results!$D$16*'Climate impacts'!I15+(1-Parameters_Results!$D$16)*'Climate impacts'!H15 -> 0 | F71: =Parameters_Results!$D$16*'Climate impacts'!K15+(1-Parameters_Results!$D$16)*'Climate impacts'!J15 -> 0
D72: =Parameters_Results!$D$16*'Climate impacts'!G16+(1-Parameters_Results!$D$16)*'Climate impacts'!F16 -> 0 | E72: =Parameters_Results!$D$16*'Climate impacts'!I16+(1-Parameters_Results!$D$16)*'Climate impacts'!H16 -> 0 | F72: =Parameters_Results!$D$16*'Climate impacts'!K16+(1-Parameters_Results!$D$16)*'Climate impacts'!J16 -> 0
B73: Expected change in operational or production costs | C73: CAPEX | D73: =Parameters_Results!$D$16*'Climate impacts'!G17+(1-Parameters_Results!$D$16)*'Climate impacts'!F17 -> 0 | E73: =Parameters_Results!$D$16*'Climate impacts'!I17+(1-Parameters_Results!$D$16)*'Climate impacts'!H17 -> 0 | F73: =Parameters_Results!$D$16*'Climate impacts'!K17+(1-Parameters_Results!$D$16)*'Climate impacts'!J17 -> 0
C74: OPEX With Project | D74: =Parameters_Results!$D$16*'Climate impacts'!G18+(1-Parameters_Results!$D$16)*'Climate impacts'!F18 -> 0.02 | E74: =Parameters_Results!$D$16*'Climate impacts'!I18+(1-Parameters_Results!$D$16)*'Climate impacts'!H18 -> 0.04 | F74: =Parameters_Results!$D$16*'Climate impacts'!K18+(1-Parameters_Results!$D$16)*'Climate impacts'!J18 -> 0
C75: OPEX Without Project | D75: =Parameters_Results!$D$16*'Climate impacts'!G19+(1-Parameters_Results!$D$16)*'Climate impacts'!F19 -> 0.06 | E75: =Parameters_Results!$D$16*'Climate impacts'!I19+(1-Parameters_Results!$D$16)*'Climate impacts'!H19 -> 0.1 | F75: =Parameters_Results!$D$16*'Climate impacts'!K19+(1-Parameters_Results!$D$16)*'Climate impacts'!J19 -> 0
B78: RESULT: Natural disaster estimates for parameters set above
...

Sheet Baseline scenario
B2: INPUT (Step 1): Baseline scenario (no climate impact)
B3: Inputs needed from the former CBA analysis which does not include climate impact aspects
B5: Please fill all green fields
D6: -1 | E6: 1.05
B7: OPTIMISTIC BASELINE SCENARIO:
D8: -1
B9: INPUT: Optimistic baseline scenario results from former CBA (no climate impact)
B10: 0.02
B11: Year | D11: =Parameters_Results!$D$10+COLUMN()-3 -> 2019 | E11: =Parameters_Results!$D$10+COLUMN()-3 -> 2020 | F11: =Parameters_Results!$D$10+COLUMN()-3 -> 2021 | G11: =Parameters_Results!$D$10+COLUMN()-3 -> 2022 | H11: =Parameters_Results!$D$10+COLUMN()-3 -> 2023 | I11: =Parameters_Results!$D$10+COLUMN()-3 -> 2024 | J11: =Parameters_Results!$D$10+COLUMN()-3 -> 2025 | K11: =Parameters_Results!$D$10+COLUMN()-3 -> 2026 | ... AC11: =Parameters_Results!$D$10+COLUMN()-3 -> 2044
B12: Flow of costs | C12: CAPEX | D12: 0 | E12: 933.08134 | F12: 974.2647 | G12: 1456.1167 | I12: 0 | J12: 0 | K12: 0 | L12: 0 | M12: 56.88 | N12: 63.00045 | O12: 0 | P12: 0 | Q12: 0 | R12: 0 | S12: 56.88 | T12: 63.00045 | U12: 0 | V12: 0 | W12: 0 | X12: 0 | Y12: 56.88 | Z12: 63.00045 | AA12: 0 | AB12: -748.65003 | AC12: 0
C13: OPEX With Project | D13: 0.14417977 | E13: 0 | F13: 0 | G13: 59.151552 | H13: 50.619565 | I13: 0 | J13: 0 | K13: 0 | L13: 0 | M13: 0.15310362 | N13: 0.07655181 | O13: 0 | P13: 0 | Q13: 0 | R13: 0 | S13: 0.0377728 | T13: 0.01783389 | U13: 0 | V13: 0 | W13: 0 | X13: 0 | Y13: 0.05590701 | Z13: 0.01783389 | AA13: 0 | AB13: 0
C14: OPEX Without Project | D14: 0.14417977 | E14: 0.89825962 | F14: 1.7986269 | G14: 2.5203077 | H14: 2.9916177 | I14: 3.1691729 | J14: 3.3006501 | K14: 3.4383134 | L14: 3.5829907 | M14: 3.7350721 | N14: 3.8948852 | O14: 4.0627427 | P14: 4.1919374 | Q14: 4.2931482 | R14: 4.3975446 | S14: 4.507815 | T14: 4.628631 | U14: 4.7617587 | V14: 4.9055742 | W14: 5.0578663 | X14: 5.2184691 | Y14: 5.3877134 | Z14: 5.5660372 | AA14: 5.753922 | AB14: 5.9518778
B15: Flow of benefits | C15: User Costs With Project | D15: -4812.677 | E15: -5084.3337 | F15: -5355.3384 | G15: -5703.8608 | H15: -5705.4901 | I15: -5663.7252 | J15: -5981.7857 | K15: -6327.7309 | L15: -7389.7455 | M15: -7821.9258 | N15: -8249.5771 | O15: -8700.0566 | P15: -9179.3778 | Q15: -9697.0593 | R15: -10250.926 | S15: -10856.027 | T15: -11519.963 | U15: -12231.39 | V15: -13004.664 | W15: -13874.045 | X15: -14815.761 | Y15: -15829.457 | Z15: -16931.297 | AA15: -18037.806 | AB15: -19287.443
C16: User Costs Without Project | D16: -4812.677 | E16: -5085.232 | F16: -5398.2859 | G16: -5785.2502 | H16: -6292.3866 | I16: -6781.2328 | J16: -7214.5215 | K16: -7705.7699 | L16: -8363.871 | M16: -8954.5207 | N16: -9492.9395 | O16: -10042.44 | P16: -10616.863 | Q16: -11226.976 | R16: -11880.515 | S16: -12584.541 | T16: -13342.524 | U16: -14145.402 | V16: -14996.875 | W16: -15933.823 | X16: -16956.784 | Y16: -18088.345 | Z16: -19373.335 | AA16: -20776.513 | AB16: -22380.735
B19: CALCULATION: NPV and BCR of baseline optimistic scenario
B20: Baseline discounted costs | D20: =(D12+D13-D14)/(1+Parameters_Results!$D$12)^('Baseline scenario'!D$11-'Baseline scenario'!$D$11) -> 2.7755576e-17 | E20: =(E12+E13-E14)/(1+Parameters_Results!$D$12)^('Baseline scenario'!E$11-'Baseline scenario'!$D$11) -> 879.418 | F20: =(F12+F13-F14)/(1+Parameters_Results!$D$12)^('Baseline scenario'!F$11-'Baseline scenario'!$D$11) -> 865.49135 | G20: =(G12+G13-G14)/(1+Parameters_Results!$D$12)^('Baseline scenario'!G$11-'Baseline scenario'!$D$11) -> 1270.1324 | H20: =(H12+H13-H14)/(1+Parameters_Results!$D$12)^('Baseline scenario'!H$11-'Baseline scenario'!$D$11) -> 37.725795 | I20: =(I12+I13-I14)/(1+Parameters_Results!$D$12)^('Baseline scenario'!I$11-'Baseline scenario'!$D$11) -> -2.3681904 | J20: =(J12+J13-J14)/(1+Parameters_Results!$D$12)^('Baseline scenario'!J$11-'Baseline scenario'!$D$11) -> -2.3268281 | K20: =(K12+K13-K14)/(1+Parameters_Results!$D$12)^('Baseline scenario'!K$11-'Baseline scenario'!$D$11) -> -2.2866748 | ... AB20: =(AB12+AB13-AB14)/(1+Parameters_Results!$D$12)^('Baseline scenario'!AB$11-'Baseline scenario'!$D$11) -> -186.37048 | AC20: =SUM(AC12:AC14)/(1+Parameters_Results!$D$12)^('Baseline scenario'!AC$11-'Baseline scenario'!$D$11) -> 0
B21: Baseline discounted benefits | D21: =(D15-D16)/(1+Parameters_Results!$D$12)^('Baseline scenario'!D$11-'Baseline scenario'!$D$11) -> 0 | E21: =(E15-E16)/(1+Parameters_Results!$D$12)^('Baseline scenario'!E$11-'Baseline scenario'!$D$11) -> 0.84741474 | F21: =(F15-F16)/(1+Parameters_Results!$D$12)^('Baseline scenario'!F$11-'Baseline scenario'!$D$11) -> 38.223063 | G21: =(G15-G16)/(1+Parameters_Results!$D$12)^('Baseline scenario'!G$11-'Baseline scenario'!$D$11) -> 68.33614 | H21: =(H15-H16)/(1+Parameters_Results!$D$12)^('Baseline scenario'!H$11-'Baseline scenario'!$D$11) -> 464.87697 | I21: =(I15-I16)/(1+Parameters_Results!$D$12)^('Baseline scenario'!I$11-'Baseline scenario'!$D$11) -> 835.06664 | J21: =(J15-J16)/(1+Parameters_Results!$D$12)^('Baseline scenario'!J$11-'Baseline scenario'!$D$11) -> 869.03013 | K21: =(K15-K16)/(1+Parameters_Results!$D$12)^('Baseline scenario'!K$11-'Baseline scenario'!$D$11) -> 916.4746 | ... AB21: =(AB15-AB16)/(1+Parameters_Results!$D$12)^('Baseline scenario'!AB$11-'Baseline scenario'!$D$11) -> 763.9766 | AC21: =SUM(AC15:AC17)/(1+Parameters_Results!$D$12)^('Baseline scenario'!AC$11-'Baseline scenario'!$D$11) -> 0
B23: Optimistic baseline NPV | D23: =SUM(D21:XY21)-SUM(D20:XY20) -> 12065.961 | F23: Discounted cost | H23: =SUM(D20:XY20) -> 2981.248
B24: Optimistic baseline BCR | D24: =SUM(D21:XY21)/SUM(D20:XY20) -> 5.0472853 | F24: Discounted benefits | H24: =SUM(D21:XY21) -> 15047.209
B26: PESSIMISTIC BASELINE SCENARIO:
B28: INPUT: Pessimistic baseline scenario results from former CBA (no climate impact)
B29: -0.02
B30: Year | D30: =Parameters_Results!$D$10+COLUMN()-3 -> 2019 | E30: =Parameters_Results!$D$10+COLUMN()-3 -> 2020 | F30: =Parameters_Results!$D$10+COLUMN()-3 -> 2021 | G30: =Parameters_Results!$D$10+COLUMN()-3 -> 2022 | H30: =Parameters_Results!$D$10+COLUMN()-3 -> 2023 | I30: =Parameters_Results!$D$10+COLUMN()-3 -> 2024 | J30: =Parameters_Results!$D$10+COLUMN()-3 -> 2025 | K30: =Parameters_Results!$D$10+COLUMN()-3 -> 2026 | ... AC30: =Parameters_Results!$D$10+COLUMN()-3 -> 2044
B31: Flow of costs | C31: CAPEX | D31: 0 | E31: 933.08134 | F31: 974.2647 | G31: 1456.1167 | H31: 56.88 | I31: 63.00045 | J31: 0 | K31: 0 | L31: 0 | M31: 56.88 | N31: 63.00045 | O31: 0 | P31: 56.88 | Q31: 63.00045 | R31: 0 | S31: 56.88 | T31: 63.00045 | U31: 933.08134 | V31: 0 | W31: 0 | X31: 0 | Y31: 56.88 | Z31: 63.00045 | AA31: 0 | AB31: -748.65003 | AC31: 0
C32: OPEX With Project | D32: 0.14417977 | E32: 0 | F32: 0 | G32: 59.151552 | H32: 50.619565 | I32: 0 | J32: 0 | K32: 0 | L32: 0 | M32: 0.15310362 | N32: 0.07655181 | O32: 0 | P32: 0 | Q32: 0 | R32: 0 | S32: 0.0377728 | T32: 0.01783389 | U32: 0 | V32: 0 | W32: 0 | X32: 0 | Y32: 0.05590701 | Z32: 0.01783389 | AA32: 0 | AB32: 0 | AC32: 0
C33: OPEX Without Project | D33: 0.14417977 | E33: 0.89825962 | F33: 1.7986269 | G33: 2.5203077 | H33: 2.9916177 | I33: 3.1691729 | J33: 3.3006501 | K33: 3.4383134 | L33: 3.5829907 | M33: 3.7350721 | N33: 3.8948852 | O33: 4.0627427 | P33: 4.1919374 | Q33: 4.2931482 | R33: 4.3975446 | S33: 4.507815 | T33: 4.628631 | U33: 4.7617587 | V33: 4.9055742 | W33: 5.0578663 | X33: 5.2184691 | Y33: 5.3877134 | Z33: 5.5660372 | AA33: 5.753922 | AB33: 5.9518778
B34: Flow of benefits | C34: User Costs With Project | D34: -4812.677 | E34: -5084.3337 | F34: -5355.3384 | G34: -5703.8608 | H34: -5705.4901 | I34: -5663.7252 | J34: -5981.7857 | K34: -6327.7309 | L34: -7389.7455 | M34: -7821.9258 | N34: -8249.5771 | O34: -8700.0566 | P34: -9179.3778 | Q34: -9697.0593 | R34: -10250.926 | S34: -10856.027 | T34: -11519.963 | U34: -12231.39 | V34: -13004.664 | W34: -13874.045 | X34: -14815.761 | Y34: -15829.457 | Z34: -16931.297 | AA34: -18037.806 | AB34: -19287.443
C35: User Coss Without Project | D35: -4812.677 | E35: -5085.232 | F35: -5398.2859 | G35: -5785.2502 | H35: -6292.3866 | I35: -6781.2328 | J35: -7214.5215 | K35: -7705.7699 | L35: -8363.871 | M35: -8954.5207 | N35: -9492.9395 | O35: -10042.44 | P35: -10616.863 | Q35: -11226.976 | R35: -11880.515 | S35: -12584.541 | T35: -13342.524 | U35: -14145.402 | V35: -14996.875 | W35: -15933.823 | X35: -16956.784 | Y35: -18088.345 | Z35: -19373.335 | AA35: -20776.513 | AB35: -22380.735
B38: CALCULATION: NPV and BCR of baseline pessimistic scenario
B39: Baseline discounted costs | D39: =(D31+D32-D33)/(1+Parameters_Results!$D$12)^('Baseline scenario'!D$30-'Baseline scenario'!$D$30) -> 2.7755576e-17 | E39: =SUM(E31:E33)/(1+Parameters_Results!$D$12)^('Baseline scenario'!E$30-'Baseline scenario'!$D$30) -> 881.11283 | F39: =SUM(F31:F33)/(1+Parameters_Results!$D$12)^('Baseline scenario'!F$30-'Baseline scenario'!$D$30) -> 868.69289 | G39: =SUM(G31:G33)/(1+Parameters_Results!$D$12)^('Baseline scenario'!G$30-'Baseline scenario'!$D$30) -> 1274.3646 | H39: =SUM(H31:H33)/(1+Parameters_Results!$D$12)^('Baseline scenario'!H$30-'Baseline scenario'!$D$30) -> 87.519366 | I39: =SUM(I31:I33)/(1+Parameters_Results!$D$12)^('Baseline scenario'!I$30-'Baseline scenario'!$D$30) -> 49.445792 | J39: =SUM(J31:J33)/(1+Parameters_Results!$D$12)^('Baseline scenario'!J$30-'Baseline scenario'!$D$30) -> 2.3268281 | K39: =SUM(K31:K33)/(1+Parameters_Results!$D$12)^('Baseline scenario'!K$30-'Baseline scenario'!$D$30) -> 2.2866748 | L39: =SUM(L31:L33)/(1+Parameters_Results!$D$12)^('Baseline scenario'!L$30-'Baseline scenario'!$D$30) -> 2.2480127 | ... AC39: =SUM(AC31:AC33)/(1+Parameters_Results!$D$12)^('Baseline scenario'!AC$30-'Baseline scenario'!$D$30) -> 0
B40: Baseline discounted benefits | D40: =(D34-D35)/(1+Parameters_Results!$D$12)^('Baseline scenario'!D$30-'Baseline scenario'!$D$30) -> 0 | E40: =(E34-E35)/(1+Parameters_Results!$D$12)^('Baseline scenario'!E$30-'Baseline scenario'!$D$30) -> 0.84741474 | F40: =(F34-F35)/(1+Parameters_Results!$D$12)^('Baseline scenario'!F$30-'Baseline scenario'!$D$30) -> 38.223063 | G40: =(G34-G35)/(1+Parameters_Results!$D$12)^('Baseline scenario'!G$30-'Baseline scenario'!$D$30) -> 68.33614 | H40: =(H34-H35)/(1+Parameters_Results!$D$12)^('Baseline scenario'!H$30-'Baseline scenario'!$D$30) -> 464.87697 | I40: =(I34-I35)/(1+Parameters_Results!$D$12)^('Baseline scenario'!I$30-'Baseline scenario'!$D$30) -> 835.06664 | J40: =(J34-J35)/(1+Parameters_Results!$D$12)^('Baseline scenario'!J$30-'Baseline scenario'!$D$30) -> 869.03013 | K40: =(K34-K35)/(1+Parameters_Results!$D$12)^('Baseline scenario'!K$30-'Baseline scenario'!$D$30) -> 916.4746 | ... AB40: =(AB34-AB35)/(1+Parameters_Results!$D$12)^('Baseline scenario'!AB$30-'Baseline scenario'!$D$30) -> 763.9766 | AC40: =SUM(AC34:AC36)/(1+Parameters_Results!$D$12)^('Baseline scenario'!AC$30-'Baseline scenario'!$D$30) -> 0
B42: Pessimistic baseline NPV | D42: =SUM(D40:XY40)-SUM(D39:XY39) -> 11478.861 | F42: Discounted cost | H42: =SUM(D39:XY39) -> 3568.3482
B43: Pessimistic baseline BCR | D43: =SUM(D40:XY40)/SUM(D39:XY39) -> 4.2168557 | F43: Discounted benefits | H43: =SUM(D40:XY40) -> 15047.209

Sheet Climate impacts
B2: Climate risks input parameters
B3: Inputs needed to calculate climate change impacts on project's costs and benefits
B5: Please fill all green fields | F5: -1
B7: INPUT (Step 2a): Estimates to assess the economic impacts of changes in average conditions
B8: Guidance: For guidance on how to estimate the required input please see "Guidance Note" chapter xy
D9: =Parameters_Results!D10 -> 2018 | F9: 2030 | H9: 2050 | J9: 2100
B10: Climate impact scenario: | F10: No/low impact | G10: High impact | H10: No/low impact | I10: High impact | J10: No/low impact | K10: High impact
B11: Expected change in user costs and operations cost, in % | C11: User costs with project | F11: 0 | G11: -0.004 | H11: -0.004 | I11: -0.008
C12: User costs without project | F12: -0.009 | G12: -0.012 | H12: -0.022 | I12: -0.041
B14: Expected change in price/value of supply, in % | C14: User costs with project | F14: 0 | G14: 0 | H14: 0 | I14: 0
C15: User costs without project | F15: 0 | G15: 0 | H15: 0 | I15: 0
B17: Expected change in investment costs, in % | C17: CAPEX | F17: 0 | G17: 0 | H17: 0 | I17: 0
C18: OPEX With Project | F18: 0.01 | G18: 0.02 | H18: 0.02 | I18: 0.04
C19: OPEX Without Project | F19: 0.04 | G19: 0.06 | H19: 0.08 | I19: 0.1
B21: Disaster 1 - | G21: Disaster 2 - Floods | L21: Disaster 3 - [Landslides]
B22: INPUT (Step 2b i): Estimates to assess the economic impacts of natural disasters in the current context | G22: INPUT (Step 2b ii): Estimates to assess the economic impacts of natural disasters in the current context | L22: INPUT (Step 2b iii): Estimates to assess the economic impacts of natural disasters in the current context
B23: Guidance: - Team has to assess the impacts of extreme events, for various probabilities of occurrence (or return periods). If the team wants only 2 or 3 intensity levels, then they can start from the most extreme (at the bottom) and fill the various levels going up, puting zero impacts for the residual ones. - Impacts of extreme events are in three metrics: impact of project outputs (%), repair/reconstruction costs (monetary), and additional out-of-system impacts (monetary). For guidance on how to estimate impacts, please see "Guidance Note" chapter xy - Return periods (yellow cells) are pre-selected, but can be modified | G23: Guidance : Follow the same instructions as the previous box for another natural disaster that you would like to include in your analysis | L23: Guidance: Follow the same instructions as the first box for another natural disaster that you would like to include in your analysis
D24: =Parameters_Results!D10 -> 2018 | I24: =Parameters_Results!D10 -> 2018 | N24: =Parameters_Results!D10 -> 2018
B25: Climate impact scenario : | D25: No/low impact | E25: High impact | G25: Climate impact scenario : | I25: No/low impact | J25: High impact | L25: Climate impact scenario: | N25: No/low impact | O25: High impact
B26: Weak intensity level | G26: Weak intensity level | L26: Weak intensity level
B27: Return period (to calculate probability of occurrence), in years | D27: 2 | G27: Return period (to calculate probability of occurrence), in years | I27: 2 | L27: Return period (to calculate probability of occurrence), in years | N27: 2
B28: Impact on quantity produced, in % of yearly output with project | D28: 0 | E28: 0 | G28: Impact on quantity produced, in % of yearly output with project | I28: 0 | J28: 0 | L28: Impact on quantity produced, in % of yearly output | N28: 0 | O28: 0
B29: Impact on quantity produced, in % of yearly output without project | D29: 0 | E29: 0 | G29: Impact on quantity produced, in % of yearly output without project | I29: 0 | J29: 0 | N29: 0 | O29: 0
B30: Repair/Reconstruction cost (CAPEX), in absolute amount/monetary unit | D30: 0 | E30: 0 | G30: Repair/Reconstruction cost (CAPEX), in absolute amount/monetary unit | I30: 0 | J30: 0 | L30: Repair/Reconstruction cost (CAPEX), in absolute amount/monetary unit | N30: 0 | O30: 0
B31: Additional out-of-system impacts, in absolute amount/monetary unit | D31: 0 | E31: 0 | G31: Additional out-of-system impacts, in absolute amount/monetary unit | I31: 0 | J31: 0 | L31: Additional out-of-system impacts, in absolute amount/monetary unit | N31: 0 | O31: 0
B32: Moderate intensity level | G32: Moderate intensity level | L32: Moderate intensity level
B33: Return period (to calculate probability of occurrence), in years | D33: 10 | G33: Return period (to calculate probability of occurrence), in years | I33: 10 | L33: Return period (to calculate probability of occurrence), in years | N33: 10
B34: Impact on quantity produced, in % of yearly output with project | D34: 0 | E34: 0 | G34: Impact on quantity produced, in % of yearly output with project | I34: -0.24657534 | J34: -0.49315068 | L34: Impact on quantity produced, in % of yearly output | N34: -0.49315068 | O34: -0.73972603
B35: Impact on quantity produced, in % of yearly output without project | D35: 0 | E35: 0 | G35: Impact on quantity produced, in % of yearly output without project | I35: -0.49315068 | J35: -0.73972603 | N35: -0.61643836 | O35: -0.8630137
B36: Repair/Reconstruction cost (CAPEX), in absolute amount/monetary unit | D36: 0 | E36: 0 | G36: Repair/Reconstruction cost (CAPEX), in absolute amount/monetary unit | I36: =I54*$C$54 -> 297.44541 | J36: =J54*$C$54 -> 594.89081 | L36: Repair/Reconstruction cost (CAPEX), in absolute amount/monetary unit | N36: =N54*$H54 -> 297.44541 | O36: =O54*$H54 -> 594.89081
B37: Additional out-of-system impacts, in absolute amount/monetary unit | D37: 0 | E37: 0 | G37: Additional out-of-system impacts, in absolute amount/monetary unit | I37: 0 | J37: 0 | L37: Additional out-of-system impacts, in absolute amount/monetary unit | N37: 0 | O37: 0
B38: Strong intensity level | G38: Strong intensity level | L38: Strong intensity level
B39: Return period (to calculate probability of occurrence), in years | D39: 100 | G39: Return period (to calculate probability of occurrence), in years | I39: 100 | L39: Return period (to calculate probability of occurrence), in years | N39: 100
B40: Impact on quantity produced, in % of yearly output with project | D40: 0 | E40: 0 | G40: Impact on quantity produced, in % of yearly output with project | I40: -0.14794521 | J40: -0.19726027 | L40: Impact on quantity produced, in % of yearly output | N40: -0.19726027 | O40: -0.29589041
B41: Impact on quantity produced, in % of yearly output without project | D41: 0 | E41: 0 | G41: Impact on quantity produced, in % of yearly output without project | I41: -0.19726027 | J41: -0.29589041 | L41: Impact on quantity produced, in % of yearly output without project | N41: -0.22191781 | O41: -0.32054795
B42: Repair/Reconstruction cost (CAPEX), in absolute amount/monetary unit | D42: 0 | E42: 0 | G42: Repair/Reconstruction cost (CAPEX), in absolute amount/monetary unit | I42: =I55*$C55 -> 743.61352 | J42: =J55*$C55 -> 1041.0589 | L42: Repair/Reconstruction cost (CAPEX), in absolute amount/monetary unit | N42: =N55*$H55 -> 743.61352 | O42: =O55*$H55 -> 1041.0589
B43: Additional out-of-system impacts, in absolute amount/monetary unit | D43: 0 | E43: 0 | G43: Additional out-of-system impacts, in absolute amount/monetary unit | I43: 0 | J43: 0 | L43: Additional out-of-system impacts, in absolute amount/monetary unit | N43: 0 | O43: 0
B44: Extreme intensity level | G44: Extreme intensity level | L44: Extreme intensity level
B45: Return period (to calculate probability of occurrence), in years | D45: 1000 | G45: Return period (to calculate probability of occurrence), in years | I45: 1000 | L45: Return period (to calculate probability of occurrence), in years | N45: 1000
B46: Impact on quantity produced, in % of yearly output with project | D46: 0 | E46: 0 | G46: Impact on quantity produced, in % of yearly output with project | I46: -0.036986301 | J46: -0.051780822 | L46: Impact on quantity produced, in % of yearly output | N46: -0.059178082 | O46: -0.073972603
...

Sheet Extrapolation disasters
B1: SIMULATION
B3: Calculation: (2bi) | I3: Calculation (2b ii) | P3: Calculation: (2biii)
B4: Calculates one weighted value per year based on selected "level of climate impact" in "Input_Parameters" | I4: Calculates one weighted value per year based on selected "level of climate impact" in "Input_Parameters" | P4: Calculates one weighted value per year based on selected "level of climate impact" in "Input_Parameters"
B5: Input: All from "Input_Parameters" | I5: Input: All from "Input_Parameters" | P5: Input: All from "Input_Parameters"
B7: Natural disasters | D7: =Parameters_Results!D10 -> 2018 | E7: 2030 | F7: 2050 | G7: 2100 | I7: Natural Disasters | K7: 2020 | L7: 2030 | M7: 2050 | N7: 2100 | P7: Natural disasters | R7: 2020 | S7: 2030 | T7: 2050 | U7: 2100
B8: Once every 2 years | I8: Once every 2 years | P8: Once every 2 years
B9: Return period | D9: ='Climate impacts'!D27 -> 2 | E9: =Parameters_Results!$D$20*'Climate impacts'!G63+(1-Parameters_Results!$D$24)*'Climate impacts'!F63 -> 2 | F9: =Parameters_Results!$D$20*'Climate impacts'!I63+(1-Parameters_Results!$D$20)*'Climate impacts'!H63 -> 2 | G9: =Parameters_Results!$D$20*'Climate impacts'!K63+(1-Parameters_Results!$D$20)*'Climate impacts'!J63 -> 0 | I9: Return period | K9: ='Climate impacts'!I27 -> 2 | L9: =Parameters_Results!$D$22*'Climate impacts'!P63+(1-Parameters_Results!$D$22)*'Climate impacts'!O63 -> 2 | M9: =Parameters_Results!$D$22*'Climate impacts'!R63+(1-Parameters_Results!$D$22)*'Climate impacts'!Q63 -> 2 | N9: =Parameters_Results!$D$22*'Climate impacts'!T63+(1-Parameters_Results!$D$22)*'Climate impacts'!S63 -> 0 | P9: Return period | R9: ='Climate impacts'!N27 -> 2 | S9: =Parameters_Results!$D$24*'Climate impacts'!Z63+(1-Parameters_Results!$D$24)*'Climate impacts'!Y63 -> 2 | T9: =Parameters_Results!$D$24*'Climate impacts'!AB63+(1-Parameters_Results!$D$24)*'Climate impacts'!AA63 -> 2 | U9: =Parameters_Results!$D$24*'Climate impacts'!AD63+(1-Parameters_Results!$D$24)*'Climate impacts'!AC63 -> 0
B10: Impact on quantity produced (% of yearly output) | D10: =Parameters_Results!$D$19*'Climate impacts'!E28+(1-Parameters_Results!$D$19)*'Climate impacts'!D28 -> 0 | E10: =Parameters_Results!$D$19*'Climate impacts'!G64+(1-Parameters_Results!$D$19)*'Climate impacts'!F64 -> 0 | F10: =Parameters_Results!$D$19*'Climate impacts'!I64+(1-Parameters_Results!$D$19)*'Climate impacts'!H64 -> 0 | G10: =Parameters_Results!$D$19*'Climate impacts'!K64+(1-Parameters_Results!$D$19)*'Climate impacts'!J64 -> 0 | I10: Impact on quantity produced (% of yearly output) | K10: =Parameters_Results!$D$21*'Climate impacts'!J28+(1-Parameters_Results!$D$21)*'Climate impacts'!I28 -> 0 | L10: =Parameters_Results!$D$21*'Climate impacts'!P64+(1-Parameters_Results!$D$21)*'Climate impacts'!O64 -> 0 | M10: =Parameters_Results!$D$21*'Climate impacts'!R64+(1-Parameters_Results!$D$21)*'Climate impacts'!Q64 -> 0 | N10: =Parameters_Results!$D$21*'Climate impacts'!T64+(1-Parameters_Results!$D$21)*'Climate impacts'!S64 -> 0 | P10: Impact on quantity produced (% of yearly output) | R10: =Parameters_Results!$D$23*'Climate impacts'!O28+(1-Parameters_Results!$D$23)*'Climate impacts'!N28 -> 0 | S10: =Parameters_Results!$D$23*'Climate impacts'!Z64+(1-Parameters_Results!$D$23)*'Climate impacts'!Y64 -> 0 | T10: =Parameters_Results!$D$23*'Climate impacts'!AA64+(1-Parameters_Results!$D$23)*'Climate impacts'!Z64 -> 0 | U10: =Parameters_Results!$D$23*'Climate impacts'!AD64+(1-Parameters_Results!$D$23)*'Climate impacts'!AC64 -> 0
B11: Impact on quantity produced (% of yearly output) without project | D11: =Parameters_Results!$D$19*'Climate impacts'!E29+(1-Parameters_Results!$D$19)*'Climate impacts'!D29 -> 0 | E11: =Parameters_Results!$D$19*'Climate impacts'!G65+(1-Parameters_Results!$D$19)*'Climate impacts'!F65 -> 0 | F11: =Parameters_Results!$D$19*'Climate impacts'!I65+(1-Parameters_Results!$D$19)*'Climate impacts'!H65 -> 0 | G11: =Parameters_Results!$D$19*'Climate impacts'!K65+(1-Parameters_Results!$D$19)*'Climate impacts'!J65 -> 0 | I11: Impact on quantity produced (% of yearly output) without project | K11: =Parameters_Results!$D$21*'Climate impacts'!J29+(1-Parameters_Results!$D$21)*'Climate impacts'!I29 -> 0 | L11: =Parameters_Results!$D$21*'Climate impacts'!P65+(1-Parameters_Results!$D$21)*'Climate impacts'!O65 -> 0 | M11: =Parameters_Results!$D$21*'Climate impacts'!R65+(1-Parameters_Results!$D$21)*'Climate impacts'!Q65 -> 0 | N11: =Parameters_Results!$D$21*'Climate impacts'!T65+(1-Parameters_Results!$D$21)*'Climate impacts'!S65 -> 0 | P11: Impact on quantity produced (% of yearly output) without project | R11: =Parameters_Results!$D$23*'Climate impacts'!O29+(1-Parameters_Results!$D$23)*'Climate impacts'!N29 -> 0 | S11: =Parameters_Results!$D$23*'Climate impacts'!Z66+(1-Parameters_Results!$D$23)*'Climate impacts'!Y66 -> 0 | T11: =Parameters_Results!$D$23*'Climate impacts'!AA66+(1-Parameters_Results!$D$23)*'Climate impacts'!Z66 -> 0 | U11: =Parameters_Results!$D$23*'Climate impacts'!AD66+(1-Parameters_Results!$D$23)*'Climate impacts'!AC66 -> 0
B12: Repair/Reconstruction cost (CAPEX) | D12: =Parameters_Results!$D$19*'Climate impacts'!D29+(1-Parameters_Results!$D$19)*'Climate impacts'!D30 -> 0 | E12: =Parameters_Results!$D$19*'Climate impacts'!G66+(1-Parameters_Results!$D$19)*'Climate impacts'!F66 -> 0 | F12: =Parameters_Results!$D$19*'Climate impacts'!I66+(1-Parameters_Results!$D$19)*'Climate impacts'!H66 -> 0 | G12: =Parameters_Results!$D$19*'Climate impacts'!K66+(1-Parameters_Results!$D$19)*'Climate impacts'!J66 -> 0 | I12: Repair/Reconstruction cost (CAPEX) | K12: =Parameters_Results!$D$21*'Climate impacts'!J30+(1-Parameters_Results!$D$21)*'Climate impacts'!I30 -> 0 | L12: =Parameters_Results!$D$21*'Climate impacts'!P66+(1-Parameters_Results!$D$21)*'Climate impacts'!O66 -> 0 | M12: =Parameters_Results!$D$21*'Climate impacts'!R66+(1-Parameters_Results!$D$21)*'Climate impacts'!Q66 -> 0 | N12: =Parameters_Results!$D$21*'Climate impacts'!T66+(1-Parameters_Results!$D$21)*'Climate impacts'!S66 -> 0 | P12: Repair/Reconstruction cost (CAPEX) | R12: =Parameters_Results!$D$23*'Climate impacts'!O30+(1-Parameters_Results!$D$23)*'Climate impacts'!N30 -> 0 | S12: =Parameters_Results!$D$23*'Climate impacts'!Z66+(1-Parameters_Results!$D$23)*'Climate impacts'!Y66 -> 0 | T12: =Parameters_Results!$D$23*'Climate impacts'!AA66+(1-Parameters_Results!$D$23)*'Climate impacts'!Z66 -> 0 | U12: =Parameters_Results!$D$23*'Climate impacts'!AD66+(1-Parameters_Results!$D$23)*'Climate impacts'!AC66 -> 0
B13: Additional out-of-system impacts | D13: =Parameters_Results!$D$19*'Climate impacts'!E31+(1-Parameters_Results!$D$19)*'Climate impacts'!D31 -> 0 | E13: =Parameters_Results!$D$19*'Climate impacts'!G67+(1-Parameters_Results!$D$19)*'Climate impacts'!F67 -> 0 | F13: =Parameters_Results!$D$19*'Climate impacts'!I67+(1-Parameters_Results!$D$19)*'Climate impacts'!H67 -> 0 | G13: =Parameters_Results!$D$19*'Climate impacts'!K67+(1-Parameters_Results!$D$19)*'Climate impacts'!J67 -> 0 | I13: Additional out-of-system impacts | K13: =Parameters_Results!$D$21*'Climate impacts'!J31+(1-Parameters_Results!$D$21)*'Climate impacts'!I31 -> 0 | L13: =Parameters_Results!$D$21*'Climate impacts'!P67+(1-Parameters_Results!$D$21)*'Climate impacts'!O67 -> 0 | M13: =Parameters_Results!$D$21*'Climate impacts'!R67+(1-Parameters_Results!$D$21)*'Climate impacts'!Q67 -> 0 | N13: =Parameters_Results!$D$21*'Climate impacts'!T67+(1-Parameters_Results!$D$21)*'Climate impacts'!S67 -> 0 | P13: Additional out-of-system impacts | R13: =Parameters_Results!$D$23*'Climate impacts'!O31+(1-Parameters_Results!$D$23)*'Climate impacts'!N31 -> 0 | S13: =Parameters_Results!$D$23*'Climate impacts'!Z67+(1-Parameters_Results!$D$23)*'Climate impacts'!Y67 -> 0 | T13: =Parameters_Results!$D$23*'Climate impacts'!AA67+(1-Parameters_Results!$D$23)*'Climate impacts'!Z67 -> 0 | U13: =Parameters_Results!$D$23*'Climate impacts'!AD67+(1-Parameters_Results!$D$23)*'Climate impacts'!AC67 -> 0
B14: Once every 10 years | I14: Once every 10 years | P14: Once every 10 years
B15: Return period | D15: ='Climate impacts'!D33:E33 -> 10 | E15: =Parameters_Results!$D$20*'Climate impacts'!G69+(1-Parameters_Results!$D$20)*'Climate impacts'!F69 -> 5 | F15: =Parameters_Results!$D$20*'Climate impacts'!I69+(1-Parameters_Results!$D$20)*'Climate impacts'!H69 -> 5 | G15: =Parameters_Results!$D$20*'Climate impacts'!K69+(1-Parameters_Results!$D$20)*'Climate impacts'!J69 -> 0 | I15: Return period | K15: ='Climate impacts'!I33 -> 10 | L15: =Parameters_Results!$D$22*'Climate impacts'!P69+(1-Parameters_Results!$D$22)*'Climate impacts'!O69 -> 5 | M15: =Parameters_Results!$D$22*'Climate impacts'!R69+(1-Parameters_Results!$D$22)*'Climate impacts'!Q69 -> 5 | N15: =Parameters_Results!$D$22*'Climate impacts'!T69+(1-Parameters_Results!$D$22)*'Climate impacts'!S69 -> 0 | P15: Return period | R15: ='Climate impacts'!N33 -> 10 | S15: =Parameters_Results!$D$24*'Climate impacts'!Z69+(1-Parameters_Results!$D$24)*'Climate impacts'!Y69 -> 5 | T15: =Parameters_Results!$D$24*'Climate impacts'!AB69+(1-Parameters_Results!$D$24)*'Climate impacts'!AA69 -> 5 | U15: =Parameters_Results!$D$24*'Climate impacts'!AD69+(1-Parameters_Results!$D$24)*'Climate impacts'!AC69 -> 0
B16: Impact on quantity produced (% of yearly output) with project | D16: =Parameters_Results!$D$19*'Climate impacts'!E34+(1-Parameters_Results!$D$19)*'Climate impacts'!D34 -> 0 | E16: =Parameters_Results!$D$19*'Climate impacts'!G70+(1-Parameters_Results!$D$19)*'Climate impacts'!F70 -> 0 | F16: =Parameters_Results!$D$19*'Climate impacts'!I70+(1-Parameters_Results!$D$19)*'Climate impacts'!H70 -> 0 | G16: =Parameters_Results!$D$19*'Climate impacts'!K70+(1-Parameters_Results!$D$19)*'Climate impacts'!J70 -> 0 | I16: Impact on quantity produced (% of yearly output) | K16: =Parameters_Results!$D$21*'Climate impacts'!J34+(1-Parameters_Results!$D$21)*'Climate impacts'!I34 -> -0.49315068 | L16: =Parameters_Results!$D$21*'Climate impacts'!P70+(1-Parameters_Results!$D$21)*'Climate impacts'!O70 -> -0.49315068 | M16: =Parameters_Results!$D$21*'Climate impacts'!R70+(1-Parameters_Results!$D$21)*'Climate impacts'!Q70 -> -0.49315068 | N16: =Parameters_Results!$D$21*'Climate impacts'!T70+(1-Parameters_Results!$D$21)*'Climate impacts'!S70 -> -0.49315068 | P16: Impact on quantity produced (% of yearly output) | R16: =Parameters_Results!$D$23*'Climate impacts'!O34+(1-Parameters_Results!$D$23)*'Climate impacts'!N34 -> -0.73972603 | S16: =Parameters_Results!$D$23*'Climate impacts'!Z70+(1-Parameters_Results!$D$23)*'Climate impacts'!Y70 -> -0.73972603 | T16: =Parameters_Results!$D$23*'Climate impacts'!AB70+(1-Parameters_Results!$D$23)*'Climate impacts'!AA70 -> -0.73972603 | U16: =Parameters_Results!$D$23*'Climate impacts'!AD70+(1-Parameters_Results!$D$23)*'Climate impacts'!AC70 -> -0.73972603
