Workbook
Name cce: Translation!$C$256
Name Country: Country_data!$B$2:$B$197
Name Country: Country_data!$B$2:$B$197
Name cr: Translation!$C$254
Name Eqpt_list: PQEquipment!$D$6:$D$97
Name filtr: Translation!$C$325:$C$327
Name Formulation: Vaccine_database!$D$10:$D$278
Name fr: Translation!$C$255
Name freez: Translation!$C$258
Name Icepack_Freezers: Supplies!$C$51:$C$60
Name Icepacks: Supplies!$E$50:$G$50
Name Langues: Translation!$D$9:$I$9
Name Langues: Translation!$D$9:$I$9
Name max: Translation!$C$326
Name min: Translation!$C$325
Name Passive_contain: Supplies!$C$64:$C$71
Name per_individual_vaccine: Translation!$C$21:$C$24
Name refr: Translation!$C$257
Name Schedule: Vaccine_Selection!$M$16:$Q$16
Name SIAs: Vaccine_Selection!$S$16:$U$16
Name smax: Abacus_Tables!$F$4:$F$7
Name target: Translation!XFC$314:XFC$315
Name target1: Translation!$C$314
Name target2: Translation!$C$315
Name Vaccines: OFFSET([1]Vaccine_database!$B$11,0,0,COUNTA([1]Vaccine_database!$B$1:$B$65536)-1,1)
Name Vaccines: Vaccine_database!$C$10:$C$278
Name Vaccines1: OFFSET([2]Vaccine_database!$B$221,0,0,COUNTA([2]Vaccine_database!$B1048574:$B36)-1,1)
Name Vaccines1: Vaccine_database!$B$283:$B$325
Name WICR: Supplies!$B$36:$B$46
Name WICR_list: Supplies!$C$36:$C$46
Name WIFR: Supplies!$N$36:$N$46

Sheet Cover
C3: =Translation!C90 -> V A C C I N E V O L U M E C A L C U L A T O R
C10: =Translation!C91 -> Country: | D10: Erehwonia
C12: =Translation!C92 -> Language: | D12: English
C14: =Translation!C93 -> Date: | D14: 40919
D18: =Translation!C94 -> Click to index page
D20: =Translation!C95 -> v 2012.1 - January 2012
E27: Contact: kones@who.int

Sheet Index
B2: =Translation!C96 -> Index and instructions
B3: =Translation!C104 -> 1) The Vaccine Volume Calculator is used to estimate the net volume of vaccines and related supplies at each level in the supply chain. It can also be used to estimate the type of cold chain equipment needed for a specific target population. The effect of new vaccine introductions can be tested by comparing one or more of these against the current schedule.
B4: =Translation!C105 -> 2) How to use the tool:
B5: =Translation!C106 -> STEP 1: Estimate net storage volume per recipient using the Vaccine_Selection worksheet.
B6: =Translation!C107 -> STEP 2: Use the Abacus_Tables worksheet to enter the data needed to generate graphs covering the range of target populations at each supply level.
B7: =Translation!C108 -> STEP 3: Use the graphs to read off the net storage volumes for a specific catchment population. Then use these data to select appropriate cold chain equipment.
B8: =Translation!C99 -> Data input sheets:
B9: =MID(D9,FIND("]",D9)+1,256) -> Vaccine_Selection | C9: =Vaccine_Selection!B2 -> Vaccine storage volumes | D9: =CELL("filename",Vaccine_Selection!A$1) -> C:\Users\WHO\Downloads\[vaccine_volume_calculator_2012.xlsx]Vaccine_Selection
B10: =MID(D10,FIND("]",D10)+1,256) -> Abacus_Tables | C10: =Abacus_Tables!B1 -> Analysis of national and sub-national storage | D10: =CELL("filename",Abacus_Tables!A$1) -> C:\Users\WHO\Downloads\[vaccine_volume_calculator_2012.xlsx]Abacus_Tables
B11: =Translation!C101 -> Data output sheets: results of assessment of requirements per recipient
B12: =MID(D12,FIND("]",D12)+1,256) -> Volume_Inject | C12: =Volume_Inject!$B$2 -> Volume of diluents and safe injection equipment per recipient | D12: =CELL("filename",Volume_Inject!A$1) -> C:\Users\WHO\Downloads\[vaccine_volume_calculator_2012.xlsx]Volume_Inject
B13: =MID(D13,FIND("]",D13)+1,256) -> Weight_Inject | C13: =Weight_Inject!$B$2 -> Weight of safe injection equipment per recipient | D13: =CELL("filename",Weight_Inject!A$1) -> C:\Users\WHO\Downloads\[vaccine_volume_calculator_2012.xlsx]Weight_Inject
B14: =MID(D14,FIND("]",D14)+1,256) -> Qty_Waste | C14: =Qty_Waste!$B$2 -> Estimate of the amount of injection waste generated per recipient | D14: =CELL("filename",Qty_Waste!A$1) -> C:\Users\WHO\Downloads\[vaccine_volume_calculator_2012.xlsx]Qty_Waste
B15: =MID(D15,FIND("]",D15)+1,256) -> Cost_Supplies | C15: =Cost_Supplies!$B$2 -> Cost of vaccines and safe injection equipment per recipient | D15: =CELL("filename",Cost_Supplies!A$1) -> C:\Users\WHO\Downloads\[vaccine_volume_calculator_2012.xlsx]Cost_Supplies
B16: =Translation!C100 -> Data output sheets: graphical illustration of results
B17: =MID(D17,FIND("]",D17)+1,256) -> Routine_illustration | C17: =Routine_illustration!B2 -> Illustration of results from analysis of vaccines used in routine vaccination | D17: =CELL("filename",Routine_illustration!A$1) -> C:\Users\WHO\Downloads\[vaccine_volume_calculator_2012.xlsx]Routine_illustration
B18: =MID(D18,FIND("]",D18)+1,256) -> SIAs_illustration | C18: =SIAs_illustration!B2 -> Illustration of results from analysis of vaccines planned for vaccination campaign | D18: =CELL("filename",SIAs_illustration!A$1) -> C:\Users\WHO\Downloads\[vaccine_volume_calculator_2012.xlsx]SIAs_illustration
B19: =Translation!C102 -> Graphs
B20: Abacus_NatStore_1 | C20: =Translation!D30 -> Graph for cold storage capacity at national and sub-national stores - @ +5°C: (different schedules with same Maximum Stock)
B21: Abacus_NatStore_2 | C21: =Translation!D32 -> Graph for cold storage capacity at national and sub-national stores - @ +5°C: (same schedule with different Maximum Stocks)
B22: Abacus_Dist_1 | C22: =Translation!D48 -> Graph for cold storage capacity at district stores - @ +5°C: (different schedules with same Maximum Stock)
B23: Abacus_Dist_2 | C23: =Translation!D50 -> Graph for cold storage capacity at district stores - @ +5°C: (same schedule with different Maximum Stocks)
B24: Abacus_SP_1 | C24: =Translation!D58 -> Graph for cold storage capacity at service points - @ +5°C: (different schedules with same Maximum Stock)
B25: Abacus_SP_2 | C25: =Translation!D60 -> Graph for cold storage capacity at service points - @ +5°C: (same schedule with different Maximum Stocks)
B26: ds_Abacus_NatStore_1 | C26: =Translation!D34 -> Graph for dry storage capacity at national and sub-national stores: (different schedules with same Maximum Stock)
B27: ds_Abacus_NatStore_2 | C27: =Translation!D36 -> Graph for dry storage capacity at national and sub-national stores: (same schedule with different Maximum Stocks)
B28: ds_Abacus_Dist_1 | C28: =Translation!D52 -> Graph for dry storage capacity at district stores: (different schedules with same Maximum Stock)
B29: ds_Abacus_Dist_2 | C29: =Translation!D54 -> Graph for dry storage capacity at district stores: (same schedule with different Maximum Stocks)
B30: ds_Abacus_SP_1 | C30: =Translation!D62 -> Graph for dry storage capacity at service points (different schedules with same Maximum Stock)
B31: ds_Abacus_SP_2 | C31: =Translation!D64 -> Graph for dry storage capacity at service points: (same schedule with different Maximum Stocks)
B32: =Translation!C103 -> Sheets with reference data:
B33: =MID(D33,FIND("]",D33)+1,256) -> Vaccine_database | C33: =Vaccine_database!B1 -> Vaccine database | D33: =CELL("filename",Vaccine_database!B$1) -> C:\Users\WHO\Downloads\[vaccine_volume_calculator_2012.xlsx]Vaccine_database
B34: =MID(D34,FIND("]",D34)+1,256) -> Supplies | C34: =Supplies!B2 -> Safe injection supplies and cold chain equipment | D34: =CELL("filename",Supplies!A$1) -> C:\Users\WHO\Downloads\[vaccine_volume_calculator_2012.xlsx]Supplies
B35: PQEquipment | C35: =PQEquipment!B1 -> Refrigerator and freezer database
B36: =MID(D36,FIND("]",D36)+1,256) -> Passive_containers | C36: =Passive_containers!B1 -> Passive container database | D36: =CELL("filename",Passive_containers!B2) -> C:\Users\WHO\Downloads\[vaccine_volume_calculator_2012.xlsx]Passive_containers
B37: =MID(D37,FIND("]",D37)+1,256) -> Translation | C37: =Translation!B1 -> Translation | D37: =CELL("filename",Translation!A1) -> C:\Users\WHO\Downloads\[vaccine_volume_calculator_2012.xlsx]Translation

Sheet Vaccine_Selection
B2: =Translation!C311 -> Vaccine storage volumes | V2: =Translation!C109 -> Index
B5: =Translation!C317 -> STEP 1: Choose vaccine filter: | D5: Average | E5: =Translation!C328 -> WARNING: The packed volume for each vaccine presentation differs between manufacturers. Select 'Min/Max/Average' depending upon whether you want to use the minimum, maximum or average packed volume per vaccine presentation from the vaccine database.
B6: =Translation!C318 -> STEP 2: Choose applicable vaccine types and presentations from the vaccine database. Optionally, enter volume/dose data for vaccine types that are not in the database.
B7: =Translation!C319 -> STEP 3: Indicate country-specific wastage rates for each vaccine. If there no national data, WHO/GAVI indicative rates will apply.
B8: =Translation!C320 -> STEP 4: Choose target group type: | E8: Unit of Population | G8: =Translation!C316 -> Choose 'FIC' (Fully Immunized Child) or choose 'Unit of Population' (UP) for an analysis based on percentage of total population receiving each vaccine. | AC8: =IF(E8=target1,target1,"")
B9: =Translation!C321 -> STEP 5: If you chosen 'Unit of Population' in step 5, enter the Unit of Population % for each vaccine in cells L18 to L37. Otherwise go to STEP 6.
B10: =Translation!C322 -> STEP 6: In column M, enter the number of doses per recipient for vaccines in the current schedule. Optionally use columns N to Q for alternative schedules. In cells N17 to Q17 enter a title for each schedule.
B11: =Translation!C323 -> STEP 7: Use columns S to U to enter the number of doses per recipient for planned mass vaccination campaigns. In cells S17 to U17 enter a title for each schedule.
B12: =Translation!C324 -> STEP 8: For each vaccine, enter the maximum supply interval and the safety stock level at the primary store.
B14: =Translation!C329 -> Characteristics of vaccines selected for use | I14: =Translation!C340 -> Vaccine wastage | L14: =Translation!C344 -> UP data | M14: =Translation!C346 -> National immunization schedule | S14: =Translation!C349 -> Supplementary | V14: =Translation!C351 -> Primary store | Y14: =M14 -> National immunization schedule
B15: =Translation!C330 -> Vaccine | C15: =Translation!C331 -> Presentation | D15: =Translation!C333 -> National figures | F15: =Translation!C335 -> from data base | H15: =Translation!C338 -> Price | M15: =Translation!C347 -> (Routine vaccinations) | S15: =Translation!C350 -> activities (SIAs) | V15: =Translation!C352 -> supply parameters (months) | Y15: =Translation!C355 -> (based on individual vaccine shipments)
B16: =Translation!C332 -> Choose from dropdown list | C16: =B16 -> Choose from dropdown list | D16: =Translation!C336 -> Vaccine volume (cm³/dose) | E16: =Translation!C337 -> Diluent volume (cm³/dose) | F16: =D16 -> Vaccine volume (cm³/dose) | G16: =E16 -> Diluent volume (cm³/dose) | H16: =Translation!C339 -> (US$/ dose) | I16: =Translation!C341 -> National wastage rates (%) | J16: =Translation!C342 -> WHO/GAVI indicative rates (%) | K16: =Translation!C343 -> Wastage factor | L16: =Translation!C345 -> Enter as % of total population | M16: =Translation!C348 -> Current schedule | N16: Current schedule with penta 1d | O16: Current schedule with penta CAD | S16: H1N1 campaign | V16: =Translation!C353 -> Maxi supply interval | W16: =Translation!C354 -> Safety stock | Y16: =M16 -> Current schedule | Z16: =IF(N16="","",N16) -> Current schedule with penta 1d | AA16: =IF(O16="","",O16) -> Current schedule with penta CAD | AB16: =IF(P16="","",P16) | AC16: =IF(Q16="","",Q16)
B17: BCG | C17: 20 | F17: {=IF(B17="",0,IF($D$5=min,MIN(IF(Vaccines=$B17,IF(Formulation=Volume_Inject!$C13,IF(Vaccine_database!$E$10:$E$278=Volume_Inject!$D13,IF(Vaccine_database!$J$10:$J$278=$C17,Vaccine_database!K$10:K$278))))),IF($D$5=max,MAX(IF(Vaccines=$B17,IF(Formulation=Volume_Inject!$C13,IF(Vaccine_database!$E$10:$E$278=Volume_Inject!$D13,IF(Vaccine_database!$J$10:$J$278=$C17,Vaccine_database!K$10:K$278))))),AVERAGE(IF(Vaccines=$B17,IF(Formulation=Volume_Inject!$C13,IF(Vaccine_database!$E$10:$E$278=Volume_Inject!$D13,IF(Vaccine_database!$J$10:$J$278=$C17,Vaccine_database!K$10:K$278))))))))} -> 1.2102 | G17: {=IF(C17="",0,IF($D$5=min,MIN(IF(Vaccines=$B17,IF(Formulation=Volume_Inject!$C13,IF(Vaccine_database!$E$10:$E$278=Volume_Inject!$D13,IF(Vaccine_database!$J$10:$J$278=$C17,Vaccine_database!L$10:L$278))))),IF($D$5=max,MAX(IF(Vaccines=$B17,IF(Formulation=Volume_Inject!$C13,IF(Vaccine_database!$E$10:$E$278=Volume_Inject!$D13,IF(Vaccine_database!$J$10:$J$278=$C17,Vaccine_database!L$10:L$278))))),AVERAGE(IF(Vaccines=$B17,IF(Formulation=Volume_Inject!$C13,IF(Vaccine_database!$E$10:$E$278=Volume_Inject!$D13,IF(Vaccine_database!$J$10:$J$278=$C17,Vaccine_database!L$10:L$278))))))))} -> 1.1256667 | J17: =IF(B17="","",IF(OR(ISTEXT(C17),C17=1),5,IF(Volume_Inject!$C13<>"liquid",IF(C17>=20,50,IF(C17=10,40,10)),IF(C17>=10,25,10)))) -> 50 | K17: =IF(I17="",IF($J17="",0,100/(100-$J17)),100/(100-$I17)) -> 2 | L17: 0.019 | M17: 1 | N17: 1 | O17: 1 | V17: 4 | W17: 1 | Y17: =IF($V17="",0,Volume_Inject!$F13*$K17*M17*($V17+$W17)/12) -> 1.0085 | Z17: =IF($V17="",0,Volume_Inject!$F13*$K17*N17*($V17+$W17)/12) -> 1.0085 | AA17: =IF($V17="",0,Volume_Inject!$F13*$K17*O17*($V17+$W17)/12) -> 1.0085 | AB17: =IF($V17="",0,Volume_Inject!$F13*$K17*P17*($V17+$W17)/12) -> 0 | AC17: =IF($V17="",0,Volume_Inject!$F13*$K17*Q17*($V17+$W17)/12) -> 0
B18: OPV | C18: 10 | F18: {=IF(B18="",0,IF($D$5=min,MIN(IF(Vaccines=$B18,IF(Formulation=Volume_Inject!$C14,IF(Vaccine_database!$E$10:$E$278=Volume_Inject!$D14,IF(Vaccine_database!$J$10:$J$278=$C18,Vaccine_database!K$10:K$278))))),IF($D$5=max,MAX(IF(Vaccines=$B18,IF(Formulation=Volume_Inject!$C14,IF(Vaccine_database!$E$10:$E$278=Volume_Inject!$D14,IF(Vaccine_database!$J$10:$J$278=$C18,Vaccine_database!K$10:K$278))))),AVERAGE(IF(Vaccines=$B18,IF(Formulation=Volume_Inject!$C14,IF(Vaccine_database!$E$10:$E$278=Volume_Inject!$D14,IF(Vaccine_database!$J$10:$J$278=$C18,Vaccine_database!K$10:K$278))))))))} -> 2 | G18: {=IF(C18="",0,IF($D$5=min,MIN(IF(Vaccines=$B18,IF(Formulation=Volume_Inject!$C14,IF(Vaccine_database!$E$10:$E$278=Volume_Inject!$D14,IF(Vaccine_database!$J$10:$J$278=$C18,Vaccine_database!L$10:L$278))))),IF($D$5=max,MAX(IF(Vaccines=$B18,IF(Formulation=Volume_Inject!$C14,IF(Vaccine_database!$E$10:$E$278=Volume_Inject!$D14,IF(Vaccine_database!$J$10:$J$278=$C18,Vaccine_database!L$10:L$278))))),AVERAGE(IF(Vaccines=$B18,IF(Formulation=Volume_Inject!$C14,IF(Vaccine_database!$E$10:$E$278=Volume_Inject!$D14,IF(Vaccine_database!$J$10:$J$278=$C18,Vaccine_database!L$10:L$278))))))))} -> 0 | J18: =IF(B18="","",IF(OR(ISTEXT(C18),C18=1),5,IF(Volume_Inject!$C14<>"liquid",IF(C18>=20,50,IF(C18=10,40,10)),IF(C18>=10,25,10)))) -> 25 | K18: =IF(I18="",IF($J18="",0,100/(100-$J18)),100/(100-$I18)) -> 1.3333333 | L18: 0.019 | M18: 4 | N18: 4 | O18: 4 | V18: 4 | W18: 1 | Y18: =IF($V18="",0,Volume_Inject!$F14*$K18*M18*($V18+$W18)/12) -> 4.4444444 | Z18: =IF($V18="",0,Volume_Inject!$F14*$K18*N18*($V18+$W18)/12) -> 4.4444444 | AA18: =IF($V18="",0,Volume_Inject!$F14*$K18*O18*($V18+$W18)/12) -> 4.4444444 | AB18: =IF($V18="",0,Volume_Inject!$F14*$K18*P18*($V18+$W18)/12) -> 0 | AC18: =IF($V18="",0,Volume_Inject!$F14*$K18*Q18*($V18+$W18)/12) -> 0
B19: DTP-HepB-Hib | C19: 10 | F19: {=IF(B19="",0,IF($D$5=min,MIN(IF(Vaccines=$B19,IF(Formulation=Volume_Inject!$C15,IF(Vaccine_database!$E$10:$E$278=Volume_Inject!$D15,IF(Vaccine_database!$J$10:$J$278=$C19,Vaccine_database!K$10:K$278))))),IF($D$5=max,MAX(IF(Vaccines=$B19,IF(Formulation=Volume_Inject!$C15,IF(Vaccine_database!$E$10:$E$278=Volume_Inject!$D15,IF(Vaccine_database!$J$10:$J$278=$C19,Vaccine_database!K$10:K$278))))),AVERAGE(IF(Vaccines=$B19,IF(Formulation=Volume_Inject!$C15,IF(Vaccine_database!$E$10:$E$278=Volume_Inject!$D15,IF(Vaccine_database!$J$10:$J$278=$C19,Vaccine_database!K$10:K$278))))))))} -> 2.75 | G19: {=IF(C19="",0,IF($D$5=min,MIN(IF(Vaccines=$B19,IF(Formulation=Volume_Inject!$C15,IF(Vaccine_database!$E$10:$E$278=Volume_Inject!$D15,IF(Vaccine_database!$J$10:$J$278=$C19,Vaccine_database!L$10:L$278))))),IF($D$5=max,MAX(IF(Vaccines=$B19,IF(Formulation=Volume_Inject!$C15,IF(Vaccine_database!$E$10:$E$278=Volume_Inject!$D15,IF(Vaccine_database!$J$10:$J$278=$C19,Vaccine_database!L$10:L$278))))),AVERAGE(IF(Vaccines=$B19,IF(Formulation=Volume_Inject!$C15,IF(Vaccine_database!$E$10:$E$278=Volume_Inject!$D15,IF(Vaccine_database!$J$10:$J$278=$C19,Vaccine_database!L$10:L$278))))))))} -> 0 | J19: =IF(B19="","",IF(OR(ISTEXT(C19),C19=1),5,IF(Volume_Inject!$C15<>"liquid",IF(C19>=20,50,IF(C19=10,40,10)),IF(C19>=10,25,10)))) -> 25 | K19: =IF(I19="",IF($J19="",0,100/(100-$J19)),100/(100-$I19)) -> 1.3333333 | L19: 0.019 | M19: 3 | V19: 4 | W19: 1 | Y19: =IF($V19="",0,Volume_Inject!$F15*$K19*M19*($V19+$W19)/12) -> 4.5833333 | Z19: =IF($V19="",0,Volume_Inject!$F15*$K19*N19*($V19+$W19)/12) -> 0 | AA19: =IF($V19="",0,Volume_Inject!$F15*$K19*O19*($V19+$W19)/12) -> 0 | AB19: =IF($V19="",0,Volume_Inject!$F15*$K19*P19*($V19+$W19)/12) -> 0 | AC19: =IF($V19="",0,Volume_Inject!$F15*$K19*Q19*($V19+$W19)/12) -> 0
B20: DTP-HepB-Hib | C20: 1 | F20: {=IF(B20="",0,IF($D$5=min,MIN(IF(Vaccines=$B20,IF(Formulation=Volume_Inject!$C16,IF(Vaccine_database!$E$10:$E$278=Volume_Inject!$D16,IF(Vaccine_database!$J$10:$J$278=$C20,Vaccine_database!K$10:K$278))))),IF($D$5=max,MAX(IF(Vaccines=$B20,IF(Formulation=Volume_Inject!$C16,IF(Vaccine_database!$E$10:$E$278=Volume_Inject!$D16,IF(Vaccine_database!$J$10:$J$278=$C20,Vaccine_database!K$10:K$278))))),AVERAGE(IF(Vaccines=$B20,IF(Formulation=Volume_Inject!$C16,IF(Vaccine_database!$E$10:$E$278=Volume_Inject!$D16,IF(Vaccine_database!$J$10:$J$278=$C20,Vaccine_database!K$10:K$278))))))))} -> 16.66384 | G20: {=IF(C20="",0,IF($D$5=min,MIN(IF(Vaccines=$B20,IF(Formulation=Volume_Inject!$C16,IF(Vaccine_database!$E$10:$E$278=Volume_Inject!$D16,IF(Vaccine_database!$J$10:$J$278=$C20,Vaccine_database!L$10:L$278))))),IF($D$5=max,MAX(IF(Vaccines=$B20,IF(Formulation=Volume_Inject!$C16,IF(Vaccine_database!$E$10:$E$278=Volume_Inject!$D16,IF(Vaccine_database!$J$10:$J$278=$C20,Vaccine_database!L$10:L$278))))),AVERAGE(IF(Vaccines=$B20,IF(Formulation=Volume_Inject!$C16,IF(Vaccine_database!$E$10:$E$278=Volume_Inject!$D16,IF(Vaccine_database!$J$10:$J$278=$C20,Vaccine_database!L$10:L$278))))))))} -> 0 | J20: =IF(B20="","",IF(OR(ISTEXT(C20),C20=1),5,IF(Volume_Inject!$C16<>"liquid",IF(C20>=20,50,IF(C20=10,40,10)),IF(C20>=10,25,10)))) -> 5 | K20: =IF(I20="",IF($J20="",0,100/(100-$J20)),100/(100-$I20)) -> 1.0526316 | L20: 0.019 | N20: 3 | V20: 3 | W20: 1 | Y20: =IF($V20="",0,Volume_Inject!$F16*$K20*M20*($V20+$W20)/12) -> 0 | Z20: =IF($V20="",0,Volume_Inject!$F16*$K20*N20*($V20+$W20)/12) -> 17.540884 | AA20: =IF($V20="",0,Volume_Inject!$F16*$K20*O20*($V20+$W20)/12) -> 0 | AB20: =IF($V20="",0,Volume_Inject!$F16*$K20*P20*($V20+$W20)/12) -> 0 | AC20: =IF($V20="",0,Volume_Inject!$F16*$K20*Q20*($V20+$W20)/12) -> 0
B21: DTP-HepB-Hib | C21: Uniject | D21: 12 | F21: {=IF(B21="",0,IF($D$5=min,MIN(IF(Vaccines=$B21,IF(Formulation=Volume_Inject!$C17,IF(Vaccine_database!$E$10:$E$278=Volume_Inject!$D17,IF(Vaccine_database!$J$10:$J$278=$C21,Vaccine_database!K$10:K$278))))),IF($D$5=max,MAX(IF(Vaccines=$B21,IF(Formulation=Volume_Inject!$C17,IF(Vaccine_database!$E$10:$E$278=Volume_Inject!$D17,IF(Vaccine_database!$J$10:$J$278=$C21,Vaccine_database!K$10:K$278))))),AVERAGE(IF(Vaccines=$B21,IF(Formulation=Volume_Inject!$C17,IF(Vaccine_database!$E$10:$E$278=Volume_Inject!$D17,IF(Vaccine_database!$J$10:$J$278=$C21,Vaccine_database!K$10:K$278))))))))} -> #DIV/0! | G21: {=IF(C21="",0,IF($D$5=min,MIN(IF(Vaccines=$B21,IF(Formulation=Volume_Inject!$C17,IF(Vaccine_database!$E$10:$E$278=Volume_Inject!$D17,IF(Vaccine_database!$J$10:$J$278=$C21,Vaccine_database!L$10:L$278))))),IF($D$5=max,MAX(IF(Vaccines=$B21,IF(Formulation=Volume_Inject!$C17,IF(Vaccine_database!$E$10:$E$278=Volume_Inject!$D17,IF(Vaccine_database!$J$10:$J$278=$C21,Vaccine_database!L$10:L$278))))),AVERAGE(IF(Vaccines=$B21,IF(Formulation=Volume_Inject!$C17,IF(Vaccine_database!$E$10:$E$278=Volume_Inject!$D17,IF(Vaccine_database!$J$10:$J$278=$C21,Vaccine_database!L$10:L$278))))))))} -> #DIV/0! | J21: =IF(B21="","",IF(OR(ISTEXT(C21),C21=1),5,IF(Volume_Inject!$C17<>"liquid",IF(C21>=20,50,IF(C21=10,40,10)),IF(C21>=10,25,10)))) -> 5 | K21: =IF(I21="",IF($J21="",0,100/(100-$J21)),100/(100-$I21)) -> 1.0526316 | L21: 0.019 | O21: 3 | V21: 4 | W21: 1 | Y21: =IF($V21="",0,Volume_Inject!$F17*$K21*M21*($V21+$W21)/12) -> 0 | Z21: =IF($V21="",0,Volume_Inject!$F17*$K21*N21*($V21+$W21)/12) -> 0 | AA21: =IF($V21="",0,Volume_Inject!$F17*$K21*O21*($V21+$W21)/12) -> 15.789474 | AB21: =IF($V21="",0,Volume_Inject!$F17*$K21*P21*($V21+$W21)/12) -> 0 | AC21: =IF($V21="",0,Volume_Inject!$F17*$K21*Q21*($V21+$W21)/12) -> 0
B22: Measles | C22: 10 | F22: {=IF(B22="",0,IF($D$5=min,MIN(IF(Vaccines=$B22,IF(Formulation=Volume_Inject!$C18,IF(Vaccine_database!$E$10:$E$278=Volume_Inject!$D18,IF(Vaccine_database!$J$10:$J$278=$C22,Vaccine_database!K$10:K$278))))),IF($D$5=max,MAX(IF(Vaccines=$B22,IF(Formulation=Volume_Inject!$C18,IF(Vaccine_database!$E$10:$E$278=Volume_Inject!$D18,IF(Vaccine_database!$J$10:$J$278=$C22,Vaccine_database!K$10:K$278))))),AVERAGE(IF(Vaccines=$B22,IF(Formulation=Volume_Inject!$C18,IF(Vaccine_database!$E$10:$E$278=Volume_Inject!$D18,IF(Vaccine_database!$J$10:$J$278=$C22,Vaccine_database!K$10:K$278))))))))} -> 2.4002 | G22: {=IF(C22="",0,IF($D$5=min,MIN(IF(Vaccines=$B22,IF(Formulation=Volume_Inject!$C18,IF(Vaccine_database!$E$10:$E$278=Volume_Inject!$D18,IF(Vaccine_database!$J$10:$J$278=$C22,Vaccine_database!L$10:L$278))))),IF($D$5=max,MAX(IF(Vaccines=$B22,IF(Formulation=Volume_Inject!$C18,IF(Vaccine_database!$E$10:$E$278=Volume_Inject!$D18,IF(Vaccine_database!$J$10:$J$278=$C22,Vaccine_database!L$10:L$278))))),AVERAGE(IF(Vaccines=$B22,IF(Formulation=Volume_Inject!$C18,IF(Vaccine_database!$E$10:$E$278=Volume_Inject!$D18,IF(Vaccine_database!$J$10:$J$278=$C22,Vaccine_database!L$10:L$278))))))))} -> 3.2 | J22: =IF(B22="","",IF(OR(ISTEXT(C22),C22=1),5,IF(Volume_Inject!$C18<>"liquid",IF(C22>=20,50,IF(C22=10,40,10)),IF(C22>=10,25,10)))) -> 40 | K22: =IF(I22="",IF($J22="",0,100/(100-$J22)),100/(100-$I22)) -> 1.6666667 | L22: 0.018 | M22: 1 | N22: 1 | O22: 1 | V22: 4 | W22: 1 | Y22: =IF($V22="",0,Volume_Inject!$F18*$K22*M22*($V22+$W22)/12) -> 1.6668056 | Z22: =IF($V22="",0,Volume_Inject!$F18*$K22*N22*($V22+$W22)/12) -> 1.6668056 | AA22: =IF($V22="",0,Volume_Inject!$F18*$K22*O22*($V22+$W22)/12) -> 1.6668056 | AB22: =IF($V22="",0,Volume_Inject!$F18*$K22*P22*($V22+$W22)/12) -> 0 | AC22: =IF($V22="",0,Volume_Inject!$F18*$K22*Q22*($V22+$W22)/12) -> 0
B23: YF | C23: 5 | F23: {=IF(B23="",0,IF($D$5=min,MIN(IF(Vaccines=$B23,IF(Formulation=Volume_Inject!$C19,IF(Vaccine_database!$E$10:$E$278=Volume_Inject!$D19,IF(Vaccine_database!$J$10:$J$278=$C23,Vaccine_database!K$10:K$278))))),IF($D$5=max,MAX(IF(Vaccines=$B23,IF(Formulation=Volume_Inject!$C19,IF(Vaccine_database!$E$10:$E$278=Volume_Inject!$D19,IF(Vaccine_database!$J$10:$J$278=$C23,Vaccine_database!K$10:K$278))))),AVERAGE(IF(Vaccines=$B23,IF(Formulation=Volume_Inject!$C19,IF(Vaccine_database!$E$10:$E$278=Volume_Inject!$D19,IF(Vaccine_database!$J$10:$J$278=$C23,Vaccine_database!K$10:K$278))))))))} -> 5.4025 | G23: {=IF(C23="",0,IF($D$5=min,MIN(IF(Vaccines=$B23,IF(Formulation=Volume_Inject!$C19,IF(Vaccine_database!$E$10:$E$278=Volume_Inject!$D19,IF(Vaccine_database!$J$10:$J$278=$C23,Vaccine_database!L$10:L$278))))),IF($D$5=max,MAX(IF(Vaccines=$B23,IF(Formulation=Volume_Inject!$C19,IF(Vaccine_database!$E$10:$E$278=Volume_Inject!$D19,IF(Vaccine_database!$J$10:$J$278=$C23,Vaccine_database!L$10:L$278))))),AVERAGE(IF(Vaccines=$B23,IF(Formulation=Volume_Inject!$C19,IF(Vaccine_database!$E$10:$E$278=Volume_Inject!$D19,IF(Vaccine_database!$J$10:$J$278=$C23,Vaccine_database!L$10:L$278))))))))} -> 6.75 | J23: =IF(B23="","",IF(OR(ISTEXT(C23),C23=1),5,IF(Volume_Inject!$C19<>"liquid",IF(C23>=20,50,IF(C23=10,40,10)),IF(C23>=10,25,10)))) -> 10 | K23: =IF(I23="",IF($J23="",0,100/(100-$J23)),100/(100-$I23)) -> 1.1111111 | L23: 0.018 | M23: 1 | N23: 1 | O23: 1 | V23: 4 | W23: 1 | Y23: =IF($V23="",0,Volume_Inject!$F19*$K23*M23*($V23+$W23)/12) -> 2.5011574 | Z23: =IF($V23="",0,Volume_Inject!$F19*$K23*N23*($V23+$W23)/12) -> 2.5011574 | AA23: =IF($V23="",0,Volume_Inject!$F19*$K23*O23*($V23+$W23)/12) -> 2.5011574 | AB23: =IF($V23="",0,Volume_Inject!$F19*$K23*P23*($V23+$W23)/12) -> 0 | AC23: =IF($V23="",0,Volume_Inject!$F19*$K23*Q23*($V23+$W23)/12) -> 0
B24: TT | C24: 10 | F24: {=IF(B24="",0,IF($D$5=min,MIN(IF(Vaccines=$B24,IF(Formulation=Volume_Inject!$C20,IF(Vaccine_database!$E$10:$E$278=Volume_Inject!$D20,IF(Vaccine_database!$J$10:$J$278=$C24,Vaccine_database!K$10:K$278))))),IF($D$5=max,MAX(IF(Vaccines=$B24,IF(Formulation=Volume_Inject!$C20,IF(Vaccine_database!$E$10:$E$278=Volume_Inject!$D20,IF(Vaccine_database!$J$10:$J$278=$C24,Vaccine_database!K$10:K$278))))),AVERAGE(IF(Vaccines=$B24,IF(Formulation=Volume_Inject!$C20,IF(Vaccine_database!$E$10:$E$278=Volume_Inject!$D20,IF(Vaccine_database!$J$10:$J$278=$C24,Vaccine_database!K$10:K$278))))))))} -> 3.1093333 | G24: {=IF(C24="",0,IF($D$5=min,MIN(IF(Vaccines=$B24,IF(Formulation=Volume_Inject!$C20,IF(Vaccine_database!$E$10:$E$278=Volume_Inject!$D20,IF(Vaccine_database!$J$10:$J$278=$C24,Vaccine_database!L$10:L$278))))),IF($D$5=max,MAX(IF(Vaccines=$B24,IF(Formulation=Volume_Inject!$C20,IF(Vaccine_database!$E$10:$E$278=Volume_Inject!$D20,IF(Vaccine_database!$J$10:$J$278=$C24,Vaccine_database!L$10:L$278))))),AVERAGE(IF(Vaccines=$B24,IF(Formulation=Volume_Inject!$C20,IF(Vaccine_database!$E$10:$E$278=Volume_Inject!$D20,IF(Vaccine_database!$J$10:$J$278=$C24,Vaccine_database!L$10:L$278))))))))} -> 0 | J24: =IF(B24="","",IF(OR(ISTEXT(C24),C24=1),5,IF(Volume_Inject!$C20<>"liquid",IF(C24>=20,50,IF(C24=10,40,10)),IF(C24>=10,25,10)))) -> 25 | K24: =IF(I24="",IF($J24="",0,100/(100-$J24)),100/(100-$I24)) -> 1.3333333 | L24: 0.02 | M24: 2 | N24: 2 | O24: 2 | V24: 3 | W24: 1 | Y24: =IF($V24="",0,Volume_Inject!$F20*$K24*M24*($V24+$W24)/12) -> 2.7638519 | Z24: =IF($V24="",0,Volume_Inject!$F20*$K24*N24*($V24+$W24)/12) -> 2.7638519 | AA24: =IF($V24="",0,Volume_Inject!$F20*$K24*O24*($V24+$W24)/12) -> 2.7638519 | AB24: =IF($V24="",0,Volume_Inject!$F20*$K24*P24*($V24+$W24)/12) -> 0 | AC24: =IF($V24="",0,Volume_Inject!$F20*$K24*Q24*($V24+$W24)/12) -> 0
B25: PCV-13 | C25: 1 | F25: {=IF(B25="",0,IF($D$5=min,MIN(IF(Vaccines=$B25,IF(Formulation=Volume_Inject!$C21,IF(Vaccine_database!$E$10:$E$278=Volume_Inject!$D21,IF(Vaccine_database!$J$10:$J$278=$C25,Vaccine_database!K$10:K$278))))),IF($D$5=max,MAX(IF(Vaccines=$B25,IF(Formulation=Volume_Inject!$C21,IF(Vaccine_database!$E$10:$E$278=Volume_Inject!$D21,IF(Vaccine_database!$J$10:$J$278=$C25,Vaccine_database!K$10:K$278))))),AVERAGE(IF(Vaccines=$B25,IF(Formulation=Volume_Inject!$C21,IF(Vaccine_database!$E$10:$E$278=Volume_Inject!$D21,IF(Vaccine_database!$J$10:$J$278=$C25,Vaccine_database!K$10:K$278))))))))} -> 13.825247 | G25: {=IF(C25="",0,IF($D$5=min,MIN(IF(Vaccines=$B25,IF(Formulation=Volume_Inject!$C21,IF(Vaccine_database!$E$10:$E$278=Volume_Inject!$D21,IF(Vaccine_database!$J$10:$J$278=$C25,Vaccine_database!L$10:L$278))))),IF($D$5=max,MAX(IF(Vaccines=$B25,IF(Formulation=Volume_Inject!$C21,IF(Vaccine_database!$E$10:$E$278=Volume_Inject!$D21,IF(Vaccine_database!$J$10:$J$278=$C25,Vaccine_database!L$10:L$278))))),AVERAGE(IF(Vaccines=$B25,IF(Formulation=Volume_Inject!$C21,IF(Vaccine_database!$E$10:$E$278=Volume_Inject!$D21,IF(Vaccine_database!$J$10:$J$278=$C25,Vaccine_database!L$10:L$278))))))))} -> 0 | J25: =IF(B25="","",IF(OR(ISTEXT(C25),C25=1),5,IF(Volume_Inject!$C21<>"liquid",IF(C25>=20,50,IF(C25=10,40,10)),IF(C25>=10,25,10)))) -> 5 | K25: =IF(I25="",IF($J25="",0,100/(100-$J25)),100/(100-$I25)) -> 1.0526316 | L25: 0.01 | V25: 12 | W25: 0 | Y25: =IF($V25="",0,Volume_Inject!$F21*$K25*M25*($V25+$W25)/12) -> 0 | Z25: =IF($V25="",0,Volume_Inject!$F21*$K25*N25*($V25+$W25)/12) -> 0 | AA25: =IF($V25="",0,Volume_Inject!$F21*$K25*O25*($V25+$W25)/12) -> 0 | AB25: =IF($V25="",0,Volume_Inject!$F21*$K25*P25*($V25+$W25)/12) -> 0 | AC25: =IF($V25="",0,Volume_Inject!$F21*$K25*Q25*($V25+$W25)/12) -> 0
B26: Rota_liq | C26: 1 | D26: 17.1 | F26: {=IF(B26="",0,IF($D$5=min,MIN(IF(Vaccines=$B26,IF(Formulation=Volume_Inject!$C22,IF(Vaccine_database!$E$10:$E$278=Volume_Inject!$D22,IF(Vaccine_database!$J$10:$J$278=$C26,Vaccine_database!K$10:K$278))))),IF($D$5=max,MAX(IF(Vaccines=$B26,IF(Formulation=Volume_Inject!$C22,IF(Vaccine_database!$E$10:$E$278=Volume_Inject!$D22,IF(Vaccine_database!$J$10:$J$278=$C26,Vaccine_database!K$10:K$278))))),AVERAGE(IF(Vaccines=$B26,IF(Formulation=Volume_Inject!$C22,IF(Vaccine_database!$E$10:$E$278=Volume_Inject!$D22,IF(Vaccine_database!$J$10:$J$278=$C26,Vaccine_database!K$10:K$278))))))))} -> 17.1258 | G26: {=IF(C26="",0,IF($D$5=min,MIN(IF(Vaccines=$B26,IF(Formulation=Volume_Inject!$C22,IF(Vaccine_database!$E$10:$E$278=Volume_Inject!$D22,IF(Vaccine_database!$J$10:$J$278=$C26,Vaccine_database!L$10:L$278))))),IF($D$5=max,MAX(IF(Vaccines=$B26,IF(Formulation=Volume_Inject!$C22,IF(Vaccine_database!$E$10:$E$278=Volume_Inject!$D22,IF(Vaccine_database!$J$10:$J$278=$C26,Vaccine_database!L$10:L$278))))),AVERAGE(IF(Vaccines=$B26,IF(Formulation=Volume_Inject!$C22,IF(Vaccine_database!$E$10:$E$278=Volume_Inject!$D22,IF(Vaccine_database!$J$10:$J$278=$C26,Vaccine_database!L$10:L$278))))))))} -> 0 | J26: =IF(B26="","",IF(OR(ISTEXT(C26),C26=1),5,IF(Volume_Inject!$C22<>"liquid",IF(C26>=20,50,IF(C26=10,40,10)),IF(C26>=10,25,10)))) -> 5 | K26: =IF(I26="",IF($J26="",0,100/(100-$J26)),100/(100-$I26)) -> 1.0526316 | L26: 0.035 | S26: 1 | Y26: =IF($V26="",0,Volume_Inject!$F22*$K26*M26*($V26+$W26)/12) -> 0 | Z26: =IF($V26="",0,Volume_Inject!$F22*$K26*N26*($V26+$W26)/12) -> 0 | AA26: =IF($V26="",0,Volume_Inject!$F22*$K26*O26*($V26+$W26)/12) -> 0 | AB26: =IF($V26="",0,Volume_Inject!$F22*$K26*P26*($V26+$W26)/12) -> 0 | AC26: =IF($V26="",0,Volume_Inject!$F22*$K26*Q26*($V26+$W26)/12) -> 0
F27: {=IF(B27="",0,IF($D$5=min,MIN(IF(Vaccines=$B27,IF(Formulation=Volume_Inject!$C23,IF(Vaccine_database!$E$10:$E$278=Volume_Inject!$D23,IF(Vaccine_database!$J$10:$J$278=$C27,Vaccine_database!K$10:K$278))))),IF($D$5=max,MAX(IF(Vaccines=$B27,IF(Formulation=Volume_Inject!$C23,IF(Vaccine_database!$E$10:$E$278=Volume_Inject!$D23,IF(Vaccine_database!$J$10:$J$278=$C27,Vaccine_database!K$10:K$278))))),AVERAGE(IF(Vaccines=$B27,IF(Formulation=Volume_Inject!$C23,IF(Vaccine_database!$E$10:$E$278=Volume_Inject!$D23,IF(Vaccine_database!$J$10:$J$278=$C27,Vaccine_database!K$10:K$278))))))))} -> 0 | G27: {=IF(C27="",0,IF($D$5=min,MIN(IF(Vaccines=$B27,IF(Formulation=Volume_Inject!$C23,IF(Vaccine_database!$E$10:$E$278=Volume_Inject!$D23,IF(Vaccine_database!$J$10:$J$278=$C27,Vaccine_database!L$10:L$278))))),IF($D$5=max,MAX(IF(Vaccines=$B27,IF(Formulation=Volume_Inject!$C23,IF(Vaccine_database!$E$10:$E$278=Volume_Inject!$D23,IF(Vaccine_database!$J$10:$J$278=$C27,Vaccine_database!L$10:L$278))))),AVERAGE(IF(Vaccines=$B27,IF(Formulation=Volume_Inject!$C23,IF(Vaccine_database!$E$10:$E$278=Volume_Inject!$D23,IF(Vaccine_database!$J$10:$J$278=$C27,Vaccine_database!L$10:L$278))))))))} -> 0 | J27: =IF(B27="","",IF(OR(ISTEXT(C27),C27=1),5,IF(Volume_Inject!$C23<>"liquid",IF(C27>=20,50,IF(C27=10,40,10)),IF(C27>=10,25,10)))) | K27: =IF(I27="",IF($J27="",0,100/(100-$J27)),100/(100-$I27)) -> 0 | Y27: =IF($V27="",0,Volume_Inject!$F23*$K27*M27*($V27+$W27)/12) -> 0 | Z27: =IF($V27="",0,Volume_Inject!$F23*$K27*N27*($V27+$W27)/12) -> 0 | AA27: =IF($V27="",0,Volume_Inject!$F23*$K27*O27*($V27+$W27)/12) -> 0 | AB27: =IF($V27="",0,Volume_Inject!$F23*$K27*P27*($V27+$W27)/12) -> 0 | AC27: =IF($V27="",0,Volume_Inject!$F23*$K27*Q27*($V27+$W27)/12) -> 0
F28: {=IF(B28="",0,IF($D$5=min,MIN(IF(Vaccines=$B28,IF(Formulation=Volume_Inject!$C24,IF(Vaccine_database!$E$10:$E$278=Volume_Inject!$D24,IF(Vaccine_database!$J$10:$J$278=$C28,Vaccine_database!K$10:K$278))))),IF($D$5=max,MAX(IF(Vaccines=$B28,IF(Formulation=Volume_Inject!$C24,IF(Vaccine_database!$E$10:$E$278=Volume_Inject!$D24,IF(Vaccine_database!$J$10:$J$278=$C28,Vaccine_database!K$10:K$278))))),AVERAGE(IF(Vaccines=$B28,IF(Formulation=Volume_Inject!$C24,IF(Vaccine_database!$E$10:$E$278=Volume_Inject!$D24,IF(Vaccine_database!$J$10:$J$278=$C28,Vaccine_database!K$10:K$278))))))))} -> 0 | G28: {=IF(C28="",0,IF($D$5=min,MIN(IF(Vaccines=$B28,IF(Formulation=Volume_Inject!$C24,IF(Vaccine_database!$E$10:$E$278=Volume_Inject!$D24,IF(Vaccine_database!$J$10:$J$278=$C28,Vaccine_database!L$10:L$278))))),IF($D$5=max,MAX(IF(Vaccines=$B28,IF(Formulation=Volume_Inject!$C24,IF(Vaccine_database!$E$10:$E$278=Volume_Inject!$D24,IF(Vaccine_database!$J$10:$J$278=$C28,Vaccine_database!L$10:L$278))))),AVERAGE(IF(Vaccines=$B28,IF(Formulation=Volume_Inject!$C24,IF(Vaccine_database!$E$10:$E$278=Volume_Inject!$D24,IF(Vaccine_database!$J$10:$J$278=$C28,Vaccine_database!L$10:L$278))))))))} -> 0 | J28: =IF(B28="","",IF(OR(ISTEXT(C28),C28=1),5,IF(Volume_Inject!$C24<>"liquid",IF(C28>=20,50,IF(C28=10,40,10)),IF(C28>=10,25,10)))) | K28: =IF(I28="",IF($J28="",0,100/(100-$J28)),100/(100-$I28)) -> 0 | Y28: =IF($V28="",0,Volume_Inject!$F24*$K28*M28*($V28+$W28)/12) -> 0 | Z28: =IF($V28="",0,Volume_Inject!$F24*$K28*N28*($V28+$W28)/12) -> 0 | AA28: =IF($V28="",0,Volume_Inject!$F24*$K28*O28*($V28+$W28)/12) -> 0 | AB28: =IF($V28="",0,Volume_Inject!$F24*$K28*P28*($V28+$W28)/12) -> 0 | AC28: =IF($V28="",0,Volume_Inject!$F24*$K28*Q28*($V28+$W28)/12) -> 0
F29: {=IF(B29="",0,IF($D$5=min,MIN(IF(Vaccines=$B29,IF(Formulation=Volume_Inject!$C25,IF(Vaccine_database!$E$10:$E$278=Volume_Inject!$D25,IF(Vaccine_database!$J$10:$J$278=$C29,Vaccine_database!K$10:K$278))))),IF($D$5=max,MAX(IF(Vaccines=$B29,IF(Formulation=Volume_Inject!$C25,IF(Vaccine_database!$E$10:$E$278=Volume_Inject!$D25,IF(Vaccine_database!$J$10:$J$278=$C29,Vaccine_database!K$10:K$278))))),AVERAGE(IF(Vaccines=$B29,IF(Formulation=Volume_Inject!$C25,IF(Vaccine_database!$E$10:$E$278=Volume_Inject!$D25,IF(Vaccine_database!$J$10:$J$278=$C29,Vaccine_database!K$10:K$278))))))))} -> 0 | G29: {=IF(C29="",0,IF($D$5=min,MIN(IF(Vaccines=$B29,IF(Formulation=Volume_Inject!$C25,IF(Vaccine_database!$E$10:$E$278=Volume_Inject!$D25,IF(Vaccine_database!$J$10:$J$278=$C29,Vaccine_database!L$10:L$278))))),IF($D$5=max,MAX(IF(Vaccines=$B29,IF(Formulation=Volume_Inject!$C25,IF(Vaccine_database!$E$10:$E$278=Volume_Inject!$D25,IF(Vaccine_database!$J$10:$J$278=$C29,Vaccine_database!L$10:L$278))))),AVERAGE(IF(Vaccines=$B29,IF(Formulation=Volume_Inject!$C25,IF(Vaccine_database!$E$10:$E$278=Volume_Inject!$D25,IF(Vaccine_database!$J$10:$J$278=$C29,Vaccine_database!L$10:L$278))))))))} -> 0 | J29: =IF(B29="","",IF(OR(ISTEXT(C29),C29=1),5,IF(Volume_Inject!$C25<>"liquid",IF(C29>=20,50,IF(C29=10,40,10)),IF(C29>=10,25,10)))) | K29: =IF(I29="",IF($J29="",0,100/(100-$J29)),100/(100-$I29)) -> 0 | Y29: =IF($V29="",0,Volume_Inject!$F25*$K29*M29*($V29+$W29)/12) -> 0 | Z29: =IF($V29="",0,Volume_Inject!$F25*$K29*N29*($V29+$W29)/12) -> 0 | AA29: =IF($V29="",0,Volume_Inject!$F25*$K29*O29*($V29+$W29)/12) -> 0 | AB29: =IF($V29="",0,Volume_Inject!$F25*$K29*P29*($V29+$W29)/12) -> 0 | AC29: =IF($V29="",0,Volume_Inject!$F25*$K29*Q29*($V29+$W29)/12) -> 0
F30: {=IF(B30="",0,IF($D$5=min,MIN(IF(Vaccines=$B30,IF(Formulation=Volume_Inject!$C26,IF(Vaccine_database!$E$10:$E$278=Volume_Inject!$D26,IF(Vaccine_database!$J$10:$J$278=$C30,Vaccine_database!K$10:K$278))))),IF($D$5=max,MAX(IF(Vaccines=$B30,IF(Formulation=Volume_Inject!$C26,IF(Vaccine_database!$E$10:$E$278=Volume_Inject!$D26,IF(Vaccine_database!$J$10:$J$278=$C30,Vaccine_database!K$10:K$278))))),AVERAGE(IF(Vaccines=$B30,IF(Formulation=Volume_Inject!$C26,IF(Vaccine_database!$E$10:$E$278=Volume_Inject!$D26,IF(Vaccine_database!$J$10:$J$278=$C30,Vaccine_database!K$10:K$278))))))))} -> 0 | G30: {=IF(C30="",0,IF($D$5=min,MIN(IF(Vaccines=$B30,IF(Formulation=Volume_Inject!$C26,IF(Vaccine_database!$E$10:$E$278=Volume_Inject!$D26,IF(Vaccine_database!$J$10:$J$278=$C30,Vaccine_database!L$10:L$278))))),IF($D$5=max,MAX(IF(Vaccines=$B30,IF(Formulation=Volume_Inject!$C26,IF(Vaccine_database!$E$10:$E$278=Volume_Inject!$D26,IF(Vaccine_database!$J$10:$J$278=$C30,Vaccine_database!L$10:L$278))))),AVERAGE(IF(Vaccines=$B30,IF(Formulation=Volume_Inject!$C26,IF(Vaccine_database!$E$10:$E$278=Volume_Inject!$D26,IF(Vaccine_database!$J$10:$J$278=$C30,Vaccine_database!L$10:L$278))))))))} -> 0 | J30: =IF(B30="","",IF(OR(ISTEXT(C30),C30=1),5,IF(Volume_Inject!$C26<>"liquid",IF(C30>=20,50,IF(C30=10,40,10)),IF(C30>=10,25,10)))) | K30: =IF(I30="",IF($J30="",0,100/(100-$J30)),100/(100-$I30)) -> 0 | Y30: =IF($V30="",0,Volume_Inject!$F26*$K30*M30*($V30+$W30)/12) -> 0 | Z30: =IF($V30="",0,Volume_Inject!$F26*$K30*N30*($V30+$W30)/12) -> 0 | AA30: =IF($V30="",0,Volume_Inject!$F26*$K30*O30*($V30+$W30)/12) -> 0 | AB30: =IF($V30="",0,Volume_Inject!$F26*$K30*P30*($V30+$W30)/12) -> 0 | AC30: =IF($V30="",0,Volume_Inject!$F26*$K30*Q30*($V30+$W30)/12) -> 0
F31: {=IF(B31="",0,IF($D$5=min,MIN(IF(Vaccines=$B31,IF(Formulation=Volume_Inject!$C27,IF(Vaccine_database!$E$10:$E$278=Volume_Inject!$D27,IF(Vaccine_database!$J$10:$J$278=$C31,Vaccine_database!K$10:K$278))))),IF($D$5=max,MAX(IF(Vaccines=$B31,IF(Formulation=Volume_Inject!$C27,IF(Vaccine_database!$E$10:$E$278=Volume_Inject!$D27,IF(Vaccine_database!$J$10:$J$278=$C31,Vaccine_database!K$10:K$278))))),AVERAGE(IF(Vaccines=$B31,IF(Formulation=Volume_Inject!$C27,IF(Vaccine_database!$E$10:$E$278=Volume_Inject!$D27,IF(Vaccine_database!$J$10:$J$278=$C31,Vaccine_database!K$10:K$278))))))))} -> 0 | G31: {=IF(C31="",0,IF($D$5=min,MIN(IF(Vaccines=$B31,IF(Formulation=Volume_Inject!$C27,IF(Vaccine_database!$E$10:$E$278=Volume_Inject!$D27,IF(Vaccine_database!$J$10:$J$278=$C31,Vaccine_database!L$10:L$278))))),IF($D$5=max,MAX(IF(Vaccines=$B31,IF(Formulation=Volume_Inject!$C27,IF(Vaccine_database!$E$10:$E$278=Volume_Inject!$D27,IF(Vaccine_database!$J$10:$J$278=$C31,Vaccine_database!L$10:L$278))))),AVERAGE(IF(Vaccines=$B31,IF(Formulation=Volume_Inject!$C27,IF(Vaccine_database!$E$10:$E$278=Volume_Inject!$D27,IF(Vaccine_database!$J$10:$J$278=$C31,Vaccine_database!L$10:L$278))))))))} -> 0 | J31: =IF(B31="","",IF(OR(ISTEXT(C31),C31=1),5,IF(Volume_Inject!$C27<>"liquid",IF(C31>=20,50,IF(C31=10,40,10)),IF(C31>=10,25,10)))) | K31: =IF(I31="",IF($J31="",0,100/(100-$J31)),100/(100-$I31)) -> 0 | Y31: =IF($V31="",0,Volume_Inject!$F27*$K31*M31*($V31+$W31)/12) -> 0 | Z31: =IF($V31="",0,Volume_Inject!$F27*$K31*N31*($V31+$W31)/12) -> 0 | AA31: =IF($V31="",0,Volume_Inject!$F27*$K31*O31*($V31+$W31)/12) -> 0 | AB31: =IF($V31="",0,Volume_Inject!$F27*$K31*P31*($V31+$W31)/12) -> 0 | AC31: =IF($V31="",0,Volume_Inject!$F27*$K31*Q31*($V31+$W31)/12) -> 0
F32: {=IF(B32="",0,IF($D$5=min,MIN(IF(Vaccines=$B32,IF(Formulation=Volume_Inject!$C28,IF(Vaccine_database!$E$10:$E$278=Volume_Inject!$D28,IF(Vaccine_database!$J$10:$J$278=$C32,Vaccine_database!K$10:K$278))))),IF($D$5=max,MAX(IF(Vaccines=$B32,IF(Formulation=Volume_Inject!$C28,IF(Vaccine_database!$E$10:$E$278=Volume_Inject!$D28,IF(Vaccine_database!$J$10:$J$278=$C32,Vaccine_database!K$10:K$278))))),AVERAGE(IF(Vaccines=$B32,IF(Formulation=Volume_Inject!$C28,IF(Vaccine_database!$E$10:$E$278=Volume_Inject!$D28,IF(Vaccine_database!$J$10:$J$278=$C32,Vaccine_database!K$10:K$278))))))))} -> 0 | G32: {=IF(C32="",0,IF($D$5=min,MIN(IF(Vaccines=$B32,IF(Formulation=Volume_Inject!$C28,IF(Vaccine_database!$E$10:$E$278=Volume_Inject!$D28,IF(Vaccine_database!$J$10:$J$278=$C32,Vaccine_database!L$10:L$278))))),IF($D$5=max,MAX(IF(Vaccines=$B32,IF(Formulation=Volume_Inject!$C28,IF(Vaccine_database!$E$10:$E$278=Volume_Inject!$D28,IF(Vaccine_database!$J$10:$J$278=$C32,Vaccine_database!L$10:L$278))))),AVERAGE(IF(Vaccines=$B32,IF(Formulation=Volume_Inject!$C28,IF(Vaccine_database!$E$10:$E$278=Volume_Inject!$D28,IF(Vaccine_database!$J$10:$J$278=$C32,Vaccine_database!L$10:L$278))))))))} -> 0 | J32: =IF(B32="","",IF(OR(ISTEXT(C32),C32=1),5,IF(Volume_Inject!$C28<>"liquid",IF(C32>=20,50,IF(C32=10,40,10)),IF(C32>=10,25,10)))) | K32: =IF(I32="",IF($J32="",0,100/(100-$J32)),100/(100-$I32)) -> 0 | Y32: =IF($V32="",0,Volume_Inject!$F28*$K32*M32*($V32+$W32)/12) -> 0 | Z32: =IF($V32="",0,Volume_Inject!$F28*$K32*N32*($V32+$W32)/12) -> 0 | AA32: =IF($V32="",0,Volume_Inject!$F28*$K32*O32*($V32+$W32)/12) -> 0 | AB32: =IF($V32="",0,Volume_Inject!$F28*$K32*P32*($V32+$W32)/12) -> 0 | AC32: =IF($V32="",0,Volume_Inject!$F28*$K32*Q32*($V32+$W32)/12) -> 0
F33: {=IF(B33="",0,IF($D$5=min,MIN(IF(Vaccines=$B33,IF(Formulation=Volume_Inject!$C29,IF(Vaccine_database!$E$10:$E$278=Volume_Inject!$D29,IF(Vaccine_database!$J$10:$J$278=$C33,Vaccine_database!K$10:K$278))))),IF($D$5=max,MAX(IF(Vaccines=$B33,IF(Formulation=Volume_Inject!$C29,IF(Vaccine_database!$E$10:$E$278=Volume_Inject!$D29,IF(Vaccine_database!$J$10:$J$278=$C33,Vaccine_database!K$10:K$278))))),AVERAGE(IF(Vaccines=$B33,IF(Formulation=Volume_Inject!$C29,IF(Vaccine_database!$E$10:$E$278=Volume_Inject!$D29,IF(Vaccine_database!$J$10:$J$278=$C33,Vaccine_database!K$10:K$278))))))))} -> 0 | G33: {=IF(C33="",0,IF($D$5=min,MIN(IF(Vaccines=$B33,IF(Formulation=Volume_Inject!$C29,IF(Vaccine_database!$E$10:$E$278=Volume_Inject!$D29,IF(Vaccine_database!$J$10:$J$278=$C33,Vaccine_database!L$10:L$278))))),IF($D$5=max,MAX(IF(Vaccines=$B33,IF(Formulation=Volume_Inject!$C29,IF(Vaccine_database!$E$10:$E$278=Volume_Inject!$D29,IF(Vaccine_database!$J$10:$J$278=$C33,Vaccine_database!L$10:L$278))))),AVERAGE(IF(Vaccines=$B33,IF(Formulation=Volume_Inject!$C29,IF(Vaccine_database!$E$10:$E$278=Volume_Inject!$D29,IF(Vaccine_database!$J$10:$J$278=$C33,Vaccine_database!L$10:L$278))))))))} -> 0 | J33: =IF(B33="","",IF(OR(ISTEXT(C33),C33=1),5,IF(Volume_Inject!$C29<>"liquid",IF(C33>=20,50,IF(C33=10,40,10)),IF(C33>=10,25,10)))) | K33: =IF(I33="",IF($J33="",0,100/(100-$J33)),100/(100-$I33)) -> 0 | Y33: =IF($V33="",0,Volume_Inject!$F29*$K33*M33*($V33+$W33)/12) -> 0 | Z33: =IF($V33="",0,Volume_Inject!$F29*$K33*N33*($V33+$W33)/12) -> 0 | AA33: =IF($V33="",0,Volume_Inject!$F29*$K33*O33*($V33+$W33)/12) -> 0 | AB33: =IF($V33="",0,Volume_Inject!$F29*$K33*P33*($V33+$W33)/12) -> 0 | AC33: =IF($V33="",0,Volume_Inject!$F29*$K33*Q33*($V33+$W33)/12) -> 0
F34: {=IF(B34="",0,IF($D$5=min,MIN(IF(Vaccines=$B34,IF(Formulation=Volume_Inject!$C30,IF(Vaccine_database!$E$10:$E$278=Volume_Inject!$D30,IF(Vaccine_database!$J$10:$J$278=$C34,Vaccine_database!K$10:K$278))))),IF($D$5=max,MAX(IF(Vaccines=$B34,IF(Formulation=Volume_Inject!$C30,IF(Vaccine_database!$E$10:$E$278=Volume_Inject!$D30,IF(Vaccine_database!$J$10:$J$278=$C34,Vaccine_database!K$10:K$278))))),AVERAGE(IF(Vaccines=$B34,IF(Formulation=Volume_Inject!$C30,IF(Vaccine_database!$E$10:$E$278=Volume_Inject!$D30,IF(Vaccine_database!$J$10:$J$278=$C34,Vaccine_database!K$10:K$278))))))))} -> 0 | G34: {=IF(C34="",0,IF($D$5=min,MIN(IF(Vaccines=$B34,IF(Formulation=Volume_Inject!$C30,IF(Vaccine_database!$E$10:$E$278=Volume_Inject!$D30,IF(Vaccine_database!$J$10:$J$278=$C34,Vaccine_database!L$10:L$278))))),IF($D$5=max,MAX(IF(Vaccines=$B34,IF(Formulation=Volume_Inject!$C30,IF(Vaccine_database!$E$10:$E$278=Volume_Inject!$D30,IF(Vaccine_database!$J$10:$J$278=$C34,Vaccine_database!L$10:L$278))))),AVERAGE(IF(Vaccines=$B34,IF(Formulation=Volume_Inject!$C30,IF(Vaccine_database!$E$10:$E$278=Volume_Inject!$D30,IF(Vaccine_database!$J$10:$J$278=$C34,Vaccine_database!L$10:L$278))))))))} -> 0 | J34: =IF(B34="","",IF(OR(ISTEXT(C34),C34=1),5,IF(Volume_Inject!$C30<>"liquid",IF(C34>=20,50,IF(C34=10,40,10)),IF(C34>=10,25,10)))) | K34: =IF(I34="",IF($J34="",0,100/(100-$J34)),100/(100-$I34)) -> 0 | Y34: =IF($V34="",0,Volume_Inject!$F30*$K34*M34*($V34+$W34)/12) -> 0 | Z34: =IF($V34="",0,Volume_Inject!$F30*$K34*N34*($V34+$W34)/12) -> 0 | AA34: =IF($V34="",0,Volume_Inject!$F30*$K34*O34*($V34+$W34)/12) -> 0 | AB34: =IF($V34="",0,Volume_Inject!$F30*$K34*P34*($V34+$W34)/12) -> 0 | AC34: =IF($V34="",0,Volume_Inject!$F30*$K34*Q34*($V34+$W34)/12) -> 0
F35: {=IF(B35="",0,IF($D$5=min,MIN(IF(Vaccines=$B35,IF(Formulation=Volume_Inject!$C31,IF(Vaccine_database!$E$10:$E$278=Volume_Inject!$D31,IF(Vaccine_database!$J$10:$J$278=$C35,Vaccine_database!K$10:K$278))))),IF($D$5=max,MAX(IF(Vaccines=$B35,IF(Formulation=Volume_Inject!$C31,IF(Vaccine_database!$E$10:$E$278=Volume_Inject!$D31,IF(Vaccine_database!$J$10:$J$278=$C35,Vaccine_database!K$10:K$278))))),AVERAGE(IF(Vaccines=$B35,IF(Formulation=Volume_Inject!$C31,IF(Vaccine_database!$E$10:$E$278=Volume_Inject!$D31,IF(Vaccine_database!$J$10:$J$278=$C35,Vaccine_database!K$10:K$278))))))))} -> 0 | G35: {=IF(C35="",0,IF($D$5=min,MIN(IF(Vaccines=$B35,IF(Formulation=Volume_Inject!$C31,IF(Vaccine_database!$E$10:$E$278=Volume_Inject!$D31,IF(Vaccine_database!$J$10:$J$278=$C35,Vaccine_database!L$10:L$278))))),IF($D$5=max,MAX(IF(Vaccines=$B35,IF(Formulation=Volume_Inject!$C31,IF(Vaccine_database!$E$10:$E$278=Volume_Inject!$D31,IF(Vaccine_database!$J$10:$J$278=$C35,Vaccine_database!L$10:L$278))))),AVERAGE(IF(Vaccines=$B35,IF(Formulation=Volume_Inject!$C31,IF(Vaccine_database!$E$10:$E$278=Volume_Inject!$D31,IF(Vaccine_database!$J$10:$J$278=$C35,Vaccine_database!L$10:L$278))))))))} -> 0 | J35: =IF(B35="","",IF(OR(ISTEXT(C35),C35=1),5,IF(Volume_Inject!$C31<>"liquid",IF(C35>=20,50,IF(C35=10,40,10)),IF(C35>=10,25,10)))) | K35: =IF(I35="",IF($J35="",0,100/(100-$J35)),100/(100-$I35)) -> 0 | Y35: =IF($V35="",0,Volume_Inject!$F31*$K35*M35*($V35+$W35)/12) -> 0 | Z35: =IF($V35="",0,Volume_Inject!$F31*$K35*N35*($V35+$W35)/12) -> 0 | AA35: =IF($V35="",0,Volume_Inject!$F31*$K35*O35*($V35+$W35)/12) -> 0 | AB35: =IF($V35="",0,Volume_Inject!$F31*$K35*P35*($V35+$W35)/12) -> 0 | AC35: =IF($V35="",0,Volume_Inject!$F31*$K35*Q35*($V35+$W35)/12) -> 0
F36: {=IF(B36="",0,IF($D$5=min,MIN(IF(Vaccines=$B36,IF(Formulation=Volume_Inject!$C32,IF(Vaccine_database!$E$10:$E$278=Volume_Inject!$D32,IF(Vaccine_database!$J$10:$J$278=$C36,Vaccine_database!K$10:K$278))))),IF($D$5=max,MAX(IF(Vaccines=$B36,IF(Formulation=Volume_Inject!$C32,IF(Vaccine_database!$E$10:$E$278=Volume_Inject!$D32,IF(Vaccine_database!$J$10:$J$278=$C36,Vaccine_database!K$10:K$278))))),AVERAGE(IF(Vaccines=$B36,IF(Formulation=Volume_Inject!$C32,IF(Vaccine_database!$E$10:$E$278=Volume_Inject!$D32,IF(Vaccine_database!$J$10:$J$278=$C36,Vaccine_database!K$10:K$278))))))))} -> 0 | G36: {=IF(C36="",0,IF($D$5=min,MIN(IF(Vaccines=$B36,IF(Formulation=Volume_Inject!$C32,IF(Vaccine_database!$E$10:$E$278=Volume_Inject!$D32,IF(Vaccine_database!$J$10:$J$278=$C36,Vaccine_database!L$10:L$278))))),IF($D$5=max,MAX(IF(Vaccines=$B36,IF(Formulation=Volume_Inject!$C32,IF(Vaccine_database!$E$10:$E$278=Volume_Inject!$D32,IF(Vaccine_database!$J$10:$J$278=$C36,Vaccine_database!L$10:L$278))))),AVERAGE(IF(Vaccines=$B36,IF(Formulation=Volume_Inject!$C32,IF(Vaccine_database!$E$10:$E$278=Volume_Inject!$D32,IF(Vaccine_database!$J$10:$J$278=$C36,Vaccine_database!L$10:L$278))))))))} -> 0 | J36: =IF(B36="","",IF(OR(ISTEXT(C36),C36=1),5,IF(Volume_Inject!$C32<>"liquid",IF(C36>=20,50,IF(C36=10,40,10)),IF(C36>=10,25,10)))) | K36: =IF(I36="",IF($J36="",0,100/(100-$J36)),100/(100-$I36)) -> 0 | Y36: =IF($V36="",0,Volume_Inject!$F32*$K36*M36*($V36+$W36)/12) -> 0 | Z36: =IF($V36="",0,Volume_Inject!$F32*$K36*N36*($V36+$W36)/12) -> 0 | AA36: =IF($V36="",0,Volume_Inject!$F32*$K36*O36*($V36+$W36)/12) -> 0 | AB36: =IF($V36="",0,Volume_Inject!$F32*$K36*P36*($V36+$W36)/12) -> 0 | AC36: =IF($V36="",0,Volume_Inject!$F32*$K36*Q36*($V36+$W36)/12) -> 0
L38: =CONCATENATE(Translation!C356," ",E$8) -> Net volume of OPV at -20°C in higher level stores, per Unit of Population | M38: {=IF($E$8=target1,SUM(($B$17:$B$36="OPV")*(Volume_Inject!$F$13:$F$32)*($K$17:$K$36)*(M$17:M$36)),SUM(($B$17:$B$36="OPV")*(Volume_Inject!$F$13:$F$32)*($K$17:$K$36)*($L$17:$L$36)*(M$17:M$36)))} -> 0.20266667 | N38: {=IF($E$8=target1,SUM(($B$17:$B$36="OPV")*(Volume_Inject!$F$13:$F$32)*($K$17:$K$36)*(N$17:N$36)),SUM(($B$17:$B$36="OPV")*(Volume_Inject!$F$13:$F$32)*($K$17:$K$36)*($L$17:$L$36)*(N$17:N$36)))} -> 0.20266667 | O38: {=IF($E$8=target1,SUM(($B$17:$B$36="OPV")*(Volume_Inject!$F$13:$F$32)*($K$17:$K$36)*(O$17:O$36)),SUM(($B$17:$B$36="OPV")*(Volume_Inject!$F$13:$F$32)*($K$17:$K$36)*($L$17:$L$36)*(O$17:O$36)))} -> 0.20266667 | P38: {=IF($E$8=target1,SUM(($B$17:$B$36="OPV")*(Volume_Inject!$F$13:$F$32)*($K$17:$K$36)*(P$17:P$36)),SUM(($B$17:$B$36="OPV")*(Volume_Inject!$F$13:$F$32)*($K$17:$K$36)*($L$17:$L$36)*(P$17:P$36)))} -> 0 | Q38: {=IF($E$8=target1,SUM(($B$17:$B$36="OPV")*(Volume_Inject!$F$13:$F$32)*($K$17:$K$36)*(Q$17:Q$36)),SUM(($B$17:$B$36="OPV")*(Volume_Inject!$F$13:$F$32)*($K$17:$K$36)*($L$17:$L$36)*(Q$17:Q$36)))} -> 0 | Y38: {=IF($E$8=target1,SUMIF($B$17:$B$36,"OPV",Y$17:Y$36),SUM(($B$17:$B$36="OPV")*($L$17:$L$36)*(Y$17:Y$36)))} -> 0.084444444 | Z38: {=IF($E$8=target1,SUMIF($B$17:$B$36,"OPV",Z$17:Z$36),SUM(($B$17:$B$36="OPV")*($L$17:$L$36)*(Z$17:Z$36)))} -> 0.084444444 | AA38: {=IF($E$8=target1,SUMIF($B$17:$B$36,"OPV",AA$17:AA$36),SUM(($B$17:$B$36="OPV")*($L$17:$L$36)*(AA$17:AA$36)))} -> 0.084444444 | AB38: {=IF($E$8=target1,SUMIF($B$17:$B$36,"OPV",AB$17:AB$36),SUM(($B$17:$B$36="OPV")*($L$17:$L$36)*(AB$17:AB$36)))} -> 0 | AC38: {=IF($E$8=target1,SUMIF($B$17:$B$36,"OPV",AC$17:AC$36),SUM(($B$17:$B$36="OPV")*($L$17:$L$36)*(AC$17:AC$36)))} -> 0
L39: =CONCATENATE(Translation!C357," ",E$8) -> Net volume of all vaccines except OPV stored at +5°C in higher level stores, per Unit of Population | M39: {=IF($E$8=target1,SUMPRODUCT(Volume_Inject!$F$13:$F$32,$K$17:$K$36,M$17:M$36),SUMPRODUCT(Volume_Inject!$F$13:$F$32,$K$17:$K$36,$L$17:$L$36,M$17:M$36))-M38} -> 0.60087471 | N39: {=IF($E$8=target1,SUMPRODUCT(Volume_Inject!$F$13:$F$32,$K$17:$K$36,N$17:N$36),SUMPRODUCT(Volume_Inject!$F$13:$F$32,$K$17:$K$36,$L$17:$L$36,N$17:N$36))-N38} -> 1.3917051 | O39: {=IF($E$8=target1,SUMPRODUCT(Volume_Inject!$F$13:$F$32,$K$17:$K$36,O$17:O$36),SUMPRODUCT(Volume_Inject!$F$13:$F$32,$K$17:$K$36,$L$17:$L$36,O$17:O$36))-O38} -> 1.1118747 | P39: {=IF($E$8=target1,SUMPRODUCT(Volume_Inject!$F$13:$F$32,$K$17:$K$36,P$17:P$36),SUMPRODUCT(Volume_Inject!$F$13:$F$32,$K$17:$K$36,$L$17:$L$36,P$17:P$36))-P38} -> 0 | Q39: {=IF($E$8=target1,SUMPRODUCT(Volume_Inject!$F$13:$F$32,$K$17:$K$36,Q$17:Q$36),SUMPRODUCT(Volume_Inject!$F$13:$F$32,$K$17:$K$36,$L$17:$L$36,Q$17:Q$36))-Q38} -> 0 | Y39: =Y40-Y38 -> 0.2365452 | Z39: =Z40-Z38 -> 0.48273867 | AA39: =AA40-AA38 -> 0.44946187 | AB39: =AB40-AB38 -> 0 | AC39: =AC40-AC38 -> 0
L40: =CONCATENATE(Translation!C358," ",E$8) -> Net volume of all vaccines, including OPV, stored at +5°C in lower level stores, per Unit of Population | M40: {=IF($E$8=target1,SUMPRODUCT(Volume_Inject!$F$13:$F$32,$K$17:$K$36,M$17:M$36),SUMPRODUCT(Volume_Inject!$F$13:$F$32,$K$17:$K$36,$L$17:$L$36,M$17:M$36))} -> 0.80354138 | N40: {=IF($E$8=target1,SUMPRODUCT(Volume_Inject!$F$13:$F$32,$K$17:$K$36,N$17:N$36),SUMPRODUCT(Volume_Inject!$F$13:$F$32,$K$17:$K$36,$L$17:$L$36,N$17:N$36))} -> 1.5943718 | O40: {=IF($E$8=target1,SUMPRODUCT(Volume_Inject!$F$13:$F$32,$K$17:$K$36,O$17:O$36),SUMPRODUCT(Volume_Inject!$F$13:$F$32,$K$17:$K$36,$L$17:$L$36,O$17:O$36))} -> 1.3145414 | P40: {=IF($E$8=target1,SUMPRODUCT(Volume_Inject!$F$13:$F$32,$K$17:$K$36,P$17:P$36),SUMPRODUCT(Volume_Inject!$F$13:$F$32,$K$17:$K$36,$L$17:$L$36,P$17:P$36))} -> 0 | Q40: {=IF($E$8=target1,SUMPRODUCT(Volume_Inject!$F$13:$F$32,$K$17:$K$36,Q$17:Q$36),SUMPRODUCT(Volume_Inject!$F$13:$F$32,$K$17:$K$36,$L$17:$L$36,Q$17:Q$36))} -> 0 | R40: =Translation!C357 -> Net volume of all vaccines except OPV stored at +5°C in higher level stores, per | S40: =SUMPRODUCT(Volume_Inject!$F$13:$F$32,$K$17:$K$36,S$17:S$36) -> 18 | T40: =SUMPRODUCT(Volume_Inject!$F$13:$F$32,$K$17:$K$36,T$17:T$36) -> 0 | U40: =SUMPRODUCT(Volume_Inject!$F$13:$F$32,$K$17:$K$36,U$17:U$36) -> 0 | Y40: {=IF($E$8=target1,SUM(Y$17:Y$36),SUM(($L$17:$L$36)*(Y$17:Y$36)))} -> 0.32098965 | Z40: {=IF($E$8=target1,SUM(Z$17:Z$36),SUM(($L$17:$L$36)*(Z$17:Z$36)))} -> 0.56718311 | AA40: {=IF($E$8=target1,SUM(AA$17:AA$36),SUM(($L$17:$L$36)*(AA$17:AA$36)))} -> 0.53390631 | AB40: {=IF($E$8=target1,SUM(AB$17:AB$36),SUM(($L$17:$L$36)*(AB$17:AB$36)))} -> 0 | AC40: {=IF($E$8=target1,SUM(AC$17:AC$36),SUM(($L$17:$L$36)*(AC$17:AC$36)))} -> 0
L41: =CONCATENATE(Translation!C359," ",E$8) -> Net volume of vaccines and diluents, stored at +5°C at service points, per Unit of Population | M41: =IF($E$8=target1,SUMPRODUCT(Volume_Inject!$F$13:$F$32,$K$17:$K$36,M$17:M$36)+SUMPRODUCT(Volume_Inject!$G$13:$G$32,$K$17:$K$36,M$17:M$36),SUMPRODUCT(Volume_Inject!$F$13:$F$32,$K$17:$K$36,$L$17:$L$36,M$17:M$36)+SUMPRODUCT(Volume_Inject!$G$13:$G$32,$K$17:$K$36,$L$17:$L$36,M$17:M$36)) -> 1.0773167 | N41: =IF($E$8=target1,SUMPRODUCT(Volume_Inject!$F$13:$F$32,$K$17:$K$36,N$17:N$36)+SUMPRODUCT(Volume_Inject!$G$13:$G$32,$K$17:$K$36,N$17:N$36),SUMPRODUCT(Volume_Inject!$F$13:$F$32,$K$17:$K$36,$L$17:$L$36,N$17:N$36)+SUMPRODUCT(Volume_Inject!$G$13:$G$32,$K$17:$K$36,$L$17:$L$36,N$17:N$36)) -> 1.8681471 | O41: =IF($E$8=target1,SUMPRODUCT(Volume_Inject!$F$13:$F$32,$K$17:$K$36,O$17:O$36)+SUMPRODUCT(Volume_Inject!$G$13:$G$32,$K$17:$K$36,O$17:O$36),SUMPRODUCT(Volume_Inject!$F$13:$F$32,$K$17:$K$36,$L$17:$L$36,O$17:O$36)+SUMPRODUCT(Volume_Inject!$G$13:$G$32,$K$17:$K$36,$L$17:$L$36,O$17:O$36)) -> 1.5883167 | P41: =IF($E$8=target1,SUMPRODUCT(Volume_Inject!$F$13:$F$32,$K$17:$K$36,P$17:P$36)+SUMPRODUCT(Volume_Inject!$G$13:$G$32,$K$17:$K$36,P$17:P$36),SUMPRODUCT(Volume_Inject!$F$13:$F$32,$K$17:$K$36,$L$17:$L$36,P$17:P$36)+SUMPRODUCT(Volume_Inject!$G$13:$G$32,$K$17:$K$36,$L$17:$L$36,P$17:P$36)) -> 0 | Q41: =IF($E$8=target1,SUMPRODUCT(Volume_Inject!$F$13:$F$32,$K$17:$K$36,Q$17:Q$36)+SUMPRODUCT(Volume_Inject!$G$13:$G$32,$K$17:$K$36,Q$17:Q$36),SUMPRODUCT(Volume_Inject!$F$13:$F$32,$K$17:$K$36,$L$17:$L$36,Q$17:Q$36)+SUMPRODUCT(Volume_Inject!$G$13:$G$32,$K$17:$K$36,$L$17:$L$36,Q$17:Q$36)) -> 0 | R41: =Translation!C366 -> Total net storage volume of vaccines & diluents per recipient | S41: =SUMPRODUCT(Volume_Inject!$F$13:$F$32,$K$17:$K$36,S$17:S$36)+SUMPRODUCT(Volume_Inject!$G$13:$G$32,$K$17:$K$36,S$17:S$36) -> 18 | T41: =SUMPRODUCT(Volume_Inject!$F$13:$F$32,$K$17:$K$36,T$17:T$36)+SUMPRODUCT(Volume_Inject!$G$13:$G$32,$K$17:$K$36,T$17:T$36) -> 0 | U41: =SUMPRODUCT(Volume_Inject!$F$13:$F$32,$K$17:$K$36,U$17:U$36)+SUMPRODUCT(Volume_Inject!$G$13:$G$32,$K$17:$K$36,U$17:U$36) -> 0
L43: =CONCATENATE(Translation!C360," ",$E$8) -> No. of vaccine doses per Unit of Population | M43: =SUM(M$17:M$36) -> 12 | N43: =SUM(N$17:N$36) -> 12 | O43: =SUM(O$17:O$36) -> 12 | P43: =SUM(P$17:P$36) -> 0 | Q43: =SUM(Q$17:Q$36) -> 0 | S43: =SUMPRODUCT(S$17:S$36,$K$17:$K$36) -> 1.0526316 | T43: =SUMPRODUCT(T$17:T$36,$K$17:$K$36) -> 0 | U43: =SUMPRODUCT(U$17:U$36,$K$17:$K$36) -> 0
L45: =Translation!C361 -> Percent increase of the net vaccine volume compared to current schedule in store for -20°C | N45: =IF(OR($M$38=0,N38=0),"",(N38-$M$38)/$M$38) -> 0 | O45: =IF(OR($M$38=0,O38=0),"",(O38-$M$38)/$M$38) -> 0 | P45: =IF(OR($M$38=0,P38=0),"",(P38-$M$38)/$M$38) | Q45: =IF(OR($M$38=0,Q38=0),"",(Q38-$M$38)/$M$38) | Z45: =IF(OR($Y$38=0,Z38=0),"",(Z38-$Y$38)/$Y$38) -> 0 | AA45: =IF(OR($Y$38=0,AA38=0),"",(AA38-$Y$38)/$Y$38) -> 0 | AB45: =IF(OR($Y$38=0,AB38=0),"",(AB38-$Y$38)/$Y$38) | AC45: =IF(OR($Y$38=0,AC38=0),"",(AC38-$Y$38)/$Y$38)
L46: =Translation!C362 -> % increase of the net vaccine volume compared to current schedule in store w/o OPV @+5°C | N46: =IF(OR($M$39=0,N39=0),"",(N39-$M$39)/$M$39) -> 1.3161319 | O46: =IF(OR($M$39=0,O39=0),"",(O39-$M$39)/$M$39) -> 0.85042687 | P46: =IF(OR($M$39=0,P39=0),"",(P39-$M$39)/$M$39) | Q46: =IF(OR($M$39=0,Q39=0),"",(Q39-$M$39)/$M$39) | Z46: =IF(OR($Y$39=0,Z39=0),"",(Z39-$Y$39)/$Y$39) -> 1.0407882 | AA46: =IF(OR($Y$39=0,AA39=0),"",(AA39-$Y$39)/$Y$39) -> 0.90010985 | AB46: =IF(OR($Y$39=0,AB39=0),"",(AB39-$Y$39)/$Y$39) | AC46: =IF(OR($Y$39=0,AC39=0),"",(AC39-$Y$39)/$Y$39)
L47: =Translation!C363 -> % increase of the net vaccine volume compared to current schedule in store with OPV @+5°C | N47: =IF(OR($M$40=0,N40=0),"",(N40-$M$40)/$M$40) -> 0.9841813 | O47: =IF(OR($M$40=0,O40=0),"",(O40-$M$40)/$M$40) -> 0.63593489 | P47: =IF(OR($M$40=0,P40=0),"",(P40-$M$40)/$M$40) | Q47: =IF(OR($M$40=0,Q40=0),"",(Q40-$M$40)/$M$40) | T47: =IF(OR($S$40=0,T40=0),"",(T40-$S$40)/$S$40) | U47: =IF(OR($S$40=0,U40=0),"",(U40-$S$40)/$S$40) | Z47: =IF(OR($Y$40=0,Z40=0),"",(Z40-$Y$40)/$Y$40) -> 0.76698257 | AA47: =IF(OR($Y$40=0,AA40=0),"",(AA40-$Y$40)/$Y$40) -> 0.66331319 | AB47: =IF(OR($Y$40=0,AB40=0),"",(AB40-$Y$40)/$Y$40) | AC47: =IF(OR($Y$40=0,AC40=0),"",(AC40-$Y$40)/$Y$40)
...

Sheet Abacus_Tables
B1: =Translation!C10 -> Analysis of national and sub-national storage | O1: =Translation!C109 -> Index
F2: =Translation!C19 -> Maximum stock levels (months)
F3: =Translation!C20 -> Vaccines | H3: =Translation!C25 -> Safe injection equipment
B4: =Translation!C11 -> Analysis per | C4: =Vaccine_Selection!$E$8 -> Unit of Population | F4: 4 | H4: 6
B5: =IF($C$4=target2,CONCATENATE(Translation!$C$12," ",Translation!$C$15),CONCATENATE(Translation!$C$13," ",Translation!$C$15)) -> Total population (minimum) | C5: 500000 | F5: 6 | H5: 9 | K5: =Translation!C26 -> Cold room cost equation | N5: 4.2 | O5: =Translation!C27 -> Indicative grossing factor
B6: =IF($C$4=target2,CONCATENATE(Translation!$C$12," ",Translation!$C$14),CONCATENATE(Translation!$C$13," ",Translation!$C$14)) -> Total population (maximum) | C6: 10000000 | F6: 9 | H6: 12 | K6: Y1 = | L6: 0.0403 | M6: -11.316 | N6: 2326.5 | O6: =Translation!C254 -> WICR
B7: =Translation!C18 -> MaxiStock | C7: per individual vaccine | E7: =Translation!C17 -> months | F7: par vaccin individuel | K7: Y2 = | L7: 0.0506 | M7: -14.207 | N7: 2944.4 | O7: =Translation!C255 -> WIFR
C8: =(C6-C5)/25 -> 380000 | D8: =IF(C8=0,0,ROUNDUP(C8,-(ROUND(LOG(C8),1)))) -> 400000
B10: =Translation!C28 -> Vaccine net volume for supply period and cold room capacities | F10: =IF($C$4=target2,Translation!$C$12,Translation!$C$13) -> Total population
B11: =CONCATENATE(F10,": ",) -> Total population: | C11: =$C$5 -> 500000 | D11: =C11+$D$8 -> 900000 | E11: =D11+$D$8 -> 1300000 | F11: =E11+$D$8 -> 1700000 | G11: =F11+$D$8 -> 2100000 | H11: =G11+$D$8 -> 2500000 | I11: =H11+$D$8 -> 2900000 | J11: =I11+$D$8 -> 3300000 | K11: =J11+$D$8 -> 3700000 | ... AB11: =AA11+$D$8 -> 10500000
B12: =Translation!C29 -> Estimate of cold-chain capacity per schedule (litres)
B13: =IF(Vaccine_Selection!$M$16="","",CONCATENATE(Vaccine_Selection!$M$16," @ ",$C$7,$E$7,"-MaxiStock")) -> Current schedule @ per individual vaccine months-MaxiStock | C13: =IF(ISTEXT($C$7),Vaccine_Selection!$Y$39,Vaccine_Selection!$M$39*$C$7/12)*C$11/1000 -> 118.2726 | D13: =IF(ISTEXT($C$7),Vaccine_Selection!$Y$39,Vaccine_Selection!$M$39*$C$7/12)*D$11/1000 -> 212.89068 | E13: =IF(ISTEXT($C$7),Vaccine_Selection!$Y$39,Vaccine_Selection!$M$39*$C$7/12)*E$11/1000 -> 307.50876 | F13: =IF(ISTEXT($C$7),Vaccine_Selection!$Y$39,Vaccine_Selection!$M$39*$C$7/12)*F$11/1000 -> 402.12685 | G13: =IF(ISTEXT($C$7),Vaccine_Selection!$Y$39,Vaccine_Selection!$M$39*$C$7/12)*G$11/1000 -> 496.74493 | H13: =IF(ISTEXT($C$7),Vaccine_Selection!$Y$39,Vaccine_Selection!$M$39*$C$7/12)*H$11/1000 -> 591.36301 | I13: =IF(ISTEXT($C$7),Vaccine_Selection!$Y$39,Vaccine_Selection!$M$39*$C$7/12)*I$11/1000 -> 685.98109 | J13: =IF(ISTEXT($C$7),Vaccine_Selection!$Y$39,Vaccine_Selection!$M$39*$C$7/12)*J$11/1000 -> 780.59917 | ... AB13: =IF(ISTEXT($C$7),Vaccine_Selection!$Y$39,Vaccine_Selection!$M$39*$C$7/12)*AB$11/1000 -> 2483.7246
